Workbook

Sheet How to use this calculator

Sheet Input and Summary Results
A2: Data set:
B4: Position | C4: Mutation | D4: Measured Value | E4: Error | G4: Positions Analyzed | I4: Should the data be converted to a log scale? | J4: yes | N4: Scores
A5: Wild Type | B5: NA | C5: NA | L5: Position | M5: # of variants | N5: Enhancing | O5: Neutral | P5: Unweighted rheostat | Q5: Weighted rheostat | R5: Toggle | S5: Binary | T5: Average | U5: Standard Deviation | V5: Assignment | AA5: Enhancing | AB5: =O5 -> Neutral | AC5: =P5 -> Unweighted rheostat | AD5: =Q5 -> Weighted rheostat | AE5: =R5 -> Toggle | AF5: Binary
A6: Format Example | B6: 45 | C6: A | D6: 0.563 | E6: 0.0034 | I6: Data statistics | L6: all | M6: =INDEX('Bin Analysis'!$C$3:$S$505,MATCH($L6,'Bin Analysis'!$B$3:$B$505,0),MATCH(M$5,'Bin Analysis'!$C$2:$S$2,0)) -> FALSE | N6: =INDEX('Bin Analysis'!$C$3:$S$505,MATCH($L6,'Bin Analysis'!$B$3:$B$505,0),MATCH(N$5,'Bin Analysis'!$C$2:$S$2,0)) -> 0 | O6: =INDEX('Bin Analysis'!$C$3:$S$505,MATCH($L6,'Bin Analysis'!$B$3:$B$505,0),MATCH(O$5,'Bin Analysis'!$C$2:$S$2,0)) -> #N/A | P6: =INDEX('Bin Analysis'!$C$3:$S$505,MATCH($L6,'Bin Analysis'!$B$3:$B$505,0),MATCH(P$5,'Bin Analysis'!$C$2:$S$2,0)) -> #N/A | Q6: =INDEX('Bin Analysis'!$C$3:$S$505,MATCH($L6,'Bin Analysis'!$B$3:$B$505,0),MATCH(Q$5,'Bin Analysis'!$C$2:$S$2,0)) -> #N/A | R6: =INDEX('Bin Analysis'!$C$3:$S$505,MATCH($L6,'Bin Analysis'!$B$3:$B$505,0),MATCH(R$5,'Bin Analysis'!$C$2:$S$2,0)) -> #N/A | S6: =INDEX('Bin Analysis'!$C$3:$S$505,MATCH($L6,'Bin Analysis'!$B$3:$B$505,0),MATCH(S$5,'Bin Analysis'!$C$2:$S$2,0)) -> #N/A | T6: =Assignments!K5 | U6: =Assignments!L5 -> 0 | Z6: <0.1 | AA6: =COUNTIF(N$7:N$427,"<0.1") -> 0 | AB6: =COUNTIF(O$7:O$427,"<0.1") -> 0 | AC6: =COUNTIF(P$7:P$427,"<0.1") -> 0 | AD6: =COUNTIF(Q$7:Q$427,"<0.1") -> 0 | AE6: =COUNTIF(R$7:R$427,"<0.1") -> 0 | AF6: =COUNTIF(S$7:S$427,"=yes") -> 0
A7: the WT aa | I7: Minimum | J7: =IF($J$4="yes",10^('Data Transformation'!R3),'Data Transformation'!R3) -> 1 | L7: =$G8 | M7: =IF(L7=" "," ",(IF($L7>0,INDEX('Bin Analysis'!$C$3:$S$10110,MATCH($L7,'Bin Analysis'!$L$3:$L$10110,0),MATCH(M$5,'Bin Analysis'!$C$2:$S$2,0))," "))) | N7: =IF($L7=" "," ",(IF($M7=FALSE," ",(IF($M7>0,INDEX('Bin Analysis'!$C$3:$S$10110,MATCH($L7,'Bin Analysis'!$L$3:$L$10110,0),MATCH(N$5,'Bin Analysis'!$C$2:$S$2,0))," "))))) | O7: =IF($L7=" "," ",(IF($M7=FALSE," ",(IF($M7>0,INDEX('Bin Analysis'!$C$3:$S$10110,MATCH($L7,'Bin Analysis'!$L$3:$L$10110,0),MATCH(O$5,'Bin Analysis'!$C$2:$S$2,0))," "))))) | P7: =IF($L7=" "," ",(IF($M7=FALSE," ",(IF($M7>0,INDEX('Bin Analysis'!$C$3:$S$10110,MATCH($L7,'Bin Analysis'!$L$3:$L$10110,0),MATCH(P$5,'Bin Analysis'!$C$2:$S$2,0))," "))))) | Q7: =IF($L7=" "," ",(IF($M7=FALSE," ",(IF($M7>0,INDEX('Bin Analysis'!$C$3:$S$10110,MATCH($L7,'Bin Analysis'!$L$3:$L$10110,0),MATCH(Q$5,'Bin Analysis'!$C$2:$S$2,0))," "))))) | R7: =IF($L7=" "," ",(IF($M7=FALSE," ",(IF($M7>0,INDEX('Bin Analysis'!$C$3:$S$10110,MATCH($L7,'Bin Analysis'!$L$3:$L$10110,0),MATCH(R$5,'Bin Analysis'!$C$2:$S$2,0))," "))))) | S7: =IF($L7=" "," ",(IF($M7=FALSE," ",(IF($M7>0,INDEX('Bin Analysis'!$C$3:$S$10110,MATCH($L7,'Bin Analysis'!$L$3:$L$10110,0),MATCH(S$5,'Bin Analysis'!$C$2:$S$2,0))," "))))) | T7: =Assignments!K6 | U7: =Assignments!L6 | V7: =Assignments!V6 | Z7: 0.1 to < 0.2 | AA7: =COUNTIF(N$7:N$427,"<0.2")-SUM(AA6) -> 0 | AB7: =COUNTIF(O$7:O$427,"<0.2")-SUM(AB6) -> 0 | AC7: =COUNTIF(P$7:P$427,"<0.2")-SUM(AC6) -> 0 | AD7: =COUNTIF(Q$7:Q$427,"<0.2")-SUM(AD6) -> 0 | AE7: =COUNTIF(R$7:R$427,"<0.2")-SUM(AE6) -> 0
A8: for each | G8: =IFERROR('Data Transformation'!M6," ") | I8: Maximum | J8: =IF($J$4="yes",10^('Data Transformation'!R4),'Data Transformation'!R4) -> 1 | L8: =$G9 | M8: =IF(L8=" "," ",(IF($L8>0,INDEX('Bin Analysis'!$C$3:$S$10110,MATCH($L8,'Bin Analysis'!$L$3:$L$10110,0),MATCH(M$5,'Bin Analysis'!$C$2:$S$2,0))," "))) | N8: =IF($L8=" "," ",(IF($M8=FALSE," ",(IF($M8>0,INDEX('Bin Analysis'!$C$3:$S$10110,MATCH($L8,'Bin Analysis'!$L$3:$L$10110,0),MATCH(N$5,'Bin Analysis'!$C$2:$S$2,0))," "))))) | O8: =IF($L8=" "," ",(IF($M8=FALSE," ",(IF($M8>0,INDEX('Bin Analysis'!$C$3:$S$10110,MATCH($L8,'Bin Analysis'!$L$3:$L$10110,0),MATCH(O$5,'Bin Analysis'!$C$2:$S$2,0))," "))))) | P8: =IF($L8=" "," ",(IF($M8=FALSE," ",(IF($M8>0,INDEX('Bin Analysis'!$C$3:$S$10110,MATCH($L8,'Bin Analysis'!$L$3:$L$10110,0),MATCH(P$5,'Bin Analysis'!$C$2:$S$2,0))," "))))) | Q8: =IF($L8=" "," ",(IF($M8=FALSE," ",(IF($M8>0,INDEX('Bin Analysis'!$C$3:$S$10110,MATCH($L8,'Bin Analysis'!$L$3:$L$10110,0),MATCH(Q$5,'Bin Analysis'!$C$2:$S$2,0))," "))))) | R8: =IF($L8=" "," ",(IF($M8=FALSE," ",(IF($M8>0,INDEX('Bin Analysis'!$C$3:$S$10110,MATCH($L8,'Bin Analysis'!$L$3:$L$10110,0),MATCH(R$5,'Bin Analysis'!$C$2:$S$2,0))," "))))) | S8: =IF($L8=" "," ",(IF($M8=FALSE," ",(IF($M8>0,INDEX('Bin Analysis'!$C$3:$S$10110,MATCH($L8,'Bin Analysis'!$L$3:$L$10110,0),MATCH(S$5,'Bin Analysis'!$C$2:$S$2,0))," "))))) | T8: =Assignments!K7 | U8: =Assignments!L7 | V8: =Assignments!V7 | Z8: 0.2 to < 0.3 | AA8: =COUNTIF(N$7:N$427,"<0.3")-SUM(AA6:AA7) -> 0 | AB8: =COUNTIF(O$7:O$427,"<0.3")-SUM(AB6:AB7) -> 0 | AC8: =COUNTIF(P$7:P$427,"<0.3")-SUM(AC6:AC7) -> 0 | AD8: =COUNTIF(Q$7:Q$427,"<0.3")-SUM(AD6:AD7) -> 0 | AE8: =COUNTIF(R$7:R$427,"<0.3")-SUM(AE6:AE7) -> 0
A9: subsitution | G9: =IFERROR('Data Transformation'!M7," ") | L9: =$G10 | M9: =IF(L9=" "," ",(IF($L9>0,INDEX('Bin Analysis'!$C$3:$S$10110,MATCH($L9,'Bin Analysis'!$L$3:$L$10110,0),MATCH(M$5,'Bin Analysis'!$C$2:$S$2,0))," "))) | N9: =IF($L9=" "," ",(IF($M9=FALSE," ",(IF($M9>0,INDEX('Bin Analysis'!$C$3:$S$10110,MATCH($L9,'Bin Analysis'!$L$3:$L$10110,0),MATCH(N$5,'Bin Analysis'!$C$2:$S$2,0))," "))))) | O9: =IF($L9=" "," ",(IF($M9=FALSE," ",(IF($M9>0,INDEX('Bin Analysis'!$C$3:$S$10110,MATCH($L9,'Bin Analysis'!$L$3:$L$10110,0),MATCH(O$5,'Bin Analysis'!$C$2:$S$2,0))," "))))) | P9: =IF($L9=" "," ",(IF($M9=FALSE," ",(IF($M9>0,INDEX('Bin Analysis'!$C$3:$S$10110,MATCH($L9,'Bin Analysis'!$L$3:$L$10110,0),MATCH(P$5,'Bin Analysis'!$C$2:$S$2,0))," "))))) | Q9: =IF($L9=" "," ",(IF($M9=FALSE," ",(IF($M9>0,INDEX('Bin Analysis'!$C$3:$S$10110,MATCH($L9,'Bin Analysis'!$L$3:$L$10110,0),MATCH(Q$5,'Bin Analysis'!$C$2:$S$2,0))," "))))) | R9: =IF($L9=" "," ",(IF($M9=FALSE," ",(IF($M9>0,INDEX('Bin Analysis'!$C$3:$S$10110,MATCH($L9,'Bin Analysis'!$L$3:$L$10110,0),MATCH(R$5,'Bin Analysis'!$C$2:$S$2,0))," "))))) | S9: =IF($L9=" "," ",(IF($M9=FALSE," ",(IF($M9>0,INDEX('Bin Analysis'!$C$3:$S$10110,MATCH($L9,'Bin Analysis'!$L$3:$L$10110,0),MATCH(S$5,'Bin Analysis'!$C$2:$S$2,0))," "))))) | T9: =Assignments!K8 | U9: =Assignments!L8 | V9: =Assignments!V8 | Z9: 0.3 to < 0.4 | AA9: =COUNTIF(N$7:N$427,"<0.4")-SUM(AA6:AA8) -> 0 | AB9: =COUNTIF(O$7:O$427,"<0.4")-SUM(AB6:AB8) -> 0 | AC9: =COUNTIF(P$7:P$427,"<0.4")-SUM(AC6:AC8) -> 0 | AD9: =COUNTIF(Q$7:Q$427,"<0.4")-SUM(AD6:AD8) -> 0 | AE9: =COUNTIF(R$7:R$427,"<0.4")-SUM(AE6:AE8) -> 0
A10: could go in | G10: =IFERROR('Data Transformation'!M8," ") | I10: Min/Max override | L10: =$G11 | M10: =IF(L10=" "," ",(IF($L10>0,INDEX('Bin Analysis'!$C$3:$S$10110,MATCH($L10,'Bin Analysis'!$L$3:$L$10110,0),MATCH(M$5,'Bin Analysis'!$C$2:$S$2,0))," "))) | N10: =IF($L10=" "," ",(IF($M10=FALSE," ",(IF($M10>0,INDEX('Bin Analysis'!$C$3:$S$10110,MATCH($L10,'Bin Analysis'!$L$3:$L$10110,0),MATCH(N$5,'Bin Analysis'!$C$2:$S$2,0))," "))))) | O10: =IF($L10=" "," ",(IF($M10=FALSE," ",(IF($M10>0,INDEX('Bin Analysis'!$C$3:$S$10110,MATCH($L10,'Bin Analysis'!$L$3:$L$10110,0),MATCH(O$5,'Bin Analysis'!$C$2:$S$2,0))," "))))) | P10: =IF($L10=" "," ",(IF($M10=FALSE," ",(IF($M10>0,INDEX('Bin Analysis'!$C$3:$S$10110,MATCH($L10,'Bin Analysis'!$L$3:$L$10110,0),MATCH(P$5,'Bin Analysis'!$C$2:$S$2,0))," "))))) | Q10: =IF($L10=" "," ",(IF($M10=FALSE," ",(IF($M10>0,INDEX('Bin Analysis'!$C$3:$S$10110,MATCH($L10,'Bin Analysis'!$L$3:$L$10110,0),MATCH(Q$5,'Bin Analysis'!$C$2:$S$2,0))," "))))) | R10: =IF($L10=" "," ",(IF($M10=FALSE," ",(IF($M10>0,INDEX('Bin Analysis'!$C$3:$S$10110,MATCH($L10,'Bin Analysis'!$L$3:$L$10110,0),MATCH(R$5,'Bin Analysis'!$C$2:$S$2,0))," "))))) | S10: =IF($L10=" "," ",(IF($M10=FALSE," ",(IF($M10>0,INDEX('Bin Analysis'!$C$3:$S$10110,MATCH($L10,'Bin Analysis'!$L$3:$L$10110,0),MATCH(S$5,'Bin Analysis'!$C$2:$S$2,0))," "))))) | T10: =Assignments!K9 | U10: =Assignments!L9 | V10: =Assignments!V9 | Z10: 0.4 to < 0.5 | AA10: =COUNTIF(N$7:N$427,"<0.5")-SUM(AA6:AA9) -> 0 | AB10: =COUNTIF(O$7:O$427,"<0.5")-SUM(AB6:AB9) -> 0 | AC10: =COUNTIF(P$7:P$427,"<0.5")-SUM(AC6:AC9) -> 0 | AD10: =COUNTIF(Q$7:Q$427,"<0.5")-SUM(AD6:AD9) -> 0 | AE10: =COUNTIF(R$7:R$427,"<0.5")-SUM(AE6:AE9) -> 0
A11: column A | G11: =IFERROR('Data Transformation'!M9," ") | I11: Minimum | L11: =$G12 | M11: =IF(L11=" "," ",(IF($L11>0,INDEX('Bin Analysis'!$C$3:$S$10110,MATCH($L11,'Bin Analysis'!$L$3:$L$10110,0),MATCH(M$5,'Bin Analysis'!$C$2:$S$2,0))," "))) | N11: =IF($L11=" "," ",(IF($M11=FALSE," ",(IF($M11>0,INDEX('Bin Analysis'!$C$3:$S$10110,MATCH($L11,'Bin Analysis'!$L$3:$L$10110,0),MATCH(N$5,'Bin Analysis'!$C$2:$S$2,0))," "))))) | O11: =IF($L11=" "," ",(IF($M11=FALSE," ",(IF($M11>0,INDEX('Bin Analysis'!$C$3:$S$10110,MATCH($L11,'Bin Analysis'!$L$3:$L$10110,0),MATCH(O$5,'Bin Analysis'!$C$2:$S$2,0))," "))))) | P11: =IF($L11=" "," ",(IF($M11=FALSE," ",(IF($M11>0,INDEX('Bin Analysis'!$C$3:$S$10110,MATCH($L11,'Bin Analysis'!$L$3:$L$10110,0),MATCH(P$5,'Bin Analysis'!$C$2:$S$2,0))," "))))) | Q11: =IF($L11=" "," ",(IF($M11=FALSE," ",(IF($M11>0,INDEX('Bin Analysis'!$C$3:$S$10110,MATCH($L11,'Bin Analysis'!$L$3:$L$10110,0),MATCH(Q$5,'Bin Analysis'!$C$2:$S$2,0))," "))))) | R11: =IF($L11=" "," ",(IF($M11=FALSE," ",(IF($M11>0,INDEX('Bin Analysis'!$C$3:$S$10110,MATCH($L11,'Bin Analysis'!$L$3:$L$10110,0),MATCH(R$5,'Bin Analysis'!$C$2:$S$2,0))," "))))) | S11: =IF($L11=" "," ",(IF($M11=FALSE," ",(IF($M11>0,INDEX('Bin Analysis'!$C$3:$S$10110,MATCH($L11,'Bin Analysis'!$L$3:$L$10110,0),MATCH(S$5,'Bin Analysis'!$C$2:$S$2,0))," "))))) | T11: =Assignments!K10 | U11: =Assignments!L10 | V11: =Assignments!V10 | Z11: 0.5 to < 0.6 | AA11: =COUNTIF(N$7:N$427,"<0.6")-SUM(AA6:AA10) -> 0 | AB11: =COUNTIF(O$7:O$427,"<0.6")-SUM(AB6:AB10) -> 0 | AC11: =COUNTIF(P$7:P$427,"<0.6")-SUM(AC6:AC10) -> 0 | AD11: =COUNTIF(Q$7:Q$427,"<0.6")-SUM(AD6:AD10) -> 0 | AE11: =COUNTIF(R$7:R$427,"<0.6")-SUM(AE6:AE10) -> 0
G12: =IFERROR('Data Transformation'!M10," ") | I12: Maximum | L12: =$G13 | M12: =IF(L12=" "," ",(IF($L12>0,INDEX('Bin Analysis'!$C$3:$S$10110,MATCH($L12,'Bin Analysis'!$L$3:$L$10110,0),MATCH(M$5,'Bin Analysis'!$C$2:$S$2,0))," "))) | N12: =IF($L12=" "," ",(IF($M12=FALSE," ",(IF($M12>0,INDEX('Bin Analysis'!$C$3:$S$10110,MATCH($L12,'Bin Analysis'!$L$3:$L$10110,0),MATCH(N$5,'Bin Analysis'!$C$2:$S$2,0))," "))))) | O12: =IF($L12=" "," ",(IF($M12=FALSE," ",(IF($M12>0,INDEX('Bin Analysis'!$C$3:$S$10110,MATCH($L12,'Bin Analysis'!$L$3:$L$10110,0),MATCH(O$5,'Bin Analysis'!$C$2:$S$2,0))," "))))) | P12: =IF($L12=" "," ",(IF($M12=FALSE," ",(IF($M12>0,INDEX('Bin Analysis'!$C$3:$S$10110,MATCH($L12,'Bin Analysis'!$L$3:$L$10110,0),MATCH(P$5,'Bin Analysis'!$C$2:$S$2,0))," "))))) | Q12: =IF($L12=" "," ",(IF($M12=FALSE," ",(IF($M12>0,INDEX('Bin Analysis'!$C$3:$S$10110,MATCH($L12,'Bin Analysis'!$L$3:$L$10110,0),MATCH(Q$5,'Bin Analysis'!$C$2:$S$2,0))," "))))) | R12: =IF($L12=" "," ",(IF($M12=FALSE," ",(IF($M12>0,INDEX('Bin Analysis'!$C$3:$S$10110,MATCH($L12,'Bin Analysis'!$L$3:$L$10110,0),MATCH(R$5,'Bin Analysis'!$C$2:$S$2,0))," "))))) | S12: =IF($L12=" "," ",(IF($M12=FALSE," ",(IF($M12>0,INDEX('Bin Analysis'!$C$3:$S$10110,MATCH($L12,'Bin Analysis'!$L$3:$L$10110,0),MATCH(S$5,'Bin Analysis'!$C$2:$S$2,0))," "))))) | T12: =Assignments!K11 | U12: =Assignments!L11 | V12: =Assignments!V11 | Z12: 0.6 to < 0.7 | AA12: =COUNTIF(N$7:N$427,"<0.7")-SUM(AA6:AA11) -> 0 | AB12: =COUNTIF(O$7:O$427,"<0.7")-SUM(AB6:AB11) -> 0 | AC12: =COUNTIF(P$7:P$427,"<0.7")-SUM(AC6:AC11) -> 0 | AD12: =COUNTIF(Q$7:Q$427,"<0.7")-SUM(AD6:AD11) -> 0 | AE12: =COUNTIF(R$7:R$427,"<0.7")-SUM(AE6:AE11) -> 0
G13: =IFERROR('Data Transformation'!M11," ") | I13: (leave blank if no override) | L13: =$G14 | M13: =IF(L13=" "," ",(IF($L13>0,INDEX('Bin Analysis'!$C$3:$S$10110,MATCH($L13,'Bin Analysis'!$L$3:$L$10110,0),MATCH(M$5,'Bin Analysis'!$C$2:$S$2,0))," "))) | N13: =IF($L13=" "," ",(IF($M13=FALSE," ",(IF($M13>0,INDEX('Bin Analysis'!$C$3:$S$10110,MATCH($L13,'Bin Analysis'!$L$3:$L$10110,0),MATCH(N$5,'Bin Analysis'!$C$2:$S$2,0))," "))))) | O13: =IF($L13=" "," ",(IF($M13=FALSE," ",(IF($M13>0,INDEX('Bin Analysis'!$C$3:$S$10110,MATCH($L13,'Bin Analysis'!$L$3:$L$10110,0),MATCH(O$5,'Bin Analysis'!$C$2:$S$2,0))," "))))) | P13: =IF($L13=" "," ",(IF($M13=FALSE," ",(IF($M13>0,INDEX('Bin Analysis'!$C$3:$S$10110,MATCH($L13,'Bin Analysis'!$L$3:$L$10110,0),MATCH(P$5,'Bin Analysis'!$C$2:$S$2,0))," "))))) | Q13: =IF($L13=" "," ",(IF($M13=FALSE," ",(IF($M13>0,INDEX('Bin Analysis'!$C$3:$S$10110,MATCH($L13,'Bin Analysis'!$L$3:$L$10110,0),MATCH(Q$5,'Bin Analysis'!$C$2:$S$2,0))," "))))) | R13: =IF($L13=" "," ",(IF($M13=FALSE," ",(IF($M13>0,INDEX('Bin Analysis'!$C$3:$S$10110,MATCH($L13,'Bin Analysis'!$L$3:$L$10110,0),MATCH(R$5,'Bin Analysis'!$C$2:$S$2,0))," "))))) | S13: =IF($L13=" "," ",(IF($M13=FALSE," ",(IF($M13>0,INDEX('Bin Analysis'!$C$3:$S$10110,MATCH($L13,'Bin Analysis'!$L$3:$L$10110,0),MATCH(S$5,'Bin Analysis'!$C$2:$S$2,0))," "))))) | T13: =Assignments!K12 | U13: =Assignments!L12 | V13: =Assignments!V12 | Z13: 0.7 to < 0.8 | AA13: =COUNTIF(N$7:N$427,"<0.8")-SUM(AA6:AA12) -> 0 | AB13: =COUNTIF(O$7:O$427,"<0.8")-SUM(AB6:AB12) -> 0 | AC13: =COUNTIF(P$7:P$427,"<0.8")-SUM(AC6:AC12) -> 0 | AD13: =COUNTIF(Q$7:Q$427,"<0.8")-SUM(AD6:AD12) -> 0 | AE13: =COUNTIF(R$7:R$427,"<0.8")-SUM(AE6:AE12) -> 0
G14: =IFERROR('Data Transformation'!M12," ") | I14: Number of values greater than the maximum | J14: =COUNTIF(D7:D8007,">"&J12) -> 0 | L14: =$G15 | M14: =IF(L14=" "," ",(IF($L14>0,INDEX('Bin Analysis'!$C$3:$S$10110,MATCH($L14,'Bin Analysis'!$L$3:$L$10110,0),MATCH(M$5,'Bin Analysis'!$C$2:$S$2,0))," "))) | N14: =IF($L14=" "," ",(IF($M14=FALSE," ",(IF($M14>0,INDEX('Bin Analysis'!$C$3:$S$10110,MATCH($L14,'Bin Analysis'!$L$3:$L$10110,0),MATCH(N$5,'Bin Analysis'!$C$2:$S$2,0))," "))))) | O14: =IF($L14=" "," ",(IF($M14=FALSE," ",(IF($M14>0,INDEX('Bin Analysis'!$C$3:$S$10110,MATCH($L14,'Bin Analysis'!$L$3:$L$10110,0),MATCH(O$5,'Bin Analysis'!$C$2:$S$2,0))," "))))) | P14: =IF($L14=" "," ",(IF($M14=FALSE," ",(IF($M14>0,INDEX('Bin Analysis'!$C$3:$S$10110,MATCH($L14,'Bin Analysis'!$L$3:$L$10110,0),MATCH(P$5,'Bin Analysis'!$C$2:$S$2,0))," "))))) | Q14: =IF($L14=" "," ",(IF($M14=FALSE," ",(IF($M14>0,INDEX('Bin Analysis'!$C$3:$S$10110,MATCH($L14,'Bin Analysis'!$L$3:$L$10110,0),MATCH(Q$5,'Bin Analysis'!$C$2:$S$2,0))," "))))) | R14: =IF($L14=" "," ",(IF($M14=FALSE," ",(IF($M14>0,INDEX('Bin Analysis'!$C$3:$S$10110,MATCH($L14,'Bin Analysis'!$L$3:$L$10110,0),MATCH(R$5,'Bin Analysis'!$C$2:$S$2,0))," "))))) | S14: =IF($L14=" "," ",(IF($M14=FALSE," ",(IF($M14>0,INDEX('Bin Analysis'!$C$3:$S$10110,MATCH($L14,'Bin Analysis'!$L$3:$L$10110,0),MATCH(S$5,'Bin Analysis'!$C$2:$S$2,0))," "))))) | T14: =Assignments!K13 | U14: =Assignments!L13 | V14: =Assignments!V13 | Z14: 0.8 to < 0.9 | AA14: =COUNTIF(N$7:N$427,"<0.9")-SUM(AA6:AA13) -> 0 | AB14: =COUNTIF(O$7:O$427,"<0.9")-SUM(AB6:AB13) -> 0 | AC14: =COUNTIF(P$7:P$427,"<0.9")-SUM(AC6:AC13) -> 0 | AD14: =COUNTIF(Q$7:Q$427,"<0.9")-SUM(AD6:AD13) -> 0 | AE14: =COUNTIF(R$7:R$427,"<0.9")-SUM(AE6:AE13) -> 0
G15: =IFERROR('Data Transformation'!M13," ") | L15: =$G16 | M15: =IF(L15=" "," ",(IF($L15>0,INDEX('Bin Analysis'!$C$3:$S$10110,MATCH($L15,'Bin Analysis'!$L$3:$L$10110,0),MATCH(M$5,'Bin Analysis'!$C$2:$S$2,0))," "))) | N15: =IF($L15=" "," ",(IF($M15=FALSE," ",(IF($M15>0,INDEX('Bin Analysis'!$C$3:$S$10110,MATCH($L15,'Bin Analysis'!$L$3:$L$10110,0),MATCH(N$5,'Bin Analysis'!$C$2:$S$2,0))," "))))) | O15: =IF($L15=" "," ",(IF($M15=FALSE," ",(IF($M15>0,INDEX('Bin Analysis'!$C$3:$S$10110,MATCH($L15,'Bin Analysis'!$L$3:$L$10110,0),MATCH(O$5,'Bin Analysis'!$C$2:$S$2,0))," "))))) | P15: =IF($L15=" "," ",(IF($M15=FALSE," ",(IF($M15>0,INDEX('Bin Analysis'!$C$3:$S$10110,MATCH($L15,'Bin Analysis'!$L$3:$L$10110,0),MATCH(P$5,'Bin Analysis'!$C$2:$S$2,0))," "))))) | Q15: =IF($L15=" "," ",(IF($M15=FALSE," ",(IF($M15>0,INDEX('Bin Analysis'!$C$3:$S$10110,MATCH($L15,'Bin Analysis'!$L$3:$L$10110,0),MATCH(Q$5,'Bin Analysis'!$C$2:$S$2,0))," "))))) | R15: =IF($L15=" "," ",(IF($M15=FALSE," ",(IF($M15>0,INDEX('Bin Analysis'!$C$3:$S$10110,MATCH($L15,'Bin Analysis'!$L$3:$L$10110,0),MATCH(R$5,'Bin Analysis'!$C$2:$S$2,0))," "))))) | S15: =IF($L15=" "," ",(IF($M15=FALSE," ",(IF($M15>0,INDEX('Bin Analysis'!$C$3:$S$10110,MATCH($L15,'Bin Analysis'!$L$3:$L$10110,0),MATCH(S$5,'Bin Analysis'!$C$2:$S$2,0))," "))))) | T15: =Assignments!K14 | U15: =Assignments!L14 | V15: =Assignments!V14 | Z15: 0.9 to 1.0 | AA15: =COUNTIF(N$7:N$427,"<1.01")-SUM(AA6:AA14) -> 0 | AB15: =COUNTIF(O$7:O$427,"<1.01")-SUM(AB6:AB14) -> 0 | AC15: =COUNTIF(P$7:P$427,"<1.01")-SUM(AC6:AC14) -> 0 | AD15: =COUNTIF(Q$7:Q$427,"<1.01")-SUM(AD6:AD14) -> 0 | AE15: =COUNTIF(R$7:R$427,"<1.01")-SUM(AE6:AE14) -> 0
G16: =IFERROR('Data Transformation'!M14," ") | I16: Backgroud signal ("Dead" value) | J16: minimum | L16: =$G17 | M16: =IF(L16=" "," ",(IF($L16>0,INDEX('Bin Analysis'!$C$3:$S$10110,MATCH($L16,'Bin Analysis'!$L$3:$L$10110,0),MATCH(M$5,'Bin Analysis'!$C$2:$S$2,0))," "))) | N16: =IF($L16=" "," ",(IF($M16=FALSE," ",(IF($M16>0,INDEX('Bin Analysis'!$C$3:$S$10110,MATCH($L16,'Bin Analysis'!$L$3:$L$10110,0),MATCH(N$5,'Bin Analysis'!$C$2:$S$2,0))," "))))) | O16: =IF($L16=" "," ",(IF($M16=FALSE," ",(IF($M16>0,INDEX('Bin Analysis'!$C$3:$S$10110,MATCH($L16,'Bin Analysis'!$L$3:$L$10110,0),MATCH(O$5,'Bin Analysis'!$C$2:$S$2,0))," "))))) | P16: =IF($L16=" "," ",(IF($M16=FALSE," ",(IF($M16>0,INDEX('Bin Analysis'!$C$3:$S$10110,MATCH($L16,'Bin Analysis'!$L$3:$L$10110,0),MATCH(P$5,'Bin Analysis'!$C$2:$S$2,0))," "))))) | Q16: =IF($L16=" "," ",(IF($M16=FALSE," ",(IF($M16>0,INDEX('Bin Analysis'!$C$3:$S$10110,MATCH($L16,'Bin Analysis'!$L$3:$L$10110,0),MATCH(Q$5,'Bin Analysis'!$C$2:$S$2,0))," "))))) | R16: =IF($L16=" "," ",(IF($M16=FALSE," ",(IF($M16>0,INDEX('Bin Analysis'!$C$3:$S$10110,MATCH($L16,'Bin Analysis'!$L$3:$L$10110,0),MATCH(R$5,'Bin Analysis'!$C$2:$S$2,0))," "))))) | S16: =IF($L16=" "," ",(IF($M16=FALSE," ",(IF($M16>0,INDEX('Bin Analysis'!$C$3:$S$10110,MATCH($L16,'Bin Analysis'!$L$3:$L$10110,0),MATCH(S$5,'Bin Analysis'!$C$2:$S$2,0))," "))))) | T16: =Assignments!K15 | U16: =Assignments!L15 | V16: =Assignments!V15 | Z16: sum | AA16: =SUM(AA6:AA15) -> 0 | AB16: =SUM(AB6:AB15) -> 0 | AC16: =SUM(AC6:AC15) -> 0 | AD16: =SUM(AD6:AD15) -> 0 | AE16: =SUM(AE6:AE15) -> 0
G17: =IFERROR('Data Transformation'!M15," ") | J17: =IF(J16="maximum",'Data Transformation'!U9,'Data Transformation'!U8) -> 1 | L17: =$G18 | M17: =IF(L17=" "," ",(IF($L17>0,INDEX('Bin Analysis'!$C$3:$S$10110,MATCH($L17,'Bin Analysis'!$L$3:$L$10110,0),MATCH(M$5,'Bin Analysis'!$C$2:$S$2,0))," "))) | N17: =IF($L17=" "," ",(IF($M17=FALSE," ",(IF($M17>0,INDEX('Bin Analysis'!$C$3:$S$10110,MATCH($L17,'Bin Analysis'!$L$3:$L$10110,0),MATCH(N$5,'Bin Analysis'!$C$2:$S$2,0))," "))))) | O17: =IF($L17=" "," ",(IF($M17=FALSE," ",(IF($M17>0,INDEX('Bin Analysis'!$C$3:$S$10110,MATCH($L17,'Bin Analysis'!$L$3:$L$10110,0),MATCH(O$5,'Bin Analysis'!$C$2:$S$2,0))," "))))) | P17: =IF($L17=" "," ",(IF($M17=FALSE," ",(IF($M17>0,INDEX('Bin Analysis'!$C$3:$S$10110,MATCH($L17,'Bin Analysis'!$L$3:$L$10110,0),MATCH(P$5,'Bin Analysis'!$C$2:$S$2,0))," "))))) | Q17: =IF($L17=" "," ",(IF($M17=FALSE," ",(IF($M17>0,INDEX('Bin Analysis'!$C$3:$S$10110,MATCH($L17,'Bin Analysis'!$L$3:$L$10110,0),MATCH(Q$5,'Bin Analysis'!$C$2:$S$2,0))," "))))) | R17: =IF($L17=" "," ",(IF($M17=FALSE," ",(IF($M17>0,INDEX('Bin Analysis'!$C$3:$S$10110,MATCH($L17,'Bin Analysis'!$L$3:$L$10110,0),MATCH(R$5,'Bin Analysis'!$C$2:$S$2,0))," "))))) | S17: =IF($L17=" "," ",(IF($M17=FALSE," ",(IF($M17>0,INDEX('Bin Analysis'!$C$3:$S$10110,MATCH($L17,'Bin Analysis'!$L$3:$L$10110,0),MATCH(S$5,'Bin Analysis'!$C$2:$S$2,0))," "))))) | T17: =Assignments!K16 | U17: =Assignments!L16 | V17: =Assignments!V16
G18: =IFERROR('Data Transformation'!M16," ") | L18: =$G19 | M18: =IF(L18=" "," ",(IF($L18>0,INDEX('Bin Analysis'!$C$3:$S$10110,MATCH($L18,'Bin Analysis'!$L$3:$L$10110,0),MATCH(M$5,'Bin Analysis'!$C$2:$S$2,0))," "))) | N18: =IF($L18=" "," ",(IF($M18=FALSE," ",(IF($M18>0,INDEX('Bin Analysis'!$C$3:$S$10110,MATCH($L18,'Bin Analysis'!$L$3:$L$10110,0),MATCH(N$5,'Bin Analysis'!$C$2:$S$2,0))," "))))) | O18: =IF($L18=" "," ",(IF($M18=FALSE," ",(IF($M18>0,INDEX('Bin Analysis'!$C$3:$S$10110,MATCH($L18,'Bin Analysis'!$L$3:$L$10110,0),MATCH(O$5,'Bin Analysis'!$C$2:$S$2,0))," "))))) | P18: =IF($L18=" "," ",(IF($M18=FALSE," ",(IF($M18>0,INDEX('Bin Analysis'!$C$3:$S$10110,MATCH($L18,'Bin Analysis'!$L$3:$L$10110,0),MATCH(P$5,'Bin Analysis'!$C$2:$S$2,0))," "))))) | Q18: =IF($L18=" "," ",(IF($M18=FALSE," ",(IF($M18>0,INDEX('Bin Analysis'!$C$3:$S$10110,MATCH($L18,'Bin Analysis'!$L$3:$L$10110,0),MATCH(Q$5,'Bin Analysis'!$C$2:$S$2,0))," "))))) | R18: =IF($L18=" "," ",(IF($M18=FALSE," ",(IF($M18>0,INDEX('Bin Analysis'!$C$3:$S$10110,MATCH($L18,'Bin Analysis'!$L$3:$L$10110,0),MATCH(R$5,'Bin Analysis'!$C$2:$S$2,0))," "))))) | S18: =IF($L18=" "," ",(IF($M18=FALSE," ",(IF($M18>0,INDEX('Bin Analysis'!$C$3:$S$10110,MATCH($L18,'Bin Analysis'!$L$3:$L$10110,0),MATCH(S$5,'Bin Analysis'!$C$2:$S$2,0))," "))))) | T18: =Assignments!K17 | U18: =Assignments!L17 | V18: =Assignments!V17
G19: =IFERROR('Data Transformation'!M17," ") | I19: Error override | L19: =$G20 | M19: =IF(L19=" "," ",(IF($L19>0,INDEX('Bin Analysis'!$C$3:$S$10110,MATCH($L19,'Bin Analysis'!$L$3:$L$10110,0),MATCH(M$5,'Bin Analysis'!$C$2:$S$2,0))," "))) | N19: =IF($L19=" "," ",(IF($M19=FALSE," ",(IF($M19>0,INDEX('Bin Analysis'!$C$3:$S$10110,MATCH($L19,'Bin Analysis'!$L$3:$L$10110,0),MATCH(N$5,'Bin Analysis'!$C$2:$S$2,0))," "))))) | O19: =IF($L19=" "," ",(IF($M19=FALSE," ",(IF($M19>0,INDEX('Bin Analysis'!$C$3:$S$10110,MATCH($L19,'Bin Analysis'!$L$3:$L$10110,0),MATCH(O$5,'Bin Analysis'!$C$2:$S$2,0))," "))))) | P19: =IF($L19=" "," ",(IF($M19=FALSE," ",(IF($M19>0,INDEX('Bin Analysis'!$C$3:$S$10110,MATCH($L19,'Bin Analysis'!$L$3:$L$10110,0),MATCH(P$5,'Bin Analysis'!$C$2:$S$2,0))," "))))) | Q19: =IF($L19=" "," ",(IF($M19=FALSE," ",(IF($M19>0,INDEX('Bin Analysis'!$C$3:$S$10110,MATCH($L19,'Bin Analysis'!$L$3:$L$10110,0),MATCH(Q$5,'Bin Analysis'!$C$2:$S$2,0))," "))))) | R19: =IF($L19=" "," ",(IF($M19=FALSE," ",(IF($M19>0,INDEX('Bin Analysis'!$C$3:$S$10110,MATCH($L19,'Bin Analysis'!$L$3:$L$10110,0),MATCH(R$5,'Bin Analysis'!$C$2:$S$2,0))," "))))) | S19: =IF($L19=" "," ",(IF($M19=FALSE," ",(IF($M19>0,INDEX('Bin Analysis'!$C$3:$S$10110,MATCH($L19,'Bin Analysis'!$L$3:$L$10110,0),MATCH(S$5,'Bin Analysis'!$C$2:$S$2,0))," "))))) | T19: =Assignments!K18 | U19: =Assignments!L18 | V19: =Assignments!V18
G20: =IFERROR('Data Transformation'!M18," ") | I20: =IF(AND(J4="yes",NOT(J19="")),"see note #3 under the 'Entering data on the Input and Summary Results worksheet' section on first page regarding log and error","leave blank if no override") -> leave blank if no override | L20: =$G21 | M20: =IF(L20=" "," ",(IF($L20>0,INDEX('Bin Analysis'!$C$3:$S$10110,MATCH($L20,'Bin Analysis'!$L$3:$L$10110,0),MATCH(M$5,'Bin Analysis'!$C$2:$S$2,0))," "))) | N20: =IF($L20=" "," ",(IF($M20=FALSE," ",(IF($M20>0,INDEX('Bin Analysis'!$C$3:$S$10110,MATCH($L20,'Bin Analysis'!$L$3:$L$10110,0),MATCH(N$5,'Bin Analysis'!$C$2:$S$2,0))," "))))) | O20: =IF($L20=" "," ",(IF($M20=FALSE," ",(IF($M20>0,INDEX('Bin Analysis'!$C$3:$S$10110,MATCH($L20,'Bin Analysis'!$L$3:$L$10110,0),MATCH(O$5,'Bin Analysis'!$C$2:$S$2,0))," "))))) | P20: =IF($L20=" "," ",(IF($M20=FALSE," ",(IF($M20>0,INDEX('Bin Analysis'!$C$3:$S$10110,MATCH($L20,'Bin Analysis'!$L$3:$L$10110,0),MATCH(P$5,'Bin Analysis'!$C$2:$S$2,0))," "))))) | Q20: =IF($L20=" "," ",(IF($M20=FALSE," ",(IF($M20>0,INDEX('Bin Analysis'!$C$3:$S$10110,MATCH($L20,'Bin Analysis'!$L$3:$L$10110,0),MATCH(Q$5,'Bin Analysis'!$C$2:$S$2,0))," "))))) | R20: =IF($L20=" "," ",(IF($M20=FALSE," ",(IF($M20>0,INDEX('Bin Analysis'!$C$3:$S$10110,MATCH($L20,'Bin Analysis'!$L$3:$L$10110,0),MATCH(R$5,'Bin Analysis'!$C$2:$S$2,0))," "))))) | S20: =IF($L20=" "," ",(IF($M20=FALSE," ",(IF($M20>0,INDEX('Bin Analysis'!$C$3:$S$10110,MATCH($L20,'Bin Analysis'!$L$3:$L$10110,0),MATCH(S$5,'Bin Analysis'!$C$2:$S$2,0))," "))))) | T20: =Assignments!K19 | U20: =Assignments!L19 | V20: =Assignments!V19
G21: =IFERROR('Data Transformation'!M19," ") | L21: =$G22 | M21: =IF(L21=" "," ",(IF($L21>0,INDEX('Bin Analysis'!$C$3:$S$10110,MATCH($L21,'Bin Analysis'!$L$3:$L$10110,0),MATCH(M$5,'Bin Analysis'!$C$2:$S$2,0))," "))) | N21: =IF($L21=" "," ",(IF($M21=FALSE," ",(IF($M21>0,INDEX('Bin Analysis'!$C$3:$S$10110,MATCH($L21,'Bin Analysis'!$L$3:$L$10110,0),MATCH(N$5,'Bin Analysis'!$C$2:$S$2,0))," "))))) | O21: =IF($L21=" "," ",(IF($M21=FALSE," ",(IF($M21>0,INDEX('Bin Analysis'!$C$3:$S$10110,MATCH($L21,'Bin Analysis'!$L$3:$L$10110,0),MATCH(O$5,'Bin Analysis'!$C$2:$S$2,0))," "))))) | P21: =IF($L21=" "," ",(IF($M21=FALSE," ",(IF($M21>0,INDEX('Bin Analysis'!$C$3:$S$10110,MATCH($L21,'Bin Analysis'!$L$3:$L$10110,0),MATCH(P$5,'Bin Analysis'!$C$2:$S$2,0))," "))))) | Q21: =IF($L21=" "," ",(IF($M21=FALSE," ",(IF($M21>0,INDEX('Bin Analysis'!$C$3:$S$10110,MATCH($L21,'Bin Analysis'!$L$3:$L$10110,0),MATCH(Q$5,'Bin Analysis'!$C$2:$S$2,0))," "))))) | R21: =IF($L21=" "," ",(IF($M21=FALSE," ",(IF($M21>0,INDEX('Bin Analysis'!$C$3:$S$10110,MATCH($L21,'Bin Analysis'!$L$3:$L$10110,0),MATCH(R$5,'Bin Analysis'!$C$2:$S$2,0))," "))))) | S21: =IF($L21=" "," ",(IF($M21=FALSE," ",(IF($M21>0,INDEX('Bin Analysis'!$C$3:$S$10110,MATCH($L21,'Bin Analysis'!$L$3:$L$10110,0),MATCH(S$5,'Bin Analysis'!$C$2:$S$2,0))," "))))) | T21: =Assignments!K20 | U21: =Assignments!L20 | V21: =Assignments!V20
G22: =IFERROR('Data Transformation'!M20," ") | I22: Recommended number of bins | J22: ='Data Transformation'!R23 -> #DIV/0! | L22: =$G23 | M22: =IF(L22=" "," ",(IF($L22>0,INDEX('Bin Analysis'!$C$3:$S$10110,MATCH($L22,'Bin Analysis'!$L$3:$L$10110,0),MATCH(M$5,'Bin Analysis'!$C$2:$S$2,0))," "))) | N22: =IF($L22=" "," ",(IF($M22=FALSE," ",(IF($M22>0,INDEX('Bin Analysis'!$C$3:$S$10110,MATCH($L22,'Bin Analysis'!$L$3:$L$10110,0),MATCH(N$5,'Bin Analysis'!$C$2:$S$2,0))," "))))) | O22: =IF($L22=" "," ",(IF($M22=FALSE," ",(IF($M22>0,INDEX('Bin Analysis'!$C$3:$S$10110,MATCH($L22,'Bin Analysis'!$L$3:$L$10110,0),MATCH(O$5,'Bin Analysis'!$C$2:$S$2,0))," "))))) | P22: =IF($L22=" "," ",(IF($M22=FALSE," ",(IF($M22>0,INDEX('Bin Analysis'!$C$3:$S$10110,MATCH($L22,'Bin Analysis'!$L$3:$L$10110,0),MATCH(P$5,'Bin Analysis'!$C$2:$S$2,0))," "))))) | Q22: =IF($L22=" "," ",(IF($M22=FALSE," ",(IF($M22>0,INDEX('Bin Analysis'!$C$3:$S$10110,MATCH($L22,'Bin Analysis'!$L$3:$L$10110,0),MATCH(Q$5,'Bin Analysis'!$C$2:$S$2,0))," "))))) | R22: =IF($L22=" "," ",(IF($M22=FALSE," ",(IF($M22>0,INDEX('Bin Analysis'!$C$3:$S$10110,MATCH($L22,'Bin Analysis'!$L$3:$L$10110,0),MATCH(R$5,'Bin Analysis'!$C$2:$S$2,0))," "))))) | S22: =IF($L22=" "," ",(IF($M22=FALSE," ",(IF($M22>0,INDEX('Bin Analysis'!$C$3:$S$10110,MATCH($L22,'Bin Analysis'!$L$3:$L$10110,0),MATCH(S$5,'Bin Analysis'!$C$2:$S$2,0))," "))))) | T22: =Assignments!K21 | U22: =Assignments!L21 | V22: =Assignments!V21
G23: =IFERROR('Data Transformation'!M21," ") | I23: Number of bins override | L23: =$G24 | M23: =IF(L23=" "," ",(IF($L23>0,INDEX('Bin Analysis'!$C$3:$S$10110,MATCH($L23,'Bin Analysis'!$L$3:$L$10110,0),MATCH(M$5,'Bin Analysis'!$C$2:$S$2,0))," "))) | N23: =IF($L23=" "," ",(IF($M23=FALSE," ",(IF($M23>0,INDEX('Bin Analysis'!$C$3:$S$10110,MATCH($L23,'Bin Analysis'!$L$3:$L$10110,0),MATCH(N$5,'Bin Analysis'!$C$2:$S$2,0))," "))))) | O23: =IF($L23=" "," ",(IF($M23=FALSE," ",(IF($M23>0,INDEX('Bin Analysis'!$C$3:$S$10110,MATCH($L23,'Bin Analysis'!$L$3:$L$10110,0),MATCH(O$5,'Bin Analysis'!$C$2:$S$2,0))," "))))) | P23: =IF($L23=" "," ",(IF($M23=FALSE," ",(IF($M23>0,INDEX('Bin Analysis'!$C$3:$S$10110,MATCH($L23,'Bin Analysis'!$L$3:$L$10110,0),MATCH(P$5,'Bin Analysis'!$C$2:$S$2,0))," "))))) | Q23: =IF($L23=" "," ",(IF($M23=FALSE," ",(IF($M23>0,INDEX('Bin Analysis'!$C$3:$S$10110,MATCH($L23,'Bin Analysis'!$L$3:$L$10110,0),MATCH(Q$5,'Bin Analysis'!$C$2:$S$2,0))," "))))) | R23: =IF($L23=" "," ",(IF($M23=FALSE," ",(IF($M23>0,INDEX('Bin Analysis'!$C$3:$S$10110,MATCH($L23,'Bin Analysis'!$L$3:$L$10110,0),MATCH(R$5,'Bin Analysis'!$C$2:$S$2,0))," "))))) | S23: =IF($L23=" "," ",(IF($M23=FALSE," ",(IF($M23>0,INDEX('Bin Analysis'!$C$3:$S$10110,MATCH($L23,'Bin Analysis'!$L$3:$L$10110,0),MATCH(S$5,'Bin Analysis'!$C$2:$S$2,0))," "))))) | T23: =Assignments!K22 | U23: =Assignments!L22 | V23: =Assignments!V22
G24: =IFERROR('Data Transformation'!M22," ") | I24: (leave blank if no override) | L24: =$G25 | M24: =IF(L24=" "," ",(IF($L24>0,INDEX('Bin Analysis'!$C$3:$S$10110,MATCH($L24,'Bin Analysis'!$L$3:$L$10110,0),MATCH(M$5,'Bin Analysis'!$C$2:$S$2,0))," "))) | N24: =IF($L24=" "," ",(IF($M24=FALSE," ",(IF($M24>0,INDEX('Bin Analysis'!$C$3:$S$10110,MATCH($L24,'Bin Analysis'!$L$3:$L$10110,0),MATCH(N$5,'Bin Analysis'!$C$2:$S$2,0))," "))))) | O24: =IF($L24=" "," ",(IF($M24=FALSE," ",(IF($M24>0,INDEX('Bin Analysis'!$C$3:$S$10110,MATCH($L24,'Bin Analysis'!$L$3:$L$10110,0),MATCH(O$5,'Bin Analysis'!$C$2:$S$2,0))," "))))) | P24: =IF($L24=" "," ",(IF($M24=FALSE," ",(IF($M24>0,INDEX('Bin Analysis'!$C$3:$S$10110,MATCH($L24,'Bin Analysis'!$L$3:$L$10110,0),MATCH(P$5,'Bin Analysis'!$C$2:$S$2,0))," "))))) | Q24: =IF($L24=" "," ",(IF($M24=FALSE," ",(IF($M24>0,INDEX('Bin Analysis'!$C$3:$S$10110,MATCH($L24,'Bin Analysis'!$L$3:$L$10110,0),MATCH(Q$5,'Bin Analysis'!$C$2:$S$2,0))," "))))) | R24: =IF($L24=" "," ",(IF($M24=FALSE," ",(IF($M24>0,INDEX('Bin Analysis'!$C$3:$S$10110,MATCH($L24,'Bin Analysis'!$L$3:$L$10110,0),MATCH(R$5,'Bin Analysis'!$C$2:$S$2,0))," "))))) | S24: =IF($L24=" "," ",(IF($M24=FALSE," ",(IF($M24>0,INDEX('Bin Analysis'!$C$3:$S$10110,MATCH($L24,'Bin Analysis'!$L$3:$L$10110,0),MATCH(S$5,'Bin Analysis'!$C$2:$S$2,0))," "))))) | T24: =Assignments!K23 | U24: =Assignments!L23 | V24: =Assignments!V23
G25: =IFERROR('Data Transformation'!M23," ") | I25: Rheostate/toggle bin width | J25: ='Data Transformation'!R25 -> #DIV/0! | L25: =$G26 | M25: =IF(L25=" "," ",(IF($L25>0,INDEX('Bin Analysis'!$C$3:$S$10110,MATCH($L25,'Bin Analysis'!$L$3:$L$10110,0),MATCH(M$5,'Bin Analysis'!$C$2:$S$2,0))," "))) | N25: =IF($L25=" "," ",(IF($M25=FALSE," ",(IF($M25>0,INDEX('Bin Analysis'!$C$3:$S$10110,MATCH($L25,'Bin Analysis'!$L$3:$L$10110,0),MATCH(N$5,'Bin Analysis'!$C$2:$S$2,0))," "))))) | O25: =IF($L25=" "," ",(IF($M25=FALSE," ",(IF($M25>0,INDEX('Bin Analysis'!$C$3:$S$10110,MATCH($L25,'Bin Analysis'!$L$3:$L$10110,0),MATCH(O$5,'Bin Analysis'!$C$2:$S$2,0))," "))))) | P25: =IF($L25=" "," ",(IF($M25=FALSE," ",(IF($M25>0,INDEX('Bin Analysis'!$C$3:$S$10110,MATCH($L25,'Bin Analysis'!$L$3:$L$10110,0),MATCH(P$5,'Bin Analysis'!$C$2:$S$2,0))," "))))) | Q25: =IF($L25=" "," ",(IF($M25=FALSE," ",(IF($M25>0,INDEX('Bin Analysis'!$C$3:$S$10110,MATCH($L25,'Bin Analysis'!$L$3:$L$10110,0),MATCH(Q$5,'Bin Analysis'!$C$2:$S$2,0))," "))))) | R25: =IF($L25=" "," ",(IF($M25=FALSE," ",(IF($M25>0,INDEX('Bin Analysis'!$C$3:$S$10110,MATCH($L25,'Bin Analysis'!$L$3:$L$10110,0),MATCH(R$5,'Bin Analysis'!$C$2:$S$2,0))," "))))) | S25: =IF($L25=" "," ",(IF($M25=FALSE," ",(IF($M25>0,INDEX('Bin Analysis'!$C$3:$S$10110,MATCH($L25,'Bin Analysis'!$L$3:$L$10110,0),MATCH(S$5,'Bin Analysis'!$C$2:$S$2,0))," "))))) | T25: =Assignments!K24 | U25: =Assignments!L24 | V25: =Assignments!V24
G26: =IFERROR('Data Transformation'!M24," ") | L26: =$G27 | M26: =IF(L26=" "," ",(IF($L26>0,INDEX('Bin Analysis'!$C$3:$S$10110,MATCH($L26,'Bin Analysis'!$L$3:$L$10110,0),MATCH(M$5,'Bin Analysis'!$C$2:$S$2,0))," "))) | N26: =IF($L26=" "," ",(IF($M26=FALSE," ",(IF($M26>0,INDEX('Bin Analysis'!$C$3:$S$10110,MATCH($L26,'Bin Analysis'!$L$3:$L$10110,0),MATCH(N$5,'Bin Analysis'!$C$2:$S$2,0))," "))))) | O26: =IF($L26=" "," ",(IF($M26=FALSE," ",(IF($M26>0,INDEX('Bin Analysis'!$C$3:$S$10110,MATCH($L26,'Bin Analysis'!$L$3:$L$10110,0),MATCH(O$5,'Bin Analysis'!$C$2:$S$2,0))," "))))) | P26: =IF($L26=" "," ",(IF($M26=FALSE," ",(IF($M26>0,INDEX('Bin Analysis'!$C$3:$S$10110,MATCH($L26,'Bin Analysis'!$L$3:$L$10110,0),MATCH(P$5,'Bin Analysis'!$C$2:$S$2,0))," "))))) | Q26: =IF($L26=" "," ",(IF($M26=FALSE," ",(IF($M26>0,INDEX('Bin Analysis'!$C$3:$S$10110,MATCH($L26,'Bin Analysis'!$L$3:$L$10110,0),MATCH(Q$5,'Bin Analysis'!$C$2:$S$2,0))," "))))) | R26: =IF($L26=" "," ",(IF($M26=FALSE," ",(IF($M26>0,INDEX('Bin Analysis'!$C$3:$S$10110,MATCH($L26,'Bin Analysis'!$L$3:$L$10110,0),MATCH(R$5,'Bin Analysis'!$C$2:$S$2,0))," "))))) | S26: =IF($L26=" "," ",(IF($M26=FALSE," ",(IF($M26>0,INDEX('Bin Analysis'!$C$3:$S$10110,MATCH($L26,'Bin Analysis'!$L$3:$L$10110,0),MATCH(S$5,'Bin Analysis'!$C$2:$S$2,0))," "))))) | T26: =Assignments!K25 | U26: =Assignments!L25 | V26: =Assignments!V25
G27: =IFERROR('Data Transformation'!M25," ") | I27: Neutral Bin size override | L27: =$G28 | M27: =IF(L27=" "," ",(IF($L27>0,INDEX('Bin Analysis'!$C$3:$S$10110,MATCH($L27,'Bin Analysis'!$L$3:$L$10110,0),MATCH(M$5,'Bin Analysis'!$C$2:$S$2,0))," "))) | N27: =IF($L27=" "," ",(IF($M27=FALSE," ",(IF($M27>0,INDEX('Bin Analysis'!$C$3:$S$10110,MATCH($L27,'Bin Analysis'!$L$3:$L$10110,0),MATCH(N$5,'Bin Analysis'!$C$2:$S$2,0))," "))))) | O27: =IF($L27=" "," ",(IF($M27=FALSE," ",(IF($M27>0,INDEX('Bin Analysis'!$C$3:$S$10110,MATCH($L27,'Bin Analysis'!$L$3:$L$10110,0),MATCH(O$5,'Bin Analysis'!$C$2:$S$2,0))," "))))) | P27: =IF($L27=" "," ",(IF($M27=FALSE," ",(IF($M27>0,INDEX('Bin Analysis'!$C$3:$S$10110,MATCH($L27,'Bin Analysis'!$L$3:$L$10110,0),MATCH(P$5,'Bin Analysis'!$C$2:$S$2,0))," "))))) | Q27: =IF($L27=" "," ",(IF($M27=FALSE," ",(IF($M27>0,INDEX('Bin Analysis'!$C$3:$S$10110,MATCH($L27,'Bin Analysis'!$L$3:$L$10110,0),MATCH(Q$5,'Bin Analysis'!$C$2:$S$2,0))," "))))) | R27: =IF($L27=" "," ",(IF($M27=FALSE," ",(IF($M27>0,INDEX('Bin Analysis'!$C$3:$S$10110,MATCH($L27,'Bin Analysis'!$L$3:$L$10110,0),MATCH(R$5,'Bin Analysis'!$C$2:$S$2,0))," "))))) | S27: =IF($L27=" "," ",(IF($M27=FALSE," ",(IF($M27>0,INDEX('Bin Analysis'!$C$3:$S$10110,MATCH($L27,'Bin Analysis'!$L$3:$L$10110,0),MATCH(S$5,'Bin Analysis'!$C$2:$S$2,0))," "))))) | T27: =Assignments!K26 | U27: =Assignments!L26 | V27: =Assignments!V26
G28: =IFERROR('Data Transformation'!M26," ") | I28: Neutral bin size | J28: ='Data Transformation'!W25 -> #DIV/0! | L28: =$G29 | M28: =IF(L28=" "," ",(IF($L28>0,INDEX('Bin Analysis'!$C$3:$S$10110,MATCH($L28,'Bin Analysis'!$L$3:$L$10110,0),MATCH(M$5,'Bin Analysis'!$C$2:$S$2,0))," "))) | N28: =IF($L28=" "," ",(IF($M28=FALSE," ",(IF($M28>0,INDEX('Bin Analysis'!$C$3:$S$10110,MATCH($L28,'Bin Analysis'!$L$3:$L$10110,0),MATCH(N$5,'Bin Analysis'!$C$2:$S$2,0))," "))))) | O28: =IF($L28=" "," ",(IF($M28=FALSE," ",(IF($M28>0,INDEX('Bin Analysis'!$C$3:$S$10110,MATCH($L28,'Bin Analysis'!$L$3:$L$10110,0),MATCH(O$5,'Bin Analysis'!$C$2:$S$2,0))," "))))) | P28: =IF($L28=" "," ",(IF($M28=FALSE," ",(IF($M28>0,INDEX('Bin Analysis'!$C$3:$S$10110,MATCH($L28,'Bin Analysis'!$L$3:$L$10110,0),MATCH(P$5,'Bin Analysis'!$C$2:$S$2,0))," "))))) | Q28: =IF($L28=" "," ",(IF($M28=FALSE," ",(IF($M28>0,INDEX('Bin Analysis'!$C$3:$S$10110,MATCH($L28,'Bin Analysis'!$L$3:$L$10110,0),MATCH(Q$5,'Bin Analysis'!$C$2:$S$2,0))," "))))) | R28: =IF($L28=" "," ",(IF($M28=FALSE," ",(IF($M28>0,INDEX('Bin Analysis'!$C$3:$S$10110,MATCH($L28,'Bin Analysis'!$L$3:$L$10110,0),MATCH(R$5,'Bin Analysis'!$C$2:$S$2,0))," "))))) | S28: =IF($L28=" "," ",(IF($M28=FALSE," ",(IF($M28>0,INDEX('Bin Analysis'!$C$3:$S$10110,MATCH($L28,'Bin Analysis'!$L$3:$L$10110,0),MATCH(S$5,'Bin Analysis'!$C$2:$S$2,0))," "))))) | T28: =Assignments!K27 | U28: =Assignments!L27 | V28: =Assignments!V27
G29: =IFERROR('Data Transformation'!M27," ") | L29: =$G30 | M29: =IF(L29=" "," ",(IF($L29>0,INDEX('Bin Analysis'!$C$3:$S$10110,MATCH($L29,'Bin Analysis'!$L$3:$L$10110,0),MATCH(M$5,'Bin Analysis'!$C$2:$S$2,0))," "))) | N29: =IF($L29=" "," ",(IF($M29=FALSE," ",(IF($M29>0,INDEX('Bin Analysis'!$C$3:$S$10110,MATCH($L29,'Bin Analysis'!$L$3:$L$10110,0),MATCH(N$5,'Bin Analysis'!$C$2:$S$2,0))," "))))) | O29: =IF($L29=" "," ",(IF($M29=FALSE," ",(IF($M29>0,INDEX('Bin Analysis'!$C$3:$S$10110,MATCH($L29,'Bin Analysis'!$L$3:$L$10110,0),MATCH(O$5,'Bin Analysis'!$C$2:$S$2,0))," "))))) | P29: =IF($L29=" "," ",(IF($M29=FALSE," ",(IF($M29>0,INDEX('Bin Analysis'!$C$3:$S$10110,MATCH($L29,'Bin Analysis'!$L$3:$L$10110,0),MATCH(P$5,'Bin Analysis'!$C$2:$S$2,0))," "))))) | Q29: =IF($L29=" "," ",(IF($M29=FALSE," ",(IF($M29>0,INDEX('Bin Analysis'!$C$3:$S$10110,MATCH($L29,'Bin Analysis'!$L$3:$L$10110,0),MATCH(Q$5,'Bin Analysis'!$C$2:$S$2,0))," "))))) | R29: =IF($L29=" "," ",(IF($M29=FALSE," ",(IF($M29>0,INDEX('Bin Analysis'!$C$3:$S$10110,MATCH($L29,'Bin Analysis'!$L$3:$L$10110,0),MATCH(R$5,'Bin Analysis'!$C$2:$S$2,0))," "))))) | S29: =IF($L29=" "," ",(IF($M29=FALSE," ",(IF($M29>0,INDEX('Bin Analysis'!$C$3:$S$10110,MATCH($L29,'Bin Analysis'!$L$3:$L$10110,0),MATCH(S$5,'Bin Analysis'!$C$2:$S$2,0))," "))))) | T29: =Assignments!K28 | U29: =Assignments!L28 | V29: =Assignments!V28
G30: =IFERROR('Data Transformation'!M28," ") | I30: Enhancing Score assignment | L30: =$G31 | M30: =IF(L30=" "," ",(IF($L30>0,INDEX('Bin Analysis'!$C$3:$S$10110,MATCH($L30,'Bin Analysis'!$L$3:$L$10110,0),MATCH(M$5,'Bin Analysis'!$C$2:$S$2,0))," "))) | N30: =IF($L30=" "," ",(IF($M30=FALSE," ",(IF($M30>0,INDEX('Bin Analysis'!$C$3:$S$10110,MATCH($L30,'Bin Analysis'!$L$3:$L$10110,0),MATCH(N$5,'Bin Analysis'!$C$2:$S$2,0))," "))))) | O30: =IF($L30=" "," ",(IF($M30=FALSE," ",(IF($M30>0,INDEX('Bin Analysis'!$C$3:$S$10110,MATCH($L30,'Bin Analysis'!$L$3:$L$10110,0),MATCH(O$5,'Bin Analysis'!$C$2:$S$2,0))," "))))) | P30: =IF($L30=" "," ",(IF($M30=FALSE," ",(IF($M30>0,INDEX('Bin Analysis'!$C$3:$S$10110,MATCH($L30,'Bin Analysis'!$L$3:$L$10110,0),MATCH(P$5,'Bin Analysis'!$C$2:$S$2,0))," "))))) | Q30: =IF($L30=" "," ",(IF($M30=FALSE," ",(IF($M30>0,INDEX('Bin Analysis'!$C$3:$S$10110,MATCH($L30,'Bin Analysis'!$L$3:$L$10110,0),MATCH(Q$5,'Bin Analysis'!$C$2:$S$2,0))," "))))) | R30: =IF($L30=" "," ",(IF($M30=FALSE," ",(IF($M30>0,INDEX('Bin Analysis'!$C$3:$S$10110,MATCH($L30,'Bin Analysis'!$L$3:$L$10110,0),MATCH(R$5,'Bin Analysis'!$C$2:$S$2,0))," "))))) | S30: =IF($L30=" "," ",(IF($M30=FALSE," ",(IF($M30>0,INDEX('Bin Analysis'!$C$3:$S$10110,MATCH($L30,'Bin Analysis'!$L$3:$L$10110,0),MATCH(S$5,'Bin Analysis'!$C$2:$S$2,0))," "))))) | T30: =Assignments!K29 | U30: =Assignments!L29 | V30: =Assignments!V29
G31: =IFERROR('Data Transformation'!M29," ") | I31: Default Enhancing Score assignment | J31: 0.8 | L31: =$G32 | M31: =IF(L31=" "," ",(IF($L31>0,INDEX('Bin Analysis'!$C$3:$S$10110,MATCH($L31,'Bin Analysis'!$L$3:$L$10110,0),MATCH(M$5,'Bin Analysis'!$C$2:$S$2,0))," "))) | N31: =IF($L31=" "," ",(IF($M31=FALSE," ",(IF($M31>0,INDEX('Bin Analysis'!$C$3:$S$10110,MATCH($L31,'Bin Analysis'!$L$3:$L$10110,0),MATCH(N$5,'Bin Analysis'!$C$2:$S$2,0))," "))))) | O31: =IF($L31=" "," ",(IF($M31=FALSE," ",(IF($M31>0,INDEX('Bin Analysis'!$C$3:$S$10110,MATCH($L31,'Bin Analysis'!$L$3:$L$10110,0),MATCH(O$5,'Bin Analysis'!$C$2:$S$2,0))," "))))) | P31: =IF($L31=" "," ",(IF($M31=FALSE," ",(IF($M31>0,INDEX('Bin Analysis'!$C$3:$S$10110,MATCH($L31,'Bin Analysis'!$L$3:$L$10110,0),MATCH(P$5,'Bin Analysis'!$C$2:$S$2,0))," "))))) | Q31: =IF($L31=" "," ",(IF($M31=FALSE," ",(IF($M31>0,INDEX('Bin Analysis'!$C$3:$S$10110,MATCH($L31,'Bin Analysis'!$L$3:$L$10110,0),MATCH(Q$5,'Bin Analysis'!$C$2:$S$2,0))," "))))) | R31: =IF($L31=" "," ",(IF($M31=FALSE," ",(IF($M31>0,INDEX('Bin Analysis'!$C$3:$S$10110,MATCH($L31,'Bin Analysis'!$L$3:$L$10110,0),MATCH(R$5,'Bin Analysis'!$C$2:$S$2,0))," "))))) | S31: =IF($L31=" "," ",(IF($M31=FALSE," ",(IF($M31>0,INDEX('Bin Analysis'!$C$3:$S$10110,MATCH($L31,'Bin Analysis'!$L$3:$L$10110,0),MATCH(S$5,'Bin Analysis'!$C$2:$S$2,0))," "))))) | T31: =Assignments!K30 | U31: =Assignments!L30 | V31: =Assignments!V30
G32: =IFERROR('Data Transformation'!M30," ") | L32: =$G33 | M32: =IF(L32=" "," ",(IF($L32>0,INDEX('Bin Analysis'!$C$3:$S$10110,MATCH($L32,'Bin Analysis'!$L$3:$L$10110,0),MATCH(M$5,'Bin Analysis'!$C$2:$S$2,0))," "))) | N32: =IF($L32=" "," ",(IF($M32=FALSE," ",(IF($M32>0,INDEX('Bin Analysis'!$C$3:$S$10110,MATCH($L32,'Bin Analysis'!$L$3:$L$10110,0),MATCH(N$5,'Bin Analysis'!$C$2:$S$2,0))," "))))) | O32: =IF($L32=" "," ",(IF($M32=FALSE," ",(IF($M32>0,INDEX('Bin Analysis'!$C$3:$S$10110,MATCH($L32,'Bin Analysis'!$L$3:$L$10110,0),MATCH(O$5,'Bin Analysis'!$C$2:$S$2,0))," "))))) | P32: =IF($L32=" "," ",(IF($M32=FALSE," ",(IF($M32>0,INDEX('Bin Analysis'!$C$3:$S$10110,MATCH($L32,'Bin Analysis'!$L$3:$L$10110,0),MATCH(P$5,'Bin Analysis'!$C$2:$S$2,0))," "))))) | Q32: =IF($L32=" "," ",(IF($M32=FALSE," ",(IF($M32>0,INDEX('Bin Analysis'!$C$3:$S$10110,MATCH($L32,'Bin Analysis'!$L$3:$L$10110,0),MATCH(Q$5,'Bin Analysis'!$C$2:$S$2,0))," "))))) | R32: =IF($L32=" "," ",(IF($M32=FALSE," ",(IF($M32>0,INDEX('Bin Analysis'!$C$3:$S$10110,MATCH($L32,'Bin Analysis'!$L$3:$L$10110,0),MATCH(R$5,'Bin Analysis'!$C$2:$S$2,0))," "))))) | S32: =IF($L32=" "," ",(IF($M32=FALSE," ",(IF($M32>0,INDEX('Bin Analysis'!$C$3:$S$10110,MATCH($L32,'Bin Analysis'!$L$3:$L$10110,0),MATCH(S$5,'Bin Analysis'!$C$2:$S$2,0))," "))))) | T32: =Assignments!K31 | U32: =Assignments!L31 | V32: =Assignments!V31
G33: =IFERROR('Data Transformation'!M31," ") | I33: Neutral Score assignment | L33: =$G34 | M33: =IF(L33=" "," ",(IF($L33>0,INDEX('Bin Analysis'!$C$3:$S$10110,MATCH($L33,'Bin Analysis'!$L$3:$L$10110,0),MATCH(M$5,'Bin Analysis'!$C$2:$S$2,0))," "))) | N33: =IF($L33=" "," ",(IF($M33=FALSE," ",(IF($M33>0,INDEX('Bin Analysis'!$C$3:$S$10110,MATCH($L33,'Bin Analysis'!$L$3:$L$10110,0),MATCH(N$5,'Bin Analysis'!$C$2:$S$2,0))," "))))) | O33: =IF($L33=" "," ",(IF($M33=FALSE," ",(IF($M33>0,INDEX('Bin Analysis'!$C$3:$S$10110,MATCH($L33,'Bin Analysis'!$L$3:$L$10110,0),MATCH(O$5,'Bin Analysis'!$C$2:$S$2,0))," "))))) | P33: =IF($L33=" "," ",(IF($M33=FALSE," ",(IF($M33>0,INDEX('Bin Analysis'!$C$3:$S$10110,MATCH($L33,'Bin Analysis'!$L$3:$L$10110,0),MATCH(P$5,'Bin Analysis'!$C$2:$S$2,0))," "))))) | Q33: =IF($L33=" "," ",(IF($M33=FALSE," ",(IF($M33>0,INDEX('Bin Analysis'!$C$3:$S$10110,MATCH($L33,'Bin Analysis'!$L$3:$L$10110,0),MATCH(Q$5,'Bin Analysis'!$C$2:$S$2,0))," "))))) | R33: =IF($L33=" "," ",(IF($M33=FALSE," ",(IF($M33>0,INDEX('Bin Analysis'!$C$3:$S$10110,MATCH($L33,'Bin Analysis'!$L$3:$L$10110,0),MATCH(R$5,'Bin Analysis'!$C$2:$S$2,0))," "))))) | S33: =IF($L33=" "," ",(IF($M33=FALSE," ",(IF($M33>0,INDEX('Bin Analysis'!$C$3:$S$10110,MATCH($L33,'Bin Analysis'!$L$3:$L$10110,0),MATCH(S$5,'Bin Analysis'!$C$2:$S$2,0))," "))))) | T33: =Assignments!K32 | U33: =Assignments!L32 | V33: =Assignments!V32
G34: =IFERROR('Data Transformation'!M32," ") | I34: Default Neutral Score assignment | J34: 0.7 | L34: =$G35 | M34: =IF(L34=" "," ",(IF($L34>0,INDEX('Bin Analysis'!$C$3:$S$10110,MATCH($L34,'Bin Analysis'!$L$3:$L$10110,0),MATCH(M$5,'Bin Analysis'!$C$2:$S$2,0))," "))) | N34: =IF($L34=" "," ",(IF($M34=FALSE," ",(IF($M34>0,INDEX('Bin Analysis'!$C$3:$S$10110,MATCH($L34,'Bin Analysis'!$L$3:$L$10110,0),MATCH(N$5,'Bin Analysis'!$C$2:$S$2,0))," "))))) | O34: =IF($L34=" "," ",(IF($M34=FALSE," ",(IF($M34>0,INDEX('Bin Analysis'!$C$3:$S$10110,MATCH($L34,'Bin Analysis'!$L$3:$L$10110,0),MATCH(O$5,'Bin Analysis'!$C$2:$S$2,0))," "))))) | P34: =IF($L34=" "," ",(IF($M34=FALSE," ",(IF($M34>0,INDEX('Bin Analysis'!$C$3:$S$10110,MATCH($L34,'Bin Analysis'!$L$3:$L$10110,0),MATCH(P$5,'Bin Analysis'!$C$2:$S$2,0))," "))))) | Q34: =IF($L34=" "," ",(IF($M34=FALSE," ",(IF($M34>0,INDEX('Bin Analysis'!$C$3:$S$10110,MATCH($L34,'Bin Analysis'!$L$3:$L$10110,0),MATCH(Q$5,'Bin Analysis'!$C$2:$S$2,0))," "))))) | R34: =IF($L34=" "," ",(IF($M34=FALSE," ",(IF($M34>0,INDEX('Bin Analysis'!$C$3:$S$10110,MATCH($L34,'Bin Analysis'!$L$3:$L$10110,0),MATCH(R$5,'Bin Analysis'!$C$2:$S$2,0))," "))))) | S34: =IF($L34=" "," ",(IF($M34=FALSE," ",(IF($M34>0,INDEX('Bin Analysis'!$C$3:$S$10110,MATCH($L34,'Bin Analysis'!$L$3:$L$10110,0),MATCH(S$5,'Bin Analysis'!$C$2:$S$2,0))," "))))) | T34: =Assignments!K33 | U34: =Assignments!L33 | V34: =Assignments!V33
G35: =IFERROR('Data Transformation'!M33," ") | L35: =$G36 | M35: =IF(L35=" "," ",(IF($L35>0,INDEX('Bin Analysis'!$C$3:$S$10110,MATCH($L35,'Bin Analysis'!$L$3:$L$10110,0),MATCH(M$5,'Bin Analysis'!$C$2:$S$2,0))," "))) | N35: =IF($L35=" "," ",(IF($M35=FALSE," ",(IF($M35>0,INDEX('Bin Analysis'!$C$3:$S$10110,MATCH($L35,'Bin Analysis'!$L$3:$L$10110,0),MATCH(N$5,'Bin Analysis'!$C$2:$S$2,0))," "))))) | O35: =IF($L35=" "," ",(IF($M35=FALSE," ",(IF($M35>0,INDEX('Bin Analysis'!$C$3:$S$10110,MATCH($L35,'Bin Analysis'!$L$3:$L$10110,0),MATCH(O$5,'Bin Analysis'!$C$2:$S$2,0))," "))))) | P35: =IF($L35=" "," ",(IF($M35=FALSE," ",(IF($M35>0,INDEX('Bin Analysis'!$C$3:$S$10110,MATCH($L35,'Bin Analysis'!$L$3:$L$10110,0),MATCH(P$5,'Bin Analysis'!$C$2:$S$2,0))," "))))) | Q35: =IF($L35=" "," ",(IF($M35=FALSE," ",(IF($M35>0,INDEX('Bin Analysis'!$C$3:$S$10110,MATCH($L35,'Bin Analysis'!$L$3:$L$10110,0),MATCH(Q$5,'Bin Analysis'!$C$2:$S$2,0))," "))))) | R35: =IF($L35=" "," ",(IF($M35=FALSE," ",(IF($M35>0,INDEX('Bin Analysis'!$C$3:$S$10110,MATCH($L35,'Bin Analysis'!$L$3:$L$10110,0),MATCH(R$5,'Bin Analysis'!$C$2:$S$2,0))," "))))) | S35: =IF($L35=" "," ",(IF($M35=FALSE," ",(IF($M35>0,INDEX('Bin Analysis'!$C$3:$S$10110,MATCH($L35,'Bin Analysis'!$L$3:$L$10110,0),MATCH(S$5,'Bin Analysis'!$C$2:$S$2,0))," "))))) | T35: =Assignments!K34 | U35: =Assignments!L34 | V35: =Assignments!V34
G36: =IFERROR('Data Transformation'!M34," ") | I36: Rheostat Score assignment | L36: =$G37 | M36: =IF(L36=" "," ",(IF($L36>0,INDEX('Bin Analysis'!$C$3:$S$10110,MATCH($L36,'Bin Analysis'!$L$3:$L$10110,0),MATCH(M$5,'Bin Analysis'!$C$2:$S$2,0))," "))) | N36: =IF($L36=" "," ",(IF($M36=FALSE," ",(IF($M36>0,INDEX('Bin Analysis'!$C$3:$S$10110,MATCH($L36,'Bin Analysis'!$L$3:$L$10110,0),MATCH(N$5,'Bin Analysis'!$C$2:$S$2,0))," "))))) | O36: =IF($L36=" "," ",(IF($M36=FALSE," ",(IF($M36>0,INDEX('Bin Analysis'!$C$3:$S$10110,MATCH($L36,'Bin Analysis'!$L$3:$L$10110,0),MATCH(O$5,'Bin Analysis'!$C$2:$S$2,0))," "))))) | P36: =IF($L36=" "," ",(IF($M36=FALSE," ",(IF($M36>0,INDEX('Bin Analysis'!$C$3:$S$10110,MATCH($L36,'Bin Analysis'!$L$3:$L$10110,0),MATCH(P$5,'Bin Analysis'!$C$2:$S$2,0))," "))))) | Q36: =IF($L36=" "," ",(IF($M36=FALSE," ",(IF($M36>0,INDEX('Bin Analysis'!$C$3:$S$10110,MATCH($L36,'Bin Analysis'!$L$3:$L$10110,0),MATCH(Q$5,'Bin Analysis'!$C$2:$S$2,0))," "))))) | R36: =IF($L36=" "," ",(IF($M36=FALSE," ",(IF($M36>0,INDEX('Bin Analysis'!$C$3:$S$10110,MATCH($L36,'Bin Analysis'!$L$3:$L$10110,0),MATCH(R$5,'Bin Analysis'!$C$2:$S$2,0))," "))))) | S36: =IF($L36=" "," ",(IF($M36=FALSE," ",(IF($M36>0,INDEX('Bin Analysis'!$C$3:$S$10110,MATCH($L36,'Bin Analysis'!$L$3:$L$10110,0),MATCH(S$5,'Bin Analysis'!$C$2:$S$2,0))," "))))) | T36: =Assignments!K35 | U36: =Assignments!L35 | V36: =Assignments!V35
G37: =IFERROR('Data Transformation'!M35," ") | I37: Default Rheostate Score assignment | J37: 0.5 | L37: =$G38 | M37: =IF(L37=" "," ",(IF($L37>0,INDEX('Bin Analysis'!$C$3:$S$10110,MATCH($L37,'Bin Analysis'!$L$3:$L$10110,0),MATCH(M$5,'Bin Analysis'!$C$2:$S$2,0))," "))) | N37: =IF($L37=" "," ",(IF($M37=FALSE," ",(IF($M37>0,INDEX('Bin Analysis'!$C$3:$S$10110,MATCH($L37,'Bin Analysis'!$L$3:$L$10110,0),MATCH(N$5,'Bin Analysis'!$C$2:$S$2,0))," "))))) | O37: =IF($L37=" "," ",(IF($M37=FALSE," ",(IF($M37>0,INDEX('Bin Analysis'!$C$3:$S$10110,MATCH($L37,'Bin Analysis'!$L$3:$L$10110,0),MATCH(O$5,'Bin Analysis'!$C$2:$S$2,0))," "))))) | P37: =IF($L37=" "," ",(IF($M37=FALSE," ",(IF($M37>0,INDEX('Bin Analysis'!$C$3:$S$10110,MATCH($L37,'Bin Analysis'!$L$3:$L$10110,0),MATCH(P$5,'Bin Analysis'!$C$2:$S$2,0))," "))))) | Q37: =IF($L37=" "," ",(IF($M37=FALSE," ",(IF($M37>0,INDEX('Bin Analysis'!$C$3:$S$10110,MATCH($L37,'Bin Analysis'!$L$3:$L$10110,0),MATCH(Q$5,'Bin Analysis'!$C$2:$S$2,0))," "))))) | R37: =IF($L37=" "," ",(IF($M37=FALSE," ",(IF($M37>0,INDEX('Bin Analysis'!$C$3:$S$10110,MATCH($L37,'Bin Analysis'!$L$3:$L$10110,0),MATCH(R$5,'Bin Analysis'!$C$2:$S$2,0))," "))))) | S37: =IF($L37=" "," ",(IF($M37=FALSE," ",(IF($M37>0,INDEX('Bin Analysis'!$C$3:$S$10110,MATCH($L37,'Bin Analysis'!$L$3:$L$10110,0),MATCH(S$5,'Bin Analysis'!$C$2:$S$2,0))," "))))) | T37: =Assignments!K36 | U37: =Assignments!L36 | V37: =Assignments!V36
G38: =IFERROR('Data Transformation'!M36," ") | L38: =$G39 | M38: =IF(L38=" "," ",(IF($L38>0,INDEX('Bin Analysis'!$C$3:$S$10110,MATCH($L38,'Bin Analysis'!$L$3:$L$10110,0),MATCH(M$5,'Bin Analysis'!$C$2:$S$2,0))," "))) | N38: =IF($L38=" "," ",(IF($M38=FALSE," ",(IF($M38>0,INDEX('Bin Analysis'!$C$3:$S$10110,MATCH($L38,'Bin Analysis'!$L$3:$L$10110,0),MATCH(N$5,'Bin Analysis'!$C$2:$S$2,0))," "))))) | O38: =IF($L38=" "," ",(IF($M38=FALSE," ",(IF($M38>0,INDEX('Bin Analysis'!$C$3:$S$10110,MATCH($L38,'Bin Analysis'!$L$3:$L$10110,0),MATCH(O$5,'Bin Analysis'!$C$2:$S$2,0))," "))))) | P38: =IF($L38=" "," ",(IF($M38=FALSE," ",(IF($M38>0,INDEX('Bin Analysis'!$C$3:$S$10110,MATCH($L38,'Bin Analysis'!$L$3:$L$10110,0),MATCH(P$5,'Bin Analysis'!$C$2:$S$2,0))," "))))) | Q38: =IF($L38=" "," ",(IF($M38=FALSE," ",(IF($M38>0,INDEX('Bin Analysis'!$C$3:$S$10110,MATCH($L38,'Bin Analysis'!$L$3:$L$10110,0),MATCH(Q$5,'Bin Analysis'!$C$2:$S$2,0))," "))))) | R38: =IF($L38=" "," ",(IF($M38=FALSE," ",(IF($M38>0,INDEX('Bin Analysis'!$C$3:$S$10110,MATCH($L38,'Bin Analysis'!$L$3:$L$10110,0),MATCH(R$5,'Bin Analysis'!$C$2:$S$2,0))," "))))) | S38: =IF($L38=" "," ",(IF($M38=FALSE," ",(IF($M38>0,INDEX('Bin Analysis'!$C$3:$S$10110,MATCH($L38,'Bin Analysis'!$L$3:$L$10110,0),MATCH(S$5,'Bin Analysis'!$C$2:$S$2,0))," "))))) | T38: =Assignments!K37 | U38: =Assignments!L37 | V38: =Assignments!V37
G39: =IFERROR('Data Transformation'!M37," ") | I39: Toggle Score assignment | L39: =$G40 | M39: =IF(L39=" "," ",(IF($L39>0,INDEX('Bin Analysis'!$C$3:$S$10110,MATCH($L39,'Bin Analysis'!$L$3:$L$10110,0),MATCH(M$5,'Bin Analysis'!$C$2:$S$2,0))," "))) | N39: =IF($L39=" "," ",(IF($M39=FALSE," ",(IF($M39>0,INDEX('Bin Analysis'!$C$3:$S$10110,MATCH($L39,'Bin Analysis'!$L$3:$L$10110,0),MATCH(N$5,'Bin Analysis'!$C$2:$S$2,0))," "))))) | O39: =IF($L39=" "," ",(IF($M39=FALSE," ",(IF($M39>0,INDEX('Bin Analysis'!$C$3:$S$10110,MATCH($L39,'Bin Analysis'!$L$3:$L$10110,0),MATCH(O$5,'Bin Analysis'!$C$2:$S$2,0))," "))))) | P39: =IF($L39=" "," ",(IF($M39=FALSE," ",(IF($M39>0,INDEX('Bin Analysis'!$C$3:$S$10110,MATCH($L39,'Bin Analysis'!$L$3:$L$10110,0),MATCH(P$5,'Bin Analysis'!$C$2:$S$2,0))," "))))) | Q39: =IF($L39=" "," ",(IF($M39=FALSE," ",(IF($M39>0,INDEX('Bin Analysis'!$C$3:$S$10110,MATCH($L39,'Bin Analysis'!$L$3:$L$10110,0),MATCH(Q$5,'Bin Analysis'!$C$2:$S$2,0))," "))))) | R39: =IF($L39=" "," ",(IF($M39=FALSE," ",(IF($M39>0,INDEX('Bin Analysis'!$C$3:$S$10110,MATCH($L39,'Bin Analysis'!$L$3:$L$10110,0),MATCH(R$5,'Bin Analysis'!$C$2:$S$2,0))," "))))) | S39: =IF($L39=" "," ",(IF($M39=FALSE," ",(IF($M39>0,INDEX('Bin Analysis'!$C$3:$S$10110,MATCH($L39,'Bin Analysis'!$L$3:$L$10110,0),MATCH(S$5,'Bin Analysis'!$C$2:$S$2,0))," "))))) | T39: =Assignments!K38 | U39: =Assignments!L38 | V39: =Assignments!V38
G40: =IFERROR('Data Transformation'!M38," ") | I40: Default Toggle Score assignment | J40: 0.64 | L40: =$G41 | M40: =IF(L40=" "," ",(IF($L40>0,INDEX('Bin Analysis'!$C$3:$S$10110,MATCH($L40,'Bin Analysis'!$L$3:$L$10110,0),MATCH(M$5,'Bin Analysis'!$C$2:$S$2,0))," "))) | N40: =IF($L40=" "," ",(IF($M40=FALSE," ",(IF($M40>0,INDEX('Bin Analysis'!$C$3:$S$10110,MATCH($L40,'Bin Analysis'!$L$3:$L$10110,0),MATCH(N$5,'Bin Analysis'!$C$2:$S$2,0))," "))))) | O40: =IF($L40=" "," ",(IF($M40=FALSE," ",(IF($M40>0,INDEX('Bin Analysis'!$C$3:$S$10110,MATCH($L40,'Bin Analysis'!$L$3:$L$10110,0),MATCH(O$5,'Bin Analysis'!$C$2:$S$2,0))," "))))) | P40: =IF($L40=" "," ",(IF($M40=FALSE," ",(IF($M40>0,INDEX('Bin Analysis'!$C$3:$S$10110,MATCH($L40,'Bin Analysis'!$L$3:$L$10110,0),MATCH(P$5,'Bin Analysis'!$C$2:$S$2,0))," "))))) | Q40: =IF($L40=" "," ",(IF($M40=FALSE," ",(IF($M40>0,INDEX('Bin Analysis'!$C$3:$S$10110,MATCH($L40,'Bin Analysis'!$L$3:$L$10110,0),MATCH(Q$5,'Bin Analysis'!$C$2:$S$2,0))," "))))) | R40: =IF($L40=" "," ",(IF($M40=FALSE," ",(IF($M40>0,INDEX('Bin Analysis'!$C$3:$S$10110,MATCH($L40,'Bin Analysis'!$L$3:$L$10110,0),MATCH(R$5,'Bin Analysis'!$C$2:$S$2,0))," "))))) | S40: =IF($L40=" "," ",(IF($M40=FALSE," ",(IF($M40>0,INDEX('Bin Analysis'!$C$3:$S$10110,MATCH($L40,'Bin Analysis'!$L$3:$L$10110,0),MATCH(S$5,'Bin Analysis'!$C$2:$S$2,0))," "))))) | T40: =Assignments!K39 | U40: =Assignments!L39 | V40: =Assignments!V39
G41: =IFERROR('Data Transformation'!M39," ") | L41: =$G42 | M41: =IF(L41=" "," ",(IF($L41>0,INDEX('Bin Analysis'!$C$3:$S$10110,MATCH($L41,'Bin Analysis'!$L$3:$L$10110,0),MATCH(M$5,'Bin Analysis'!$C$2:$S$2,0))," "))) | N41: =IF($L41=" "," ",(IF($M41=FALSE," ",(IF($M41>0,INDEX('Bin Analysis'!$C$3:$S$10110,MATCH($L41,'Bin Analysis'!$L$3:$L$10110,0),MATCH(N$5,'Bin Analysis'!$C$2:$S$2,0))," "))))) | O41: =IF($L41=" "," ",(IF($M41=FALSE," ",(IF($M41>0,INDEX('Bin Analysis'!$C$3:$S$10110,MATCH($L41,'Bin Analysis'!$L$3:$L$10110,0),MATCH(O$5,'Bin Analysis'!$C$2:$S$2,0))," "))))) | P41: =IF($L41=" "," ",(IF($M41=FALSE," ",(IF($M41>0,INDEX('Bin Analysis'!$C$3:$S$10110,MATCH($L41,'Bin Analysis'!$L$3:$L$10110,0),MATCH(P$5,'Bin Analysis'!$C$2:$S$2,0))," "))))) | Q41: =IF($L41=" "," ",(IF($M41=FALSE," ",(IF($M41>0,INDEX('Bin Analysis'!$C$3:$S$10110,MATCH($L41,'Bin Analysis'!$L$3:$L$10110,0),MATCH(Q$5,'Bin Analysis'!$C$2:$S$2,0))," "))))) | R41: =IF($L41=" "," ",(IF($M41=FALSE," ",(IF($M41>0,INDEX('Bin Analysis'!$C$3:$S$10110,MATCH($L41,'Bin Analysis'!$L$3:$L$10110,0),MATCH(R$5,'Bin Analysis'!$C$2:$S$2,0))," "))))) | S41: =IF($L41=" "," ",(IF($M41=FALSE," ",(IF($M41>0,INDEX('Bin Analysis'!$C$3:$S$10110,MATCH($L41,'Bin Analysis'!$L$3:$L$10110,0),MATCH(S$5,'Bin Analysis'!$C$2:$S$2,0))," "))))) | T41: =Assignments!K40 | U41: =Assignments!L40 | V41: =Assignments!V40
G42: =IFERROR('Data Transformation'!M40," ") | L42: =$G43 | M42: =IF(L42=" "," ",(IF($L42>0,INDEX('Bin Analysis'!$C$3:$S$10110,MATCH($L42,'Bin Analysis'!$L$3:$L$10110,0),MATCH(M$5,'Bin Analysis'!$C$2:$S$2,0))," "))) | N42: =IF($L42=" "," ",(IF($M42=FALSE," ",(IF($M42>0,INDEX('Bin Analysis'!$C$3:$S$10110,MATCH($L42,'Bin Analysis'!$L$3:$L$10110,0),MATCH(N$5,'Bin Analysis'!$C$2:$S$2,0))," "))))) | O42: =IF($L42=" "," ",(IF($M42=FALSE," ",(IF($M42>0,INDEX('Bin Analysis'!$C$3:$S$10110,MATCH($L42,'Bin Analysis'!$L$3:$L$10110,0),MATCH(O$5,'Bin Analysis'!$C$2:$S$2,0))," "))))) | P42: =IF($L42=" "," ",(IF($M42=FALSE," ",(IF($M42>0,INDEX('Bin Analysis'!$C$3:$S$10110,MATCH($L42,'Bin Analysis'!$L$3:$L$10110,0),MATCH(P$5,'Bin Analysis'!$C$2:$S$2,0))," "))))) | Q42: =IF($L42=" "," ",(IF($M42=FALSE," ",(IF($M42>0,INDEX('Bin Analysis'!$C$3:$S$10110,MATCH($L42,'Bin Analysis'!$L$3:$L$10110,0),MATCH(Q$5,'Bin Analysis'!$C$2:$S$2,0))," "))))) | R42: =IF($L42=" "," ",(IF($M42=FALSE," ",(IF($M42>0,INDEX('Bin Analysis'!$C$3:$S$10110,MATCH($L42,'Bin Analysis'!$L$3:$L$10110,0),MATCH(R$5,'Bin Analysis'!$C$2:$S$2,0))," "))))) | S42: =IF($L42=" "," ",(IF($M42=FALSE," ",(IF($M42>0,INDEX('Bin Analysis'!$C$3:$S$10110,MATCH($L42,'Bin Analysis'!$L$3:$L$10110,0),MATCH(S$5,'Bin Analysis'!$C$2:$S$2,0))," "))))) | T42: =Assignments!K41 | U42: =Assignments!L41 | V42: =Assignments!V41
...

Sheet Analysis working notes
A1: This worksheet is a good place to keep track of why and how the values were chosen for WT and "dead", as well as any other analysis parameters.

Sheet Data Transformation
B1: Data | J1: Position Statistics | Q1: Bin determination | T1: Drop down menu options
B2: Position | C2: Data | D2: Error | E2: Log Data | F2: Error of Log Data | G2: Data to be analyzed | H2: Error to be analyzed | I2: Position to be counted | O2: Threshold
A3: WT | C3: =IF(ISNUMBER('Input and Summary Results'!D5),'Input and Summary Results'!D5,FALSE) -> FALSE | D3: =IF(ISNUMBER('Input and Summary Results'!E5),'Input and Summary Results'!E5,FALSE) -> FALSE | E3: =LOG10(C3) -> #NUM! | F3: =0.434*D4/C4 -> #DIV/0! | G3: =IF('Input and Summary Results'!$J$4="yes",'Data Transformation'!E3,'Data Transformation'!C3) -> #NUM! | H3: =IF('Input and Summary Results'!$J$4="yes",'Data Transformation'!F3,'Data Transformation'!D3) -> #DIV/0! | J3: Unique Distinct Positions | M3: Positions ordered | N3: Total# of Mutants | O3: # of variants | Q3: Minimum | R3: =MIN(G4:G8425) -> 0 | T3: log scale?
A4: WT | B4: ='Input and Summary Results'!G$8 | C4: =IF(B4=0,FALSE,'Input and Summary Results'!$D$5) -> 0 | D4: =IF(B4=0,FALSE,'Input and Summary Results'!$E$5) -> 0 | E4: =IF(C4=FALSE,FALSE,LOG10(C4)) -> #NUM! | F4: =IF(D4=FALSE, FALSE,0.434*D4/C4) -> #DIV/0! | G4: =IF(B4=" ",FALSE,(IF('Input and Summary Results'!$J$4="yes",'Data Transformation'!E4,'Data Transformation'!C4))) -> FALSE | H4: =IF(B4=" ",FALSE,(IF('Input and Summary Results'!$J$4="yes",'Data Transformation'!F4,'Data Transformation'!D4))) -> FALSE | I4: =IF(G4=FALSE,"",B4) | J4: all | M4: =J4 -> all | N4: =(COUNTIF(I425:I8425,">0"))+1 -> 1 | O4: =IF(N4>4,N4,FALSE) -> FALSE | Q4: Maximum | R4: =IF('Input and Summary Results'!J4="yes",MAX(E425:E8425),MAX(C425:C8425)) -> 0 | T4: yes
A5: WT | B5: ='Input and Summary Results'!$G9 | C5: =IF(B5=0,FALSE,'Input and Summary Results'!$D$5) -> 0 | D5: =IF(B5=0,FALSE,'Input and Summary Results'!$E$5) -> 0 | E5: =IF(C5=FALSE,FALSE,LOG10(C5)) -> #NUM! | F5: =IF(D5=FALSE, FALSE,0.434*D5/C5) -> #DIV/0! | G5: =IF(B5=" ",FALSE,(IF('Input and Summary Results'!$J$4="yes",'Data Transformation'!E5,'Data Transformation'!C5))) -> FALSE | H5: =IF(B5=" ",FALSE,(IF('Input and Summary Results'!$J$4="yes",'Data Transformation'!F5,'Data Transformation'!D5))) -> FALSE | I5: =IF(G5=FALSE,"",B5) | J5: =LOOKUP(2,1/(COUNTIF($J$4:J4,'Input and Summary Results'!$B$7:$B$8007)=0),'Input and Summary Results'!$B$7:$B$8007) -> 0 | K5: =IFERROR(J5," ") -> 0 | M5: sum of positions | N5: =SUM(N6:N426) -> 0 | O5: =IF(N5>4,N5,FALSE) -> FALSE | Q5: Wild Type | R5: =$G$3 -> #NUM! | T5: no
A6: WT | B6: ='Input and Summary Results'!$G10 | C6: =IF(B6=0,FALSE,'Input and Summary Results'!$D$5) -> 0 | D6: =IF(B6=0,FALSE,'Input and Summary Results'!$E$5) -> 0 | E6: =IF(C6=FALSE,FALSE,LOG10(C6)) -> #NUM! | F6: =IF(D6=FALSE, FALSE,0.434*D6/C6) -> #DIV/0! | G6: =IF(B6=" ",FALSE,(IF('Input and Summary Results'!$J$4="yes",'Data Transformation'!E6,'Data Transformation'!C6))) -> FALSE | H6: =IF(B6=" ",FALSE,(IF('Input and Summary Results'!$J$4="yes",'Data Transformation'!F6,'Data Transformation'!D6))) -> FALSE | I6: =IF(G6=FALSE,"",B6) | J6: =LOOKUP(2,1/(COUNTIF($J$4:J5,'Input and Summary Results'!$B$7:$B$8007)=0),'Input and Summary Results'!$B$7:$B$8007) -> #N/A | K6: =IFERROR(J6," ") | L6: 1 | M6: =SMALL($K$6:$K$426,L6) -> #NUM! | N6: =COUNTIF($I$4:$I$8425,M6) -> 0 | O6: =IF(N6>4,N6,FALSE) -> FALSE | Q6: Dead | R6: =IF('Input and Summary Results'!J4="yes",LOG('Input and Summary Results'!J17,10),'Input and Summary Results'!J17) -> 0
A7: WT | B7: ='Input and Summary Results'!$G11 | C7: =IF(B7=0,FALSE,'Input and Summary Results'!$D$5) -> 0 | D7: =IF(B7=0,FALSE,'Input and Summary Results'!$E$5) -> 0 | E7: =IF(C7=FALSE,FALSE,LOG10(C7)) -> #NUM! | F7: =IF(D7=FALSE, FALSE,0.434*D7/C7) -> #DIV/0! | G7: =IF(B7=" ",FALSE,(IF('Input and Summary Results'!$J$4="yes",'Data Transformation'!E7,'Data Transformation'!C7))) -> FALSE | H7: =IF(B7=" ",FALSE,(IF('Input and Summary Results'!$J$4="yes",'Data Transformation'!F7,'Data Transformation'!D7))) -> FALSE | I7: =IF(G7=FALSE,"",B7) | J7: =LOOKUP(2,1/(COUNTIF($J$4:J6,'Input and Summary Results'!$B$7:$B$8007)=0),'Input and Summary Results'!$B$7:$B$8007) -> #N/A | K7: =IFERROR(J7," ") | L7: =L6+1 -> 2 | M7: =SMALL($K$6:$K$426,L7) -> #NUM! | N7: =COUNTIF($I$4:$I$8425,M7) -> 0 | O7: =IF(N7>4,N7,FALSE) -> FALSE | T7: non fxnal value
