Workbook

Sheet How to use this calculator

Sheet Input and Summary Results
A2: Data set: | B2: Plpro activity in the presence of inhibitors, from the combined and filtered set shown in Call lab SuppFig 13
B4: Position | C4: Mutation | D4: Functional Value | E4: Error | G4: Positions Analyzed | I4: Should the data be converted to a log scale? | J4: no | N4: Scores
A5: Wild Type | B5: NA | C5: NA | D5: 1 | L5: Position | M5: # of variants | N5: Enhancing | O5: Neutral | P5: Unweighted rheostat | Q5: Weighted rheostat | R5: Toggle | S5: Binary | T5: Average | U5: Standard Deviation | V5: Assignment | AA5: Enhancing | AB5: =O5 -> Neutral | AC5: =P5 -> Unweighted rheostat | AD5: =Q5 -> Weighted rheostat | AE5: =R5 -> Toggle | AF5: Binary
A6: Format Example | B6: 45 | C6: A | D6: 0.563 | E6: 0.0034 | I6: Data statistics | L6: all | M6: =INDEX('Bin Analysis'!$C$3:$S$505,MATCH($L6,'Bin Analysis'!$B$3:$B$505,0),MATCH(M$5,'Bin Analysis'!$C$2:$S$2,0)) -> 4933 | N6: =INDEX('Bin Analysis'!$C$3:$S$505,MATCH($L6,'Bin Analysis'!$B$3:$B$505,0),MATCH(N$5,'Bin Analysis'!$C$2:$S$2,0)) -> 0.02595296 | O6: =INDEX('Bin Analysis'!$C$3:$S$505,MATCH($L6,'Bin Analysis'!$B$3:$B$505,0),MATCH(O$5,'Bin Analysis'!$C$2:$S$2,0)) -> 0.26378751 | P6: =INDEX('Bin Analysis'!$C$3:$S$505,MATCH($L6,'Bin Analysis'!$B$3:$B$505,0),MATCH(P$5,'Bin Analysis'!$C$2:$S$2,0)) -> 1 | Q6: =INDEX('Bin Analysis'!$C$3:$S$505,MATCH($L6,'Bin Analysis'!$B$3:$B$505,0),MATCH(Q$5,'Bin Analysis'!$C$2:$S$2,0)) -> 1 | R6: =INDEX('Bin Analysis'!$C$3:$S$505,MATCH($L6,'Bin Analysis'!$B$3:$B$505,0),MATCH(R$5,'Bin Analysis'!$C$2:$S$2,0)) -> 0.3959854 | S6: =INDEX('Bin Analysis'!$C$3:$S$505,MATCH($L6,'Bin Analysis'!$B$3:$B$505,0),MATCH(S$5,'Bin Analysis'!$C$2:$S$2,0)) -> no | T6: =Assignments!K5 -> 0.5388359 | U6: =Assignments!L5 -> 0.40966876 | Z6: <0.1 | AA6: =COUNTIF(N$7:N$427,"<0.1") -> 290 | AB6: =COUNTIF(O$7:O$427,"<0.1") -> 139 | AC6: =COUNTIF(P$7:P$427,"<0.1") -> 0 | AD6: =COUNTIF(Q$7:Q$427,"<0.1") -> 26 | AE6: =COUNTIF(R$7:R$427,"<0.1") -> 113 | AF6: =COUNTIF(S$7:S$427,"=yes") -> 29
A7: E | B7: 1 | C7: W | D7: 0.63034 | E7: 0.08376377 | I7: Minimum | J7: =IF($J$4="yes",10^('Data Transformation'!R3),'Data Transformation'!R3) -> -0.2114974 | L7: =$G8 -> 1 | M7: =IF(L7=" "," ",(IF($L7>0,INDEX('Bin Analysis'!$C$3:$S$10110,MATCH($L7,'Bin Analysis'!$L$3:$L$10110,0),MATCH(M$5,'Bin Analysis'!$C$2:$S$2,0))," "))) -> 18 | N7: =IF($L7=" "," ",(IF($M7=FALSE," ",(IF($M7>0,INDEX('Bin Analysis'!$C$3:$S$10110,MATCH($L7,'Bin Analysis'!$L$3:$L$10110,0),MATCH(N$5,'Bin Analysis'!$C$2:$S$2,0))," "))))) -> 0 | O7: =IF($L7=" "," ",(IF($M7=FALSE," ",(IF($M7>0,INDEX('Bin Analysis'!$C$3:$S$10110,MATCH($L7,'Bin Analysis'!$L$3:$L$10110,0),MATCH(O$5,'Bin Analysis'!$C$2:$S$2,0))," "))))) -> 0.41176471 | P7: =IF($L7=" "," ",(IF($M7=FALSE," ",(IF($M7>0,INDEX('Bin Analysis'!$C$3:$S$10110,MATCH($L7,'Bin Analysis'!$L$3:$L$10110,0),MATCH(P$5,'Bin Analysis'!$C$2:$S$2,0))," "))))) -> 0.4 | Q7: =IF($L7=" "," ",(IF($M7=FALSE," ",(IF($M7>0,INDEX('Bin Analysis'!$C$3:$S$10110,MATCH($L7,'Bin Analysis'!$L$3:$L$10110,0),MATCH(Q$5,'Bin Analysis'!$C$2:$S$2,0))," "))))) -> 0.39130435 | R7: =IF($L7=" "," ",(IF($M7=FALSE," ",(IF($M7>0,INDEX('Bin Analysis'!$C$3:$S$10110,MATCH($L7,'Bin Analysis'!$L$3:$L$10110,0),MATCH(R$5,'Bin Analysis'!$C$2:$S$2,0))," "))))) -> 0 | S7: =IF($L7=" "," ",(IF($M7=FALSE," ",(IF($M7>0,INDEX('Bin Analysis'!$C$3:$S$10110,MATCH($L7,'Bin Analysis'!$L$3:$L$10110,0),MATCH(S$5,'Bin Analysis'!$C$2:$S$2,0))," "))))) -> no | T7: =Assignments!K6 -> 0.8152088 | U7: =Assignments!L6 -> 0.10373043 | V7: =Assignments!V6 -> Moderate | Z7: 0.1 to < 0.2 | AA7: =COUNTIF(N$7:N$427,"<0.2")-SUM(AA6) -> 12 | AB7: =COUNTIF(O$7:O$427,"<0.2")-SUM(AB6) -> 36 | AC7: =COUNTIF(P$7:P$427,"<0.2")-SUM(AC6) -> 0 | AD7: =COUNTIF(Q$7:Q$427,"<0.2")-SUM(AD6) -> 20 | AE7: =COUNTIF(R$7:R$427,"<0.2")-SUM(AE6) -> 34
A8: E | B8: 1 | C8: Y | D8: 0.68393146 | E8: 0.04148169 | G8: =IFERROR('Data Transformation'!M6," ") -> 1 | I8: Maximum | J8: =IF($J$4="yes",10^('Data Transformation'!R4),'Data Transformation'!R4) -> 1.4334565 | L8: =$G9 -> 2 | M8: =IF(L8=" "," ",(IF($L8>0,INDEX('Bin Analysis'!$C$3:$S$10110,MATCH($L8,'Bin Analysis'!$L$3:$L$10110,0),MATCH(M$5,'Bin Analysis'!$C$2:$S$2,0))," "))) -> 18 | N8: =IF($L8=" "," ",(IF($M8=FALSE," ",(IF($M8>0,INDEX('Bin Analysis'!$C$3:$S$10110,MATCH($L8,'Bin Analysis'!$L$3:$L$10110,0),MATCH(N$5,'Bin Analysis'!$C$2:$S$2,0))," "))))) -> 0 | O8: =IF($L8=" "," ",(IF($M8=FALSE," ",(IF($M8>0,INDEX('Bin Analysis'!$C$3:$S$10110,MATCH($L8,'Bin Analysis'!$L$3:$L$10110,0),MATCH(O$5,'Bin Analysis'!$C$2:$S$2,0))," "))))) -> 1 | P8: =IF($L8=" "," ",(IF($M8=FALSE," ",(IF($M8>0,INDEX('Bin Analysis'!$C$3:$S$10110,MATCH($L8,'Bin Analysis'!$L$3:$L$10110,0),MATCH(P$5,'Bin Analysis'!$C$2:$S$2,0))," "))))) -> 0.2 | Q8: =IF($L8=" "," ",(IF($M8=FALSE," ",(IF($M8>0,INDEX('Bin Analysis'!$C$3:$S$10110,MATCH($L8,'Bin Analysis'!$L$3:$L$10110,0),MATCH(Q$5,'Bin Analysis'!$C$2:$S$2,0))," "))))) -> 0.13043478 | R8: =IF($L8=" "," ",(IF($M8=FALSE," ",(IF($M8>0,INDEX('Bin Analysis'!$C$3:$S$10110,MATCH($L8,'Bin Analysis'!$L$3:$L$10110,0),MATCH(R$5,'Bin Analysis'!$C$2:$S$2,0))," "))))) -> 0 | S8: =IF($L8=" "," ",(IF($M8=FALSE," ",(IF($M8>0,INDEX('Bin Analysis'!$C$3:$S$10110,MATCH($L8,'Bin Analysis'!$L$3:$L$10110,0),MATCH(S$5,'Bin Analysis'!$C$2:$S$2,0))," "))))) -> yes | T8: =Assignments!K7 -> 1.0167753 | U8: =Assignments!L7 -> 0.046076489 | V8: =Assignments!V7 -> Neutral | Z8: 0.2 to < 0.3 | AA8: =COUNTIF(N$7:N$427,"<0.3")-SUM(AA6:AA7) -> 3 | AB8: =COUNTIF(O$7:O$427,"<0.3")-SUM(AB6:AB7) -> 24 | AC8: =COUNTIF(P$7:P$427,"<0.3")-SUM(AC6:AC7) -> 29 | AD8: =COUNTIF(Q$7:Q$427,"<0.3")-SUM(AD6:AD7) -> 29 | AE8: =COUNTIF(R$7:R$427,"<0.3")-SUM(AE6:AE7) -> 17
A9: E | B9: 1 | C9: H | D9: 0.68619103 | E9: 0.04493149 | G9: =IFERROR('Data Transformation'!M7," ") -> 2 | L9: =$G10 -> 3 | M9: =IF(L9=" "," ",(IF($L9>0,INDEX('Bin Analysis'!$C$3:$S$10110,MATCH($L9,'Bin Analysis'!$L$3:$L$10110,0),MATCH(M$5,'Bin Analysis'!$C$2:$S$2,0))," "))) -> 19 | N9: =IF($L9=" "," ",(IF($M9=FALSE," ",(IF($M9>0,INDEX('Bin Analysis'!$C$3:$S$10110,MATCH($L9,'Bin Analysis'!$L$3:$L$10110,0),MATCH(N$5,'Bin Analysis'!$C$2:$S$2,0))," "))))) -> 0 | O9: =IF($L9=" "," ",(IF($M9=FALSE," ",(IF($M9>0,INDEX('Bin Analysis'!$C$3:$S$10110,MATCH($L9,'Bin Analysis'!$L$3:$L$10110,0),MATCH(O$5,'Bin Analysis'!$C$2:$S$2,0))," "))))) -> 0.94444444 | P9: =IF($L9=" "," ",(IF($M9=FALSE," ",(IF($M9>0,INDEX('Bin Analysis'!$C$3:$S$10110,MATCH($L9,'Bin Analysis'!$L$3:$L$10110,0),MATCH(P$5,'Bin Analysis'!$C$2:$S$2,0))," "))))) -> 0.2 | Q9: =IF($L9=" "," ",(IF($M9=FALSE," ",(IF($M9>0,INDEX('Bin Analysis'!$C$3:$S$10110,MATCH($L9,'Bin Analysis'!$L$3:$L$10110,0),MATCH(Q$5,'Bin Analysis'!$C$2:$S$2,0))," "))))) -> 0.13043478 | R9: =IF($L9=" "," ",(IF($M9=FALSE," ",(IF($M9>0,INDEX('Bin Analysis'!$C$3:$S$10110,MATCH($L9,'Bin Analysis'!$L$3:$L$10110,0),MATCH(R$5,'Bin Analysis'!$C$2:$S$2,0))," "))))) -> 0 | S9: =IF($L9=" "," ",(IF($M9=FALSE," ",(IF($M9>0,INDEX('Bin Analysis'!$C$3:$S$10110,MATCH($L9,'Bin Analysis'!$L$3:$L$10110,0),MATCH(S$5,'Bin Analysis'!$C$2:$S$2,0))," "))))) -> yes | T9: =Assignments!K8 -> 0.98366617 | U9: =Assignments!L8 -> 0.058856242 | V9: =Assignments!V8 -> Neutral | Z9: 0.3 to < 0.4 | AA9: =COUNTIF(N$7:N$427,"<0.4")-SUM(AA6:AA8) -> 2 | AB9: =COUNTIF(O$7:O$427,"<0.4")-SUM(AB6:AB8) -> 19 | AC9: =COUNTIF(P$7:P$427,"<0.4")-SUM(AC6:AC8) -> 41 | AD9: =COUNTIF(Q$7:Q$427,"<0.4")-SUM(AD6:AD8) -> 66 | AE9: =COUNTIF(R$7:R$427,"<0.4")-SUM(AE6:AE8) -> 9
A10: E | B10: 1 | C10: S | D10: 0.69724918 | E10: 0.02762239 | G10: =IFERROR('Data Transformation'!M8," ") -> 3 | I10: Min/Max override | L10: =$G11 -> 4 | M10: =IF(L10=" "," ",(IF($L10>0,INDEX('Bin Analysis'!$C$3:$S$10110,MATCH($L10,'Bin Analysis'!$L$3:$L$10110,0),MATCH(M$5,'Bin Analysis'!$C$2:$S$2,0))," "))) -> 17 | N10: =IF($L10=" "," ",(IF($M10=FALSE," ",(IF($M10>0,INDEX('Bin Analysis'!$C$3:$S$10110,MATCH($L10,'Bin Analysis'!$L$3:$L$10110,0),MATCH(N$5,'Bin Analysis'!$C$2:$S$2,0))," "))))) -> 0 | O10: =IF($L10=" "," ",(IF($M10=FALSE," ",(IF($M10>0,INDEX('Bin Analysis'!$C$3:$S$10110,MATCH($L10,'Bin Analysis'!$L$3:$L$10110,0),MATCH(O$5,'Bin Analysis'!$C$2:$S$2,0))," "))))) -> 0.8125 | P10: =IF($L10=" "," ",(IF($M10=FALSE," ",(IF($M10>0,INDEX('Bin Analysis'!$C$3:$S$10110,MATCH($L10,'Bin Analysis'!$L$3:$L$10110,0),MATCH(P$5,'Bin Analysis'!$C$2:$S$2,0))," "))))) -> 0.3 | Q10: =IF($L10=" "," ",(IF($M10=FALSE," ",(IF($M10>0,INDEX('Bin Analysis'!$C$3:$S$10110,MATCH($L10,'Bin Analysis'!$L$3:$L$10110,0),MATCH(Q$5,'Bin Analysis'!$C$2:$S$2,0))," "))))) -> 0.26086957 | R10: =IF($L10=" "," ",(IF($M10=FALSE," ",(IF($M10>0,INDEX('Bin Analysis'!$C$3:$S$10110,MATCH($L10,'Bin Analysis'!$L$3:$L$10110,0),MATCH(R$5,'Bin Analysis'!$C$2:$S$2,0))," "))))) -> 0 | S10: =IF($L10=" "," ",(IF($M10=FALSE," ",(IF($M10>0,INDEX('Bin Analysis'!$C$3:$S$10110,MATCH($L10,'Bin Analysis'!$L$3:$L$10110,0),MATCH(S$5,'Bin Analysis'!$C$2:$S$2,0))," "))))) -> no | T10: =Assignments!K9 -> 0.92826196 | U10: =Assignments!L9 -> 0.072177105 | V10: =Assignments!V9 -> Neutral | Z10: 0.4 to < 0.5 | AA10: =COUNTIF(N$7:N$427,"<0.5")-SUM(AA6:AA9) -> 1 | AB10: =COUNTIF(O$7:O$427,"<0.5")-SUM(AB6:AB9) -> 23 | AC10: =COUNTIF(P$7:P$427,"<0.5")-SUM(AC6:AC9) -> 58 | AD10: =COUNTIF(Q$7:Q$427,"<0.5")-SUM(AD6:AD9) -> 45 | AE10: =COUNTIF(R$7:R$427,"<0.5")-SUM(AE6:AE9) -> 10
A11: E | B11: 1 | C11: I | D11: 0.74720693 | E11: 0.04182689 | G11: =IFERROR('Data Transformation'!M9," ") -> 4 | I11: Minimum | J11: 0.19 | L11: =$G12 -> 5 | M11: =IF(L11=" "," ",(IF($L11>0,INDEX('Bin Analysis'!$C$3:$S$10110,MATCH($L11,'Bin Analysis'!$L$3:$L$10110,0),MATCH(M$5,'Bin Analysis'!$C$2:$S$2,0))," "))) -> 19 | N11: =IF($L11=" "," ",(IF($M11=FALSE," ",(IF($M11>0,INDEX('Bin Analysis'!$C$3:$S$10110,MATCH($L11,'Bin Analysis'!$L$3:$L$10110,0),MATCH(N$5,'Bin Analysis'!$C$2:$S$2,0))," "))))) -> 0 | O11: =IF($L11=" "," ",(IF($M11=FALSE," ",(IF($M11>0,INDEX('Bin Analysis'!$C$3:$S$10110,MATCH($L11,'Bin Analysis'!$L$3:$L$10110,0),MATCH(O$5,'Bin Analysis'!$C$2:$S$2,0))," "))))) -> 0.27777778 | P11: =IF($L11=" "," ",(IF($M11=FALSE," ",(IF($M11>0,INDEX('Bin Analysis'!$C$3:$S$10110,MATCH($L11,'Bin Analysis'!$L$3:$L$10110,0),MATCH(P$5,'Bin Analysis'!$C$2:$S$2,0))," "))))) -> 0.7 | Q11: =IF($L11=" "," ",(IF($M11=FALSE," ",(IF($M11>0,INDEX('Bin Analysis'!$C$3:$S$10110,MATCH($L11,'Bin Analysis'!$L$3:$L$10110,0),MATCH(Q$5,'Bin Analysis'!$C$2:$S$2,0))," "))))) -> 0.65217391 | R11: =IF($L11=" "," ",(IF($M11=FALSE," ",(IF($M11>0,INDEX('Bin Analysis'!$C$3:$S$10110,MATCH($L11,'Bin Analysis'!$L$3:$L$10110,0),MATCH(R$5,'Bin Analysis'!$C$2:$S$2,0))," "))))) -> 0.16666667 | S11: =IF($L11=" "," ",(IF($M11=FALSE," ",(IF($M11>0,INDEX('Bin Analysis'!$C$3:$S$10110,MATCH($L11,'Bin Analysis'!$L$3:$L$10110,0),MATCH(S$5,'Bin Analysis'!$C$2:$S$2,0))," "))))) -> no | T11: =Assignments!K10 -> 0.65920881 | U11: =Assignments!L10 -> 0.27576934 | V11: =Assignments!V10 -> Rheostat | Z11: 0.5 to < 0.6 | AA11: =COUNTIF(N$7:N$427,"<0.6")-SUM(AA6:AA10) -> 1 | AB11: =COUNTIF(O$7:O$427,"<0.6")-SUM(AB6:AB10) -> 24 | AC11: =COUNTIF(P$7:P$427,"<0.6")-SUM(AC6:AC10) -> 61 | AD11: =COUNTIF(Q$7:Q$427,"<0.6")-SUM(AD6:AD10) -> 58 | AE11: =COUNTIF(R$7:R$427,"<0.6")-SUM(AE6:AE10) -> 22
A12: E | B12: 1 | C12: V | D12: 0.77691926 | E12: 0.05232975 | G12: =IFERROR('Data Transformation'!M10," ") -> 5 | I12: Maximum | J12: 1.5 | L12: =$G13 -> 6 | M12: =IF(L12=" "," ",(IF($L12>0,INDEX('Bin Analysis'!$C$3:$S$10110,MATCH($L12,'Bin Analysis'!$L$3:$L$10110,0),MATCH(M$5,'Bin Analysis'!$C$2:$S$2,0))," "))) -> 17 | N12: =IF($L12=" "," ",(IF($M12=FALSE," ",(IF($M12>0,INDEX('Bin Analysis'!$C$3:$S$10110,MATCH($L12,'Bin Analysis'!$L$3:$L$10110,0),MATCH(N$5,'Bin Analysis'!$C$2:$S$2,0))," "))))) -> 0 | O12: =IF($L12=" "," ",(IF($M12=FALSE," ",(IF($M12>0,INDEX('Bin Analysis'!$C$3:$S$10110,MATCH($L12,'Bin Analysis'!$L$3:$L$10110,0),MATCH(O$5,'Bin Analysis'!$C$2:$S$2,0))," "))))) -> 0.5625 | P12: =IF($L12=" "," ",(IF($M12=FALSE," ",(IF($M12>0,INDEX('Bin Analysis'!$C$3:$S$10110,MATCH($L12,'Bin Analysis'!$L$3:$L$10110,0),MATCH(P$5,'Bin Analysis'!$C$2:$S$2,0))," "))))) -> 0.3 | Q12: =IF($L12=" "," ",(IF($M12=FALSE," ",(IF($M12>0,INDEX('Bin Analysis'!$C$3:$S$10110,MATCH($L12,'Bin Analysis'!$L$3:$L$10110,0),MATCH(Q$5,'Bin Analysis'!$C$2:$S$2,0))," "))))) -> 0.26086957 | R12: =IF($L12=" "," ",(IF($M12=FALSE," ",(IF($M12>0,INDEX('Bin Analysis'!$C$3:$S$10110,MATCH($L12,'Bin Analysis'!$L$3:$L$10110,0),MATCH(R$5,'Bin Analysis'!$C$2:$S$2,0))," "))))) -> 0 | S12: =IF($L12=" "," ",(IF($M12=FALSE," ",(IF($M12>0,INDEX('Bin Analysis'!$C$3:$S$10110,MATCH($L12,'Bin Analysis'!$L$3:$L$10110,0),MATCH(S$5,'Bin Analysis'!$C$2:$S$2,0))," "))))) -> no | T12: =Assignments!K11 -> 0.88656097 | U12: =Assignments!L11 -> 0.085914381 | V12: =Assignments!V11 -> Moderate | Z12: 0.6 to < 0.7 | AA12: =COUNTIF(N$7:N$427,"<0.7")-SUM(AA6:AA11) -> 1 | AB12: =COUNTIF(O$7:O$427,"<0.7")-SUM(AB6:AB11) -> 13 | AC12: =COUNTIF(P$7:P$427,"<0.7")-SUM(AC6:AC11) -> 60 | AD12: =COUNTIF(Q$7:Q$427,"<0.7")-SUM(AD6:AD11) -> 55 | AE12: =COUNTIF(R$7:R$427,"<0.7")-SUM(AE6:AE11) -> 17
A13: E | B13: 1 | C13: F | D13: 0.78511797 | E13: 0.04382868 | G13: =IFERROR('Data Transformation'!M11," ") -> 6 | I13: (leave blank if no override) | L13: =$G14 -> 7 | M13: =IF(L13=" "," ",(IF($L13>0,INDEX('Bin Analysis'!$C$3:$S$10110,MATCH($L13,'Bin Analysis'!$L$3:$L$10110,0),MATCH(M$5,'Bin Analysis'!$C$2:$S$2,0))," "))) -> 19 | N13: =IF($L13=" "," ",(IF($M13=FALSE," ",(IF($M13>0,INDEX('Bin Analysis'!$C$3:$S$10110,MATCH($L13,'Bin Analysis'!$L$3:$L$10110,0),MATCH(N$5,'Bin Analysis'!$C$2:$S$2,0))," "))))) -> 0 | O13: =IF($L13=" "," ",(IF($M13=FALSE," ",(IF($M13>0,INDEX('Bin Analysis'!$C$3:$S$10110,MATCH($L13,'Bin Analysis'!$L$3:$L$10110,0),MATCH(O$5,'Bin Analysis'!$C$2:$S$2,0))," "))))) -> 0.16666667 | P13: =IF($L13=" "," ",(IF($M13=FALSE," ",(IF($M13>0,INDEX('Bin Analysis'!$C$3:$S$10110,MATCH($L13,'Bin Analysis'!$L$3:$L$10110,0),MATCH(P$5,'Bin Analysis'!$C$2:$S$2,0))," "))))) -> 0.6 | Q13: =IF($L13=" "," ",(IF($M13=FALSE," ",(IF($M13>0,INDEX('Bin Analysis'!$C$3:$S$10110,MATCH($L13,'Bin Analysis'!$L$3:$L$10110,0),MATCH(Q$5,'Bin Analysis'!$C$2:$S$2,0))," "))))) -> 0.52173913 | R13: =IF($L13=" "," ",(IF($M13=FALSE," ",(IF($M13>0,INDEX('Bin Analysis'!$C$3:$S$10110,MATCH($L13,'Bin Analysis'!$L$3:$L$10110,0),MATCH(R$5,'Bin Analysis'!$C$2:$S$2,0))," "))))) -> 0.66666667 | S13: =IF($L13=" "," ",(IF($M13=FALSE," ",(IF($M13>0,INDEX('Bin Analysis'!$C$3:$S$10110,MATCH($L13,'Bin Analysis'!$L$3:$L$10110,0),MATCH(S$5,'Bin Analysis'!$C$2:$S$2,0))," "))))) -> no | T13: =Assignments!K12 -> 0.44513657 | U13: =Assignments!L12 -> 0.32432725 | V13: =Assignments!V12 -> Toggle | Z13: 0.7 to < 0.8 | AA13: =COUNTIF(N$7:N$427,"<0.8")-SUM(AA6:AA12) -> 1 | AB13: =COUNTIF(O$7:O$427,"<0.8")-SUM(AB6:AB12) -> 16 | AC13: =COUNTIF(P$7:P$427,"<0.8")-SUM(AC6:AC12) -> 51 | AD13: =COUNTIF(Q$7:Q$427,"<0.8")-SUM(AD6:AD12) -> 14 | AE13: =COUNTIF(R$7:R$427,"<0.8")-SUM(AE6:AE12) -> 21
A14: E | B14: 1 | C14: Q | D14: 0.79486416 | E14: 0.05948314 | G14: =IFERROR('Data Transformation'!M12," ") -> 7 | I14: Number of values greater than the maximum | J14: =COUNTIF(D7:D8007,">"&J12) -> 0 | L14: =$G15 -> 8 | M14: =IF(L14=" "," ",(IF($L14>0,INDEX('Bin Analysis'!$C$3:$S$10110,MATCH($L14,'Bin Analysis'!$L$3:$L$10110,0),MATCH(M$5,'Bin Analysis'!$C$2:$S$2,0))," "))) -> 18 | N14: =IF($L14=" "," ",(IF($M14=FALSE," ",(IF($M14>0,INDEX('Bin Analysis'!$C$3:$S$10110,MATCH($L14,'Bin Analysis'!$L$3:$L$10110,0),MATCH(N$5,'Bin Analysis'!$C$2:$S$2,0))," "))))) -> 0 | O14: =IF($L14=" "," ",(IF($M14=FALSE," ",(IF($M14>0,INDEX('Bin Analysis'!$C$3:$S$10110,MATCH($L14,'Bin Analysis'!$L$3:$L$10110,0),MATCH(O$5,'Bin Analysis'!$C$2:$S$2,0))," "))))) -> 0.41176471 | P14: =IF($L14=" "," ",(IF($M14=FALSE," ",(IF($M14>0,INDEX('Bin Analysis'!$C$3:$S$10110,MATCH($L14,'Bin Analysis'!$L$3:$L$10110,0),MATCH(P$5,'Bin Analysis'!$C$2:$S$2,0))," "))))) -> 0.6 | Q14: =IF($L14=" "," ",(IF($M14=FALSE," ",(IF($M14>0,INDEX('Bin Analysis'!$C$3:$S$10110,MATCH($L14,'Bin Analysis'!$L$3:$L$10110,0),MATCH(Q$5,'Bin Analysis'!$C$2:$S$2,0))," "))))) -> 0.56521739 | R14: =IF($L14=" "," ",(IF($M14=FALSE," ",(IF($M14>0,INDEX('Bin Analysis'!$C$3:$S$10110,MATCH($L14,'Bin Analysis'!$L$3:$L$10110,0),MATCH(R$5,'Bin Analysis'!$C$2:$S$2,0))," "))))) -> 0.11764706 | S14: =IF($L14=" "," ",(IF($M14=FALSE," ",(IF($M14>0,INDEX('Bin Analysis'!$C$3:$S$10110,MATCH($L14,'Bin Analysis'!$L$3:$L$10110,0),MATCH(S$5,'Bin Analysis'!$C$2:$S$2,0))," "))))) -> no | T14: =Assignments!K13 -> 0.74757013 | U14: =Assignments!L13 -> 0.23142232 | V14: =Assignments!V13 -> Rheostat | Z14: 0.8 to < 0.9 | AA14: =COUNTIF(N$7:N$427,"<0.9")-SUM(AA6:AA13) -> 1 | AB14: =COUNTIF(O$7:O$427,"<0.9")-SUM(AB6:AB13) -> 8 | AC14: =COUNTIF(P$7:P$427,"<0.9")-SUM(AC6:AC13) -> 13 | AD14: =COUNTIF(Q$7:Q$427,"<0.9")-SUM(AD6:AD13) -> 0 | AE14: =COUNTIF(R$7:R$427,"<0.9")-SUM(AE6:AE13) -> 23
A15: E | B15: 1 | C15: L | D15: 0.81903011 | E15: 0.02535047 | G15: =IFERROR('Data Transformation'!M13," ") -> 8 | L15: =$G16 -> 9 | M15: =IF(L15=" "," ",(IF($L15>0,INDEX('Bin Analysis'!$C$3:$S$10110,MATCH($L15,'Bin Analysis'!$L$3:$L$10110,0),MATCH(M$5,'Bin Analysis'!$C$2:$S$2,0))," "))) -> 17 | N15: =IF($L15=" "," ",(IF($M15=FALSE," ",(IF($M15>0,INDEX('Bin Analysis'!$C$3:$S$10110,MATCH($L15,'Bin Analysis'!$L$3:$L$10110,0),MATCH(N$5,'Bin Analysis'!$C$2:$S$2,0))," "))))) -> 0 | O15: =IF($L15=" "," ",(IF($M15=FALSE," ",(IF($M15>0,INDEX('Bin Analysis'!$C$3:$S$10110,MATCH($L15,'Bin Analysis'!$L$3:$L$10110,0),MATCH(O$5,'Bin Analysis'!$C$2:$S$2,0))," "))))) -> 0.3125 | P15: =IF($L15=" "," ",(IF($M15=FALSE," ",(IF($M15>0,INDEX('Bin Analysis'!$C$3:$S$10110,MATCH($L15,'Bin Analysis'!$L$3:$L$10110,0),MATCH(P$5,'Bin Analysis'!$C$2:$S$2,0))," "))))) -> 0.7 | Q15: =IF($L15=" "," ",(IF($M15=FALSE," ",(IF($M15>0,INDEX('Bin Analysis'!$C$3:$S$10110,MATCH($L15,'Bin Analysis'!$L$3:$L$10110,0),MATCH(Q$5,'Bin Analysis'!$C$2:$S$2,0))," "))))) -> 0.65217391 | R15: =IF($L15=" "," ",(IF($M15=FALSE," ",(IF($M15>0,INDEX('Bin Analysis'!$C$3:$S$10110,MATCH($L15,'Bin Analysis'!$L$3:$L$10110,0),MATCH(R$5,'Bin Analysis'!$C$2:$S$2,0))," "))))) -> 0.125 | S15: =IF($L15=" "," ",(IF($M15=FALSE," ",(IF($M15>0,INDEX('Bin Analysis'!$C$3:$S$10110,MATCH($L15,'Bin Analysis'!$L$3:$L$10110,0),MATCH(S$5,'Bin Analysis'!$C$2:$S$2,0))," "))))) -> no | T15: =Assignments!K14 -> 0.73281933 | U15: =Assignments!L14 -> 0.24465019 | V15: =Assignments!V14 -> Rheostat | Z15: 0.9 to 1.0 | AA15: =COUNTIF(N$7:N$427,"<1.01")-SUM(AA6:AA14) -> 1 | AB15: =COUNTIF(O$7:O$427,"<1.01")-SUM(AB6:AB14) -> 11 | AC15: =COUNTIF(P$7:P$427,"<1.01")-SUM(AC6:AC14) -> 0 | AD15: =COUNTIF(Q$7:Q$427,"<1.01")-SUM(AD6:AD14) -> 0 | AE15: =COUNTIF(R$7:R$427,"<1.01")-SUM(AE6:AE14) -> 47
A16: E | B16: 1 | C16: R | D16: 0.85267206 | E16: 0.03321703 | G16: =IFERROR('Data Transformation'!M14," ") -> 9 | I16: Nonfunctional protein value ("Dead") | J16: minimum | L16: =$G17 -> 10 | M16: =IF(L16=" "," ",(IF($L16>0,INDEX('Bin Analysis'!$C$3:$S$10110,MATCH($L16,'Bin Analysis'!$L$3:$L$10110,0),MATCH(M$5,'Bin Analysis'!$C$2:$S$2,0))," "))) -> 14 | N16: =IF($L16=" "," ",(IF($M16=FALSE," ",(IF($M16>0,INDEX('Bin Analysis'!$C$3:$S$10110,MATCH($L16,'Bin Analysis'!$L$3:$L$10110,0),MATCH(N$5,'Bin Analysis'!$C$2:$S$2,0))," "))))) -> 0 | O16: =IF($L16=" "," ",(IF($M16=FALSE," ",(IF($M16>0,INDEX('Bin Analysis'!$C$3:$S$10110,MATCH($L16,'Bin Analysis'!$L$3:$L$10110,0),MATCH(O$5,'Bin Analysis'!$C$2:$S$2,0))," "))))) -> 0 | P16: =IF($L16=" "," ",(IF($M16=FALSE," ",(IF($M16>0,INDEX('Bin Analysis'!$C$3:$S$10110,MATCH($L16,'Bin Analysis'!$L$3:$L$10110,0),MATCH(P$5,'Bin Analysis'!$C$2:$S$2,0))," "))))) -> 0.4 | Q16: =IF($L16=" "," ",(IF($M16=FALSE," ",(IF($M16>0,INDEX('Bin Analysis'!$C$3:$S$10110,MATCH($L16,'Bin Analysis'!$L$3:$L$10110,0),MATCH(Q$5,'Bin Analysis'!$C$2:$S$2,0))," "))))) -> 0.30434783 | R16: =IF($L16=" "," ",(IF($M16=FALSE," ",(IF($M16>0,INDEX('Bin Analysis'!$C$3:$S$10110,MATCH($L16,'Bin Analysis'!$L$3:$L$10110,0),MATCH(R$5,'Bin Analysis'!$C$2:$S$2,0))," "))))) -> 0.53846154 | S16: =IF($L16=" "," ",(IF($M16=FALSE," ",(IF($M16>0,INDEX('Bin Analysis'!$C$3:$S$10110,MATCH($L16,'Bin Analysis'!$L$3:$L$10110,0),MATCH(S$5,'Bin Analysis'!$C$2:$S$2,0))," "))))) -> no | T16: =Assignments!K15 -> 0.33792936 | U16: =Assignments!L15 -> 0.1532218 | V16: =Assignments!V15 -> Adverse | Z16: sum | AA16: =SUM(AA6:AA15) -> 313 | AB16: =SUM(AB6:AB15) -> 313 | AC16: =SUM(AC6:AC15) -> 313 | AD16: =SUM(AD6:AD15) -> 313 | AE16: =SUM(AE6:AE15) -> 313
A17: E | B17: 1 | C17: M | D17: 0.8750614 | E17: 0.05374248 | G17: =IFERROR('Data Transformation'!M15," ") -> 10 | J17: =IF(J16="maximum",'Data Transformation'!U9,'Data Transformation'!U8) -> 0.19 | L17: =$G18 -> 11 | M17: =IF(L17=" "," ",(IF($L17>0,INDEX('Bin Analysis'!$C$3:$S$10110,MATCH($L17,'Bin Analysis'!$L$3:$L$10110,0),MATCH(M$5,'Bin Analysis'!$C$2:$S$2,0))," "))) -> 16 | N17: =IF($L17=" "," ",(IF($M17=FALSE," ",(IF($M17>0,INDEX('Bin Analysis'!$C$3:$S$10110,MATCH($L17,'Bin Analysis'!$L$3:$L$10110,0),MATCH(N$5,'Bin Analysis'!$C$2:$S$2,0))," "))))) -> 0 | O17: =IF($L17=" "," ",(IF($M17=FALSE," ",(IF($M17>0,INDEX('Bin Analysis'!$C$3:$S$10110,MATCH($L17,'Bin Analysis'!$L$3:$L$10110,0),MATCH(O$5,'Bin Analysis'!$C$2:$S$2,0))," "))))) -> 0 | P17: =IF($L17=" "," ",(IF($M17=FALSE," ",(IF($M17>0,INDEX('Bin Analysis'!$C$3:$S$10110,MATCH($L17,'Bin Analysis'!$L$3:$L$10110,0),MATCH(P$5,'Bin Analysis'!$C$2:$S$2,0))," "))))) -> 0.5 | Q17: =IF($L17=" "," ",(IF($M17=FALSE," ",(IF($M17>0,INDEX('Bin Analysis'!$C$3:$S$10110,MATCH($L17,'Bin Analysis'!$L$3:$L$10110,0),MATCH(Q$5,'Bin Analysis'!$C$2:$S$2,0))," "))))) -> 0.52173913 | R17: =IF($L17=" "," ",(IF($M17=FALSE," ",(IF($M17>0,INDEX('Bin Analysis'!$C$3:$S$10110,MATCH($L17,'Bin Analysis'!$L$3:$L$10110,0),MATCH(R$5,'Bin Analysis'!$C$2:$S$2,0))," "))))) -> 0 | S17: =IF($L17=" "," ",(IF($M17=FALSE," ",(IF($M17>0,INDEX('Bin Analysis'!$C$3:$S$10110,MATCH($L17,'Bin Analysis'!$L$3:$L$10110,0),MATCH(S$5,'Bin Analysis'!$C$2:$S$2,0))," "))))) -> no | T17: =Assignments!K16 -> 0.55615085 | U17: =Assignments!L16 -> 0.10621202 | V17: =Assignments!V16 -> Rheostat
A18: E | B18: 1 | C18: T | D18: 0.87705694 | E18: 0.03020404 | G18: =IFERROR('Data Transformation'!M16," ") -> 11 | L18: =$G19 -> 12 | M18: =IF(L18=" "," ",(IF($L18>0,INDEX('Bin Analysis'!$C$3:$S$10110,MATCH($L18,'Bin Analysis'!$L$3:$L$10110,0),MATCH(M$5,'Bin Analysis'!$C$2:$S$2,0))," "))) -> 7 | N18: =IF($L18=" "," ",(IF($M18=FALSE," ",(IF($M18>0,INDEX('Bin Analysis'!$C$3:$S$10110,MATCH($L18,'Bin Analysis'!$L$3:$L$10110,0),MATCH(N$5,'Bin Analysis'!$C$2:$S$2,0))," "))))) -> 0 | O18: =IF($L18=" "," ",(IF($M18=FALSE," ",(IF($M18>0,INDEX('Bin Analysis'!$C$3:$S$10110,MATCH($L18,'Bin Analysis'!$L$3:$L$10110,0),MATCH(O$5,'Bin Analysis'!$C$2:$S$2,0))," "))))) -> 0 | P18: =IF($L18=" "," ",(IF($M18=FALSE," ",(IF($M18>0,INDEX('Bin Analysis'!$C$3:$S$10110,MATCH($L18,'Bin Analysis'!$L$3:$L$10110,0),MATCH(P$5,'Bin Analysis'!$C$2:$S$2,0))," "))))) -> 0.4 | Q18: =IF($L18=" "," ",(IF($M18=FALSE," ",(IF($M18>0,INDEX('Bin Analysis'!$C$3:$S$10110,MATCH($L18,'Bin Analysis'!$L$3:$L$10110,0),MATCH(Q$5,'Bin Analysis'!$C$2:$S$2,0))," "))))) -> 0.30434783 | R18: =IF($L18=" "," ",(IF($M18=FALSE," ",(IF($M18>0,INDEX('Bin Analysis'!$C$3:$S$10110,MATCH($L18,'Bin Analysis'!$L$3:$L$10110,0),MATCH(R$5,'Bin Analysis'!$C$2:$S$2,0))," "))))) -> 0.5 | S18: =IF($L18=" "," ",(IF($M18=FALSE," ",(IF($M18>0,INDEX('Bin Analysis'!$C$3:$S$10110,MATCH($L18,'Bin Analysis'!$L$3:$L$10110,0),MATCH(S$5,'Bin Analysis'!$C$2:$S$2,0))," "))))) -> no | T18: =Assignments!K17 -> 0.33458867 | U18: =Assignments!L17 -> 0.20285106 | V18: =Assignments!V17 -> Adverse
A19: E | B19: 1 | C19: K | D19: 0.8785445 | E19: 0.06149139 | G19: =IFERROR('Data Transformation'!M17," ") -> 12 | I19: Error override | L19: =$G20 -> 13 | M19: =IF(L19=" "," ",(IF($L19>0,INDEX('Bin Analysis'!$C$3:$S$10110,MATCH($L19,'Bin Analysis'!$L$3:$L$10110,0),MATCH(M$5,'Bin Analysis'!$C$2:$S$2,0))," "))) -> 7 | N19: =IF($L19=" "," ",(IF($M19=FALSE," ",(IF($M19>0,INDEX('Bin Analysis'!$C$3:$S$10110,MATCH($L19,'Bin Analysis'!$L$3:$L$10110,0),MATCH(N$5,'Bin Analysis'!$C$2:$S$2,0))," "))))) -> 0 | O19: =IF($L19=" "," ",(IF($M19=FALSE," ",(IF($M19>0,INDEX('Bin Analysis'!$C$3:$S$10110,MATCH($L19,'Bin Analysis'!$L$3:$L$10110,0),MATCH(O$5,'Bin Analysis'!$C$2:$S$2,0))," "))))) -> 0.33333333 | P19: =IF($L19=" "," ",(IF($M19=FALSE," ",(IF($M19>0,INDEX('Bin Analysis'!$C$3:$S$10110,MATCH($L19,'Bin Analysis'!$L$3:$L$10110,0),MATCH(P$5,'Bin Analysis'!$C$2:$S$2,0))," "))))) -> 0.6 | Q19: =IF($L19=" "," ",(IF($M19=FALSE," ",(IF($M19>0,INDEX('Bin Analysis'!$C$3:$S$10110,MATCH($L19,'Bin Analysis'!$L$3:$L$10110,0),MATCH(Q$5,'Bin Analysis'!$C$2:$S$2,0))," "))))) -> 0.60869565 | R19: =IF($L19=" "," ",(IF($M19=FALSE," ",(IF($M19>0,INDEX('Bin Analysis'!$C$3:$S$10110,MATCH($L19,'Bin Analysis'!$L$3:$L$10110,0),MATCH(R$5,'Bin Analysis'!$C$2:$S$2,0))," "))))) -> 0 | S19: =IF($L19=" "," ",(IF($M19=FALSE," ",(IF($M19>0,INDEX('Bin Analysis'!$C$3:$S$10110,MATCH($L19,'Bin Analysis'!$L$3:$L$10110,0),MATCH(S$5,'Bin Analysis'!$C$2:$S$2,0))," "))))) -> no | T19: =Assignments!K18 -> 0.72540735 | U19: =Assignments!L18 -> 0.26793171 | V19: =Assignments!V18 -> Rheostat
A20: E | B20: 1 | C20: P | D20: 0.89276818 | E20: 0.03223224 | G20: =IFERROR('Data Transformation'!M18," ") -> 13 | I20: =IF(AND(J4="yes",NOT(J19="")),"see note #3 under the 'Entering data on the Input and Summary Results worksheet' section on first page regarding log and error","leave blank if no override") -> leave blank if no override | L20: =$G21 -> 14 | M20: =IF(L20=" "," ",(IF($L20>0,INDEX('Bin Analysis'!$C$3:$S$10110,MATCH($L20,'Bin Analysis'!$L$3:$L$10110,0),MATCH(M$5,'Bin Analysis'!$C$2:$S$2,0))," "))) -> 10 | N20: =IF($L20=" "," ",(IF($M20=FALSE," ",(IF($M20>0,INDEX('Bin Analysis'!$C$3:$S$10110,MATCH($L20,'Bin Analysis'!$L$3:$L$10110,0),MATCH(N$5,'Bin Analysis'!$C$2:$S$2,0))," "))))) -> 0 | O20: =IF($L20=" "," ",(IF($M20=FALSE," ",(IF($M20>0,INDEX('Bin Analysis'!$C$3:$S$10110,MATCH($L20,'Bin Analysis'!$L$3:$L$10110,0),MATCH(O$5,'Bin Analysis'!$C$2:$S$2,0))," "))))) -> 0.33333333 | P20: =IF($L20=" "," ",(IF($M20=FALSE," ",(IF($M20>0,INDEX('Bin Analysis'!$C$3:$S$10110,MATCH($L20,'Bin Analysis'!$L$3:$L$10110,0),MATCH(P$5,'Bin Analysis'!$C$2:$S$2,0))," "))))) -> 0.5 | Q20: =IF($L20=" "," ",(IF($M20=FALSE," ",(IF($M20>0,INDEX('Bin Analysis'!$C$3:$S$10110,MATCH($L20,'Bin Analysis'!$L$3:$L$10110,0),MATCH(Q$5,'Bin Analysis'!$C$2:$S$2,0))," "))))) -> 0.52173913 | R20: =IF($L20=" "," ",(IF($M20=FALSE," ",(IF($M20>0,INDEX('Bin Analysis'!$C$3:$S$10110,MATCH($L20,'Bin Analysis'!$L$3:$L$10110,0),MATCH(R$5,'Bin Analysis'!$C$2:$S$2,0))," "))))) -> 0 | S20: =IF($L20=" "," ",(IF($M20=FALSE," ",(IF($M20>0,INDEX('Bin Analysis'!$C$3:$S$10110,MATCH($L20,'Bin Analysis'!$L$3:$L$10110,0),MATCH(S$5,'Bin Analysis'!$C$2:$S$2,0))," "))))) -> no | T20: =Assignments!K19 -> 0.804095 | U20: =Assignments!L19 -> 0.16490741 | V20: =Assignments!V19 -> Rheostat
A21: E | B21: 1 | C21: N | D21: 0.92111225 | E21: 0.04889851 | G21: =IFERROR('Data Transformation'!M19," ") -> 14 | L21: =$G22 -> 15 | M21: =IF(L21=" "," ",(IF($L21>0,INDEX('Bin Analysis'!$C$3:$S$10110,MATCH($L21,'Bin Analysis'!$L$3:$L$10110,0),MATCH(M$5,'Bin Analysis'!$C$2:$S$2,0))," "))) -> 12 | N21: =IF($L21=" "," ",(IF($M21=FALSE," ",(IF($M21>0,INDEX('Bin Analysis'!$C$3:$S$10110,MATCH($L21,'Bin Analysis'!$L$3:$L$10110,0),MATCH(N$5,'Bin Analysis'!$C$2:$S$2,0))," "))))) -> 0 | O21: =IF($L21=" "," ",(IF($M21=FALSE," ",(IF($M21>0,INDEX('Bin Analysis'!$C$3:$S$10110,MATCH($L21,'Bin Analysis'!$L$3:$L$10110,0),MATCH(O$5,'Bin Analysis'!$C$2:$S$2,0))," "))))) -> 0.090909091 | P21: =IF($L21=" "," ",(IF($M21=FALSE," ",(IF($M21>0,INDEX('Bin Analysis'!$C$3:$S$10110,MATCH($L21,'Bin Analysis'!$L$3:$L$10110,0),MATCH(P$5,'Bin Analysis'!$C$2:$S$2,0))," "))))) -> 0.7 | Q21: =IF($L21=" "," ",(IF($M21=FALSE," ",(IF($M21>0,INDEX('Bin Analysis'!$C$3:$S$10110,MATCH($L21,'Bin Analysis'!$L$3:$L$10110,0),MATCH(Q$5,'Bin Analysis'!$C$2:$S$2,0))," "))))) -> 0.65217391 | R21: =IF($L21=" "," ",(IF($M21=FALSE," ",(IF($M21>0,INDEX('Bin Analysis'!$C$3:$S$10110,MATCH($L21,'Bin Analysis'!$L$3:$L$10110,0),MATCH(R$5,'Bin Analysis'!$C$2:$S$2,0))," "))))) -> 0.18181818 | S21: =IF($L21=" "," ",(IF($M21=FALSE," ",(IF($M21>0,INDEX('Bin Analysis'!$C$3:$S$10110,MATCH($L21,'Bin Analysis'!$L$3:$L$10110,0),MATCH(S$5,'Bin Analysis'!$C$2:$S$2,0))," "))))) -> no | T21: =Assignments!K20 -> 0.55883661 | U21: =Assignments!L20 -> 0.21789093 | V21: =Assignments!V20 -> Rheostat
A22: E | B22: 1 | C22: A | D22: 0.92206838 | E22: 0.04363049 | G22: =IFERROR('Data Transformation'!M20," ") -> 15 | I22: Recommended number of bins | J22: ='Data Transformation'!R23 -> 10 | L22: =$G23 -> 16 | M22: =IF(L22=" "," ",(IF($L22>0,INDEX('Bin Analysis'!$C$3:$S$10110,MATCH($L22,'Bin Analysis'!$L$3:$L$10110,0),MATCH(M$5,'Bin Analysis'!$C$2:$S$2,0))," "))) -> 7 | N22: =IF($L22=" "," ",(IF($M22=FALSE," ",(IF($M22>0,INDEX('Bin Analysis'!$C$3:$S$10110,MATCH($L22,'Bin Analysis'!$L$3:$L$10110,0),MATCH(N$5,'Bin Analysis'!$C$2:$S$2,0))," "))))) -> 0 | O22: =IF($L22=" "," ",(IF($M22=FALSE," ",(IF($M22>0,INDEX('Bin Analysis'!$C$3:$S$10110,MATCH($L22,'Bin Analysis'!$L$3:$L$10110,0),MATCH(O$5,'Bin Analysis'!$C$2:$S$2,0))," "))))) -> 0.33333333 | P22: =IF($L22=" "," ",(IF($M22=FALSE," ",(IF($M22>0,INDEX('Bin Analysis'!$C$3:$S$10110,MATCH($L22,'Bin Analysis'!$L$3:$L$10110,0),MATCH(P$5,'Bin Analysis'!$C$2:$S$2,0))," "))))) -> 0.5 | Q22: =IF($L22=" "," ",(IF($M22=FALSE," ",(IF($M22>0,INDEX('Bin Analysis'!$C$3:$S$10110,MATCH($L22,'Bin Analysis'!$L$3:$L$10110,0),MATCH(Q$5,'Bin Analysis'!$C$2:$S$2,0))," "))))) -> 0.43478261 | R22: =IF($L22=" "," ",(IF($M22=FALSE," ",(IF($M22>0,INDEX('Bin Analysis'!$C$3:$S$10110,MATCH($L22,'Bin Analysis'!$L$3:$L$10110,0),MATCH(R$5,'Bin Analysis'!$C$2:$S$2,0))," "))))) -> 0.16666667 | S22: =IF($L22=" "," ",(IF($M22=FALSE," ",(IF($M22>0,INDEX('Bin Analysis'!$C$3:$S$10110,MATCH($L22,'Bin Analysis'!$L$3:$L$10110,0),MATCH(S$5,'Bin Analysis'!$C$2:$S$2,0))," "))))) -> no | T22: =Assignments!K21 -> 0.70657773 | U22: =Assignments!L21 -> 0.21371467 | V22: =Assignments!V21 -> Moderate
A23: E | B23: 1 | C23: D | D23: 1.0184158 | E23: 0.04666058 | G23: =IFERROR('Data Transformation'!M21," ") -> 16 | I23: Number of bins override | J23: 10 | L23: =$G24 -> 17 | M23: =IF(L23=" "," ",(IF($L23>0,INDEX('Bin Analysis'!$C$3:$S$10110,MATCH($L23,'Bin Analysis'!$L$3:$L$10110,0),MATCH(M$5,'Bin Analysis'!$C$2:$S$2,0))," "))) -> 11 | N23: =IF($L23=" "," ",(IF($M23=FALSE," ",(IF($M23>0,INDEX('Bin Analysis'!$C$3:$S$10110,MATCH($L23,'Bin Analysis'!$L$3:$L$10110,0),MATCH(N$5,'Bin Analysis'!$C$2:$S$2,0))," "))))) -> 0 | O23: =IF($L23=" "," ",(IF($M23=FALSE," ",(IF($M23>0,INDEX('Bin Analysis'!$C$3:$S$10110,MATCH($L23,'Bin Analysis'!$L$3:$L$10110,0),MATCH(O$5,'Bin Analysis'!$C$2:$S$2,0))," "))))) -> 0 | P23: =IF($L23=" "," ",(IF($M23=FALSE," ",(IF($M23>0,INDEX('Bin Analysis'!$C$3:$S$10110,MATCH($L23,'Bin Analysis'!$L$3:$L$10110,0),MATCH(P$5,'Bin Analysis'!$C$2:$S$2,0))," "))))) -> 0.6 | Q23: =IF($L23=" "," ",(IF($M23=FALSE," ",(IF($M23>0,INDEX('Bin Analysis'!$C$3:$S$10110,MATCH($L23,'Bin Analysis'!$L$3:$L$10110,0),MATCH(Q$5,'Bin Analysis'!$C$2:$S$2,0))," "))))) -> 0.56521739 | R23: =IF($L23=" "," ",(IF($M23=FALSE," ",(IF($M23>0,INDEX('Bin Analysis'!$C$3:$S$10110,MATCH($L23,'Bin Analysis'!$L$3:$L$10110,0),MATCH(R$5,'Bin Analysis'!$C$2:$S$2,0))," "))))) -> 0.1 | S23: =IF($L23=" "," ",(IF($M23=FALSE," ",(IF($M23>0,INDEX('Bin Analysis'!$C$3:$S$10110,MATCH($L23,'Bin Analysis'!$L$3:$L$10110,0),MATCH(S$5,'Bin Analysis'!$C$2:$S$2,0))," "))))) -> no | T23: =Assignments!K22 -> 0.53952543 | U23: =Assignments!L22 -> 0.13782369 | V23: =Assignments!V22 -> Rheostat
A24: V | B24: 2 | C24: T | D24: 0.92384159 | E24: 0.03257349 | G24: =IFERROR('Data Transformation'!M22," ") -> 17 | I24: (leave blank if no override) | L24: =$G25 -> 18 | M24: =IF(L24=" "," ",(IF($L24>0,INDEX('Bin Analysis'!$C$3:$S$10110,MATCH($L24,'Bin Analysis'!$L$3:$L$10110,0),MATCH(M$5,'Bin Analysis'!$C$2:$S$2,0))," "))) -> 17 | N24: =IF($L24=" "," ",(IF($M24=FALSE," ",(IF($M24>0,INDEX('Bin Analysis'!$C$3:$S$10110,MATCH($L24,'Bin Analysis'!$L$3:$L$10110,0),MATCH(N$5,'Bin Analysis'!$C$2:$S$2,0))," "))))) -> 0 | O24: =IF($L24=" "," ",(IF($M24=FALSE," ",(IF($M24>0,INDEX('Bin Analysis'!$C$3:$S$10110,MATCH($L24,'Bin Analysis'!$L$3:$L$10110,0),MATCH(O$5,'Bin Analysis'!$C$2:$S$2,0))," "))))) -> 0.875 | P24: =IF($L24=" "," ",(IF($M24=FALSE," ",(IF($M24>0,INDEX('Bin Analysis'!$C$3:$S$10110,MATCH($L24,'Bin Analysis'!$L$3:$L$10110,0),MATCH(P$5,'Bin Analysis'!$C$2:$S$2,0))," "))))) -> 0.4 | Q24: =IF($L24=" "," ",(IF($M24=FALSE," ",(IF($M24>0,INDEX('Bin Analysis'!$C$3:$S$10110,MATCH($L24,'Bin Analysis'!$L$3:$L$10110,0),MATCH(Q$5,'Bin Analysis'!$C$2:$S$2,0))," "))))) -> 0.39130435 | R24: =IF($L24=" "," ",(IF($M24=FALSE," ",(IF($M24>0,INDEX('Bin Analysis'!$C$3:$S$10110,MATCH($L24,'Bin Analysis'!$L$3:$L$10110,0),MATCH(R$5,'Bin Analysis'!$C$2:$S$2,0))," "))))) -> 0 | S24: =IF($L24=" "," ",(IF($M24=FALSE," ",(IF($M24>0,INDEX('Bin Analysis'!$C$3:$S$10110,MATCH($L24,'Bin Analysis'!$L$3:$L$10110,0),MATCH(S$5,'Bin Analysis'!$C$2:$S$2,0))," "))))) -> no | T24: =Assignments!K23 -> 0.92731962 | U24: =Assignments!L23 -> 0.090872256 | V24: =Assignments!V23 -> Neutral
A25: V | B25: 2 | C25: G | D25: 0.9379303 | E25: 0.04741444 | G25: =IFERROR('Data Transformation'!M23," ") -> 18 | I25: Rheostate/toggle bin width | J25: ='Data Transformation'!R25 -> 0.131 | L25: =$G26 -> 19 | M25: =IF(L25=" "," ",(IF($L25>0,INDEX('Bin Analysis'!$C$3:$S$10110,MATCH($L25,'Bin Analysis'!$L$3:$L$10110,0),MATCH(M$5,'Bin Analysis'!$C$2:$S$2,0))," "))) -> 20 | N25: =IF($L25=" "," ",(IF($M25=FALSE," ",(IF($M25>0,INDEX('Bin Analysis'!$C$3:$S$10110,MATCH($L25,'Bin Analysis'!$L$3:$L$10110,0),MATCH(N$5,'Bin Analysis'!$C$2:$S$2,0))," "))))) -> 0 | O25: =IF($L25=" "," ",(IF($M25=FALSE," ",(IF($M25>0,INDEX('Bin Analysis'!$C$3:$S$10110,MATCH($L25,'Bin Analysis'!$L$3:$L$10110,0),MATCH(O$5,'Bin Analysis'!$C$2:$S$2,0))," "))))) -> 0.42105263 | P25: =IF($L25=" "," ",(IF($M25=FALSE," ",(IF($M25>0,INDEX('Bin Analysis'!$C$3:$S$10110,MATCH($L25,'Bin Analysis'!$L$3:$L$10110,0),MATCH(P$5,'Bin Analysis'!$C$2:$S$2,0))," "))))) -> 0.5 | Q25: =IF($L25=" "," ",(IF($M25=FALSE," ",(IF($M25>0,INDEX('Bin Analysis'!$C$3:$S$10110,MATCH($L25,'Bin Analysis'!$L$3:$L$10110,0),MATCH(Q$5,'Bin Analysis'!$C$2:$S$2,0))," "))))) -> 0.52173913 | R25: =IF($L25=" "," ",(IF($M25=FALSE," ",(IF($M25>0,INDEX('Bin Analysis'!$C$3:$S$10110,MATCH($L25,'Bin Analysis'!$L$3:$L$10110,0),MATCH(R$5,'Bin Analysis'!$C$2:$S$2,0))," "))))) -> 0 | S25: =IF($L25=" "," ",(IF($M25=FALSE," ",(IF($M25>0,INDEX('Bin Analysis'!$C$3:$S$10110,MATCH($L25,'Bin Analysis'!$L$3:$L$10110,0),MATCH(S$5,'Bin Analysis'!$C$2:$S$2,0))," "))))) -> no | T25: =Assignments!K24 -> 0.83416204 | U25: =Assignments!L24 -> 0.17589021 | V25: =Assignments!V24 -> Rheostat
A26: V | B26: 2 | C26: Y | D26: 0.97580104 | E26: 0.04628013 | G26: =IFERROR('Data Transformation'!M24," ") -> 19 | L26: =$G27 -> 20 | M26: =IF(L26=" "," ",(IF($L26>0,INDEX('Bin Analysis'!$C$3:$S$10110,MATCH($L26,'Bin Analysis'!$L$3:$L$10110,0),MATCH(M$5,'Bin Analysis'!$C$2:$S$2,0))," "))) -> 20 | N26: =IF($L26=" "," ",(IF($M26=FALSE," ",(IF($M26>0,INDEX('Bin Analysis'!$C$3:$S$10110,MATCH($L26,'Bin Analysis'!$L$3:$L$10110,0),MATCH(N$5,'Bin Analysis'!$C$2:$S$2,0))," "))))) -> 0 | O26: =IF($L26=" "," ",(IF($M26=FALSE," ",(IF($M26>0,INDEX('Bin Analysis'!$C$3:$S$10110,MATCH($L26,'Bin Analysis'!$L$3:$L$10110,0),MATCH(O$5,'Bin Analysis'!$C$2:$S$2,0))," "))))) -> 0.94736842 | P26: =IF($L26=" "," ",(IF($M26=FALSE," ",(IF($M26>0,INDEX('Bin Analysis'!$C$3:$S$10110,MATCH($L26,'Bin Analysis'!$L$3:$L$10110,0),MATCH(P$5,'Bin Analysis'!$C$2:$S$2,0))," "))))) -> 0.3 | Q26: =IF($L26=" "," ",(IF($M26=FALSE," ",(IF($M26>0,INDEX('Bin Analysis'!$C$3:$S$10110,MATCH($L26,'Bin Analysis'!$L$3:$L$10110,0),MATCH(Q$5,'Bin Analysis'!$C$2:$S$2,0))," "))))) -> 0.2173913 | R26: =IF($L26=" "," ",(IF($M26=FALSE," ",(IF($M26>0,INDEX('Bin Analysis'!$C$3:$S$10110,MATCH($L26,'Bin Analysis'!$L$3:$L$10110,0),MATCH(R$5,'Bin Analysis'!$C$2:$S$2,0))," "))))) -> 0 | S26: =IF($L26=" "," ",(IF($M26=FALSE," ",(IF($M26>0,INDEX('Bin Analysis'!$C$3:$S$10110,MATCH($L26,'Bin Analysis'!$L$3:$L$10110,0),MATCH(S$5,'Bin Analysis'!$C$2:$S$2,0))," "))))) -> no | T26: =Assignments!K25 -> 0.99677325 | U26: =Assignments!L25 -> 0.079588697 | V26: =Assignments!V25 -> Neutral
A27: V | B27: 2 | C27: I | D27: 0.98715491 | E27: 0.04589418 | G27: =IFERROR('Data Transformation'!M25," ") -> 20 | I27: Neutral Bin size override | L27: =$G28 -> 21 | M27: =IF(L27=" "," ",(IF($L27>0,INDEX('Bin Analysis'!$C$3:$S$10110,MATCH($L27,'Bin Analysis'!$L$3:$L$10110,0),MATCH(M$5,'Bin Analysis'!$C$2:$S$2,0))," "))) -> 19 | N27: =IF($L27=" "," ",(IF($M27=FALSE," ",(IF($M27>0,INDEX('Bin Analysis'!$C$3:$S$10110,MATCH($L27,'Bin Analysis'!$L$3:$L$10110,0),MATCH(N$5,'Bin Analysis'!$C$2:$S$2,0))," "))))) -> 0 | O27: =IF($L27=" "," ",(IF($M27=FALSE," ",(IF($M27>0,INDEX('Bin Analysis'!$C$3:$S$10110,MATCH($L27,'Bin Analysis'!$L$3:$L$10110,0),MATCH(O$5,'Bin Analysis'!$C$2:$S$2,0))," "))))) -> 0.16666667 | P27: =IF($L27=" "," ",(IF($M27=FALSE," ",(IF($M27>0,INDEX('Bin Analysis'!$C$3:$S$10110,MATCH($L27,'Bin Analysis'!$L$3:$L$10110,0),MATCH(P$5,'Bin Analysis'!$C$2:$S$2,0))," "))))) -> 0.8 | Q27: =IF($L27=" "," ",(IF($M27=FALSE," ",(IF($M27>0,INDEX('Bin Analysis'!$C$3:$S$10110,MATCH($L27,'Bin Analysis'!$L$3:$L$10110,0),MATCH(Q$5,'Bin Analysis'!$C$2:$S$2,0))," "))))) -> 0.73913043 | R27: =IF($L27=" "," ",(IF($M27=FALSE," ",(IF($M27>0,INDEX('Bin Analysis'!$C$3:$S$10110,MATCH($L27,'Bin Analysis'!$L$3:$L$10110,0),MATCH(R$5,'Bin Analysis'!$C$2:$S$2,0))," "))))) -> 0.33333333 | S27: =IF($L27=" "," ",(IF($M27=FALSE," ",(IF($M27>0,INDEX('Bin Analysis'!$C$3:$S$10110,MATCH($L27,'Bin Analysis'!$L$3:$L$10110,0),MATCH(S$5,'Bin Analysis'!$C$2:$S$2,0))," "))))) -> no | T27: =Assignments!K26 -> 0.53915798 | U27: =Assignments!L26 -> 0.33774737 | V27: =Assignments!V26 -> Rheostat
A28: V | B28: 2 | C28: Q | D28: 0.98904614 | E28: 0.05148962 | G28: =IFERROR('Data Transformation'!M26," ") -> 21 | I28: Neutral bin size | J28: ='Data Transformation'!W25 -> 0.262 | L28: =$G29 -> 22 | M28: =IF(L28=" "," ",(IF($L28>0,INDEX('Bin Analysis'!$C$3:$S$10110,MATCH($L28,'Bin Analysis'!$L$3:$L$10110,0),MATCH(M$5,'Bin Analysis'!$C$2:$S$2,0))," "))) -> 19 | N28: =IF($L28=" "," ",(IF($M28=FALSE," ",(IF($M28>0,INDEX('Bin Analysis'!$C$3:$S$10110,MATCH($L28,'Bin Analysis'!$L$3:$L$10110,0),MATCH(N$5,'Bin Analysis'!$C$2:$S$2,0))," "))))) -> 0.055555556 | O28: =IF($L28=" "," ",(IF($M28=FALSE," ",(IF($M28>0,INDEX('Bin Analysis'!$C$3:$S$10110,MATCH($L28,'Bin Analysis'!$L$3:$L$10110,0),MATCH(O$5,'Bin Analysis'!$C$2:$S$2,0))," "))))) -> 0.61111111 | P28: =IF($L28=" "," ",(IF($M28=FALSE," ",(IF($M28>0,INDEX('Bin Analysis'!$C$3:$S$10110,MATCH($L28,'Bin Analysis'!$L$3:$L$10110,0),MATCH(P$5,'Bin Analysis'!$C$2:$S$2,0))," "))))) -> 0.4 | Q28: =IF($L28=" "," ",(IF($M28=FALSE," ",(IF($M28>0,INDEX('Bin Analysis'!$C$3:$S$10110,MATCH($L28,'Bin Analysis'!$L$3:$L$10110,0),MATCH(Q$5,'Bin Analysis'!$C$2:$S$2,0))," "))))) -> 0.39130435 | R28: =IF($L28=" "," ",(IF($M28=FALSE," ",(IF($M28>0,INDEX('Bin Analysis'!$C$3:$S$10110,MATCH($L28,'Bin Analysis'!$L$3:$L$10110,0),MATCH(R$5,'Bin Analysis'!$C$2:$S$2,0))," "))))) -> 0 | S28: =IF($L28=" "," ",(IF($M28=FALSE," ",(IF($M28>0,INDEX('Bin Analysis'!$C$3:$S$10110,MATCH($L28,'Bin Analysis'!$L$3:$L$10110,0),MATCH(S$5,'Bin Analysis'!$C$2:$S$2,0))," "))))) -> no | T28: =Assignments!K27 -> 0.94085851 | U28: =Assignments!L27 -> 0.12039845 | V28: =Assignments!V27 -> Moderate
A29: V | B29: 2 | C29: K | D29: 0.9960289 | E29: 0.04281685 | G29: =IFERROR('Data Transformation'!M27," ") -> 22 | L29: =$G30 -> 23 | M29: =IF(L29=" "," ",(IF($L29>0,INDEX('Bin Analysis'!$C$3:$S$10110,MATCH($L29,'Bin Analysis'!$L$3:$L$10110,0),MATCH(M$5,'Bin Analysis'!$C$2:$S$2,0))," "))) -> 17 | N29: =IF($L29=" "," ",(IF($M29=FALSE," ",(IF($M29>0,INDEX('Bin Analysis'!$C$3:$S$10110,MATCH($L29,'Bin Analysis'!$L$3:$L$10110,0),MATCH(N$5,'Bin Analysis'!$C$2:$S$2,0))," "))))) -> 0 | O29: =IF($L29=" "," ",(IF($M29=FALSE," ",(IF($M29>0,INDEX('Bin Analysis'!$C$3:$S$10110,MATCH($L29,'Bin Analysis'!$L$3:$L$10110,0),MATCH(O$5,'Bin Analysis'!$C$2:$S$2,0))," "))))) -> 0.75 | P29: =IF($L29=" "," ",(IF($M29=FALSE," ",(IF($M29>0,INDEX('Bin Analysis'!$C$3:$S$10110,MATCH($L29,'Bin Analysis'!$L$3:$L$10110,0),MATCH(P$5,'Bin Analysis'!$C$2:$S$2,0))," "))))) -> 0.4 | Q29: =IF($L29=" "," ",(IF($M29=FALSE," ",(IF($M29>0,INDEX('Bin Analysis'!$C$3:$S$10110,MATCH($L29,'Bin Analysis'!$L$3:$L$10110,0),MATCH(Q$5,'Bin Analysis'!$C$2:$S$2,0))," "))))) -> 0.34782609 | R29: =IF($L29=" "," ",(IF($M29=FALSE," ",(IF($M29>0,INDEX('Bin Analysis'!$C$3:$S$10110,MATCH($L29,'Bin Analysis'!$L$3:$L$10110,0),MATCH(R$5,'Bin Analysis'!$C$2:$S$2,0))," "))))) -> 0 | S29: =IF($L29=" "," ",(IF($M29=FALSE," ",(IF($M29>0,INDEX('Bin Analysis'!$C$3:$S$10110,MATCH($L29,'Bin Analysis'!$L$3:$L$10110,0),MATCH(S$5,'Bin Analysis'!$C$2:$S$2,0))," "))))) -> no | T29: =Assignments!K28 -> 0.94494738 | U29: =Assignments!L28 -> 0.098351429 | V29: =Assignments!V28 -> Neutral
A30: V | B30: 2 | C30: L | D30: 0.99807479 | E30: 0.03082989 | G30: =IFERROR('Data Transformation'!M28," ") -> 23 | I30: Enhancing Score assignment | L30: =$G31 -> 24 | M30: =IF(L30=" "," ",(IF($L30>0,INDEX('Bin Analysis'!$C$3:$S$10110,MATCH($L30,'Bin Analysis'!$L$3:$L$10110,0),MATCH(M$5,'Bin Analysis'!$C$2:$S$2,0))," "))) -> 13 | N30: =IF($L30=" "," ",(IF($M30=FALSE," ",(IF($M30>0,INDEX('Bin Analysis'!$C$3:$S$10110,MATCH($L30,'Bin Analysis'!$L$3:$L$10110,0),MATCH(N$5,'Bin Analysis'!$C$2:$S$2,0))," "))))) -> 0 | O30: =IF($L30=" "," ",(IF($M30=FALSE," ",(IF($M30>0,INDEX('Bin Analysis'!$C$3:$S$10110,MATCH($L30,'Bin Analysis'!$L$3:$L$10110,0),MATCH(O$5,'Bin Analysis'!$C$2:$S$2,0))," "))))) -> 0.58333333 | P30: =IF($L30=" "," ",(IF($M30=FALSE," ",(IF($M30>0,INDEX('Bin Analysis'!$C$3:$S$10110,MATCH($L30,'Bin Analysis'!$L$3:$L$10110,0),MATCH(P$5,'Bin Analysis'!$C$2:$S$2,0))," "))))) -> 0.4 | Q30: =IF($L30=" "," ",(IF($M30=FALSE," ",(IF($M30>0,INDEX('Bin Analysis'!$C$3:$S$10110,MATCH($L30,'Bin Analysis'!$L$3:$L$10110,0),MATCH(Q$5,'Bin Analysis'!$C$2:$S$2,0))," "))))) -> 0.30434783 | R30: =IF($L30=" "," ",(IF($M30=FALSE," ",(IF($M30>0,INDEX('Bin Analysis'!$C$3:$S$10110,MATCH($L30,'Bin Analysis'!$L$3:$L$10110,0),MATCH(R$5,'Bin Analysis'!$C$2:$S$2,0))," "))))) -> 0.083333333 | S30: =IF($L30=" "," ",(IF($M30=FALSE," ",(IF($M30>0,INDEX('Bin Analysis'!$C$3:$S$10110,MATCH($L30,'Bin Analysis'!$L$3:$L$10110,0),MATCH(S$5,'Bin Analysis'!$C$2:$S$2,0))," "))))) -> no | T30: =Assignments!K29 -> 0.86188628 | U30: =Assignments!L29 -> 0.20928349 | V30: =Assignments!V29 -> Moderate
A31: V | B31: 2 | C31: N | D31: 1.006114 | E31: 0.05767099 | G31: =IFERROR('Data Transformation'!M29," ") -> 24 | I31: Default Enhancing Score assignment | J31: 0.8 | L31: =$G32 -> 25 | M31: =IF(L31=" "," ",(IF($L31>0,INDEX('Bin Analysis'!$C$3:$S$10110,MATCH($L31,'Bin Analysis'!$L$3:$L$10110,0),MATCH(M$5,'Bin Analysis'!$C$2:$S$2,0))," "))) -> 12 | N31: =IF($L31=" "," ",(IF($M31=FALSE," ",(IF($M31>0,INDEX('Bin Analysis'!$C$3:$S$10110,MATCH($L31,'Bin Analysis'!$L$3:$L$10110,0),MATCH(N$5,'Bin Analysis'!$C$2:$S$2,0))," "))))) -> 0 | O31: =IF($L31=" "," ",(IF($M31=FALSE," ",(IF($M31>0,INDEX('Bin Analysis'!$C$3:$S$10110,MATCH($L31,'Bin Analysis'!$L$3:$L$10110,0),MATCH(O$5,'Bin Analysis'!$C$2:$S$2,0))," "))))) -> 0.63636364 | P31: =IF($L31=" "," ",(IF($M31=FALSE," ",(IF($M31>0,INDEX('Bin Analysis'!$C$3:$S$10110,MATCH($L31,'Bin Analysis'!$L$3:$L$10110,0),MATCH(P$5,'Bin Analysis'!$C$2:$S$2,0))," "))))) -> 0.5 | Q31: =IF($L31=" "," ",(IF($M31=FALSE," ",(IF($M31>0,INDEX('Bin Analysis'!$C$3:$S$10110,MATCH($L31,'Bin Analysis'!$L$3:$L$10110,0),MATCH(Q$5,'Bin Analysis'!$C$2:$S$2,0))," "))))) -> 0.43478261 | R31: =IF($L31=" "," ",(IF($M31=FALSE," ",(IF($M31>0,INDEX('Bin Analysis'!$C$3:$S$10110,MATCH($L31,'Bin Analysis'!$L$3:$L$10110,0),MATCH(R$5,'Bin Analysis'!$C$2:$S$2,0))," "))))) -> 0.090909091 | S31: =IF($L31=" "," ",(IF($M31=FALSE," ",(IF($M31>0,INDEX('Bin Analysis'!$C$3:$S$10110,MATCH($L31,'Bin Analysis'!$L$3:$L$10110,0),MATCH(S$5,'Bin Analysis'!$C$2:$S$2,0))," "))))) -> no | T31: =Assignments!K30 -> 0.85869662 | U31: =Assignments!L30 -> 0.22367761 | V31: =Assignments!V30 -> Moderate
A32: V | B32: 2 | C32: A | D32: 1.0303838 | E32: 0.03900332 | G32: =IFERROR('Data Transformation'!M30," ") -> 25 | L32: =$G33 -> 26 | M32: =IF(L32=" "," ",(IF($L32>0,INDEX('Bin Analysis'!$C$3:$S$10110,MATCH($L32,'Bin Analysis'!$L$3:$L$10110,0),MATCH(M$5,'Bin Analysis'!$C$2:$S$2,0))," "))) -> 12 | N32: =IF($L32=" "," ",(IF($M32=FALSE," ",(IF($M32>0,INDEX('Bin Analysis'!$C$3:$S$10110,MATCH($L32,'Bin Analysis'!$L$3:$L$10110,0),MATCH(N$5,'Bin Analysis'!$C$2:$S$2,0))," "))))) -> 0 | O32: =IF($L32=" "," ",(IF($M32=FALSE," ",(IF($M32>0,INDEX('Bin Analysis'!$C$3:$S$10110,MATCH($L32,'Bin Analysis'!$L$3:$L$10110,0),MATCH(O$5,'Bin Analysis'!$C$2:$S$2,0))," "))))) -> 0.45454545 | P32: =IF($L32=" "," ",(IF($M32=FALSE," ",(IF($M32>0,INDEX('Bin Analysis'!$C$3:$S$10110,MATCH($L32,'Bin Analysis'!$L$3:$L$10110,0),MATCH(P$5,'Bin Analysis'!$C$2:$S$2,0))," "))))) -> 0.5 | Q32: =IF($L32=" "," ",(IF($M32=FALSE," ",(IF($M32>0,INDEX('Bin Analysis'!$C$3:$S$10110,MATCH($L32,'Bin Analysis'!$L$3:$L$10110,0),MATCH(Q$5,'Bin Analysis'!$C$2:$S$2,0))," "))))) -> 0.47826087 | R32: =IF($L32=" "," ",(IF($M32=FALSE," ",(IF($M32>0,INDEX('Bin Analysis'!$C$3:$S$10110,MATCH($L32,'Bin Analysis'!$L$3:$L$10110,0),MATCH(R$5,'Bin Analysis'!$C$2:$S$2,0))," "))))) -> 0 | S32: =IF($L32=" "," ",(IF($M32=FALSE," ",(IF($M32>0,INDEX('Bin Analysis'!$C$3:$S$10110,MATCH($L32,'Bin Analysis'!$L$3:$L$10110,0),MATCH(S$5,'Bin Analysis'!$C$2:$S$2,0))," "))))) -> no | T32: =Assignments!K31 -> 0.84327626 | U32: =Assignments!L31 -> 0.14915521 | V32: =Assignments!V31 -> Moderate
A33: V | B33: 2 | C33: M | D33: 1.0321963 | E33: 0.05128493 | G33: =IFERROR('Data Transformation'!M31," ") -> 26 | I33: Neutral Score assignment | L33: =$G34 -> 27 | M33: =IF(L33=" "," ",(IF($L33>0,INDEX('Bin Analysis'!$C$3:$S$10110,MATCH($L33,'Bin Analysis'!$L$3:$L$10110,0),MATCH(M$5,'Bin Analysis'!$C$2:$S$2,0))," "))) -> 11 | N33: =IF($L33=" "," ",(IF($M33=FALSE," ",(IF($M33>0,INDEX('Bin Analysis'!$C$3:$S$10110,MATCH($L33,'Bin Analysis'!$L$3:$L$10110,0),MATCH(N$5,'Bin Analysis'!$C$2:$S$2,0))," "))))) -> 0 | O33: =IF($L33=" "," ",(IF($M33=FALSE," ",(IF($M33>0,INDEX('Bin Analysis'!$C$3:$S$10110,MATCH($L33,'Bin Analysis'!$L$3:$L$10110,0),MATCH(O$5,'Bin Analysis'!$C$2:$S$2,0))," "))))) -> 0 | P33: =IF($L33=" "," ",(IF($M33=FALSE," ",(IF($M33>0,INDEX('Bin Analysis'!$C$3:$S$10110,MATCH($L33,'Bin Analysis'!$L$3:$L$10110,0),MATCH(P$5,'Bin Analysis'!$C$2:$S$2,0))," "))))) -> 0.3 | Q33: =IF($L33=" "," ",(IF($M33=FALSE," ",(IF($M33>0,INDEX('Bin Analysis'!$C$3:$S$10110,MATCH($L33,'Bin Analysis'!$L$3:$L$10110,0),MATCH(Q$5,'Bin Analysis'!$C$2:$S$2,0))," "))))) -> 0.17391304 | R33: =IF($L33=" "," ",(IF($M33=FALSE," ",(IF($M33>0,INDEX('Bin Analysis'!$C$3:$S$10110,MATCH($L33,'Bin Analysis'!$L$3:$L$10110,0),MATCH(R$5,'Bin Analysis'!$C$2:$S$2,0))," "))))) -> 0.9 | S33: =IF($L33=" "," ",(IF($M33=FALSE," ",(IF($M33>0,INDEX('Bin Analysis'!$C$3:$S$10110,MATCH($L33,'Bin Analysis'!$L$3:$L$10110,0),MATCH(S$5,'Bin Analysis'!$C$2:$S$2,0))," "))))) -> no | T33: =Assignments!K32 -> 0.25747592 | U33: =Assignments!L32 -> 0.059519993 | V33: =Assignments!V32 -> Toggle
A34: V | B34: 2 | C34: R | D34: 1.0421753 | E34: 0.03300177 | G34: =IFERROR('Data Transformation'!M32," ") -> 27 | I34: Default Neutral Score assignment | J34: 0.7 | L34: =$G35 -> 28 | M34: =IF(L34=" "," ",(IF($L34>0,INDEX('Bin Analysis'!$C$3:$S$10110,MATCH($L34,'Bin Analysis'!$L$3:$L$10110,0),MATCH(M$5,'Bin Analysis'!$C$2:$S$2,0))," "))) -> 16 | N34: =IF($L34=" "," ",(IF($M34=FALSE," ",(IF($M34>0,INDEX('Bin Analysis'!$C$3:$S$10110,MATCH($L34,'Bin Analysis'!$L$3:$L$10110,0),MATCH(N$5,'Bin Analysis'!$C$2:$S$2,0))," "))))) -> 0 | O34: =IF($L34=" "," ",(IF($M34=FALSE," ",(IF($M34>0,INDEX('Bin Analysis'!$C$3:$S$10110,MATCH($L34,'Bin Analysis'!$L$3:$L$10110,0),MATCH(O$5,'Bin Analysis'!$C$2:$S$2,0))," "))))) -> 0 | P34: =IF($L34=" "," ",(IF($M34=FALSE," ",(IF($M34>0,INDEX('Bin Analysis'!$C$3:$S$10110,MATCH($L34,'Bin Analysis'!$L$3:$L$10110,0),MATCH(P$5,'Bin Analysis'!$C$2:$S$2,0))," "))))) -> 0.6 | Q34: =IF($L34=" "," ",(IF($M34=FALSE," ",(IF($M34>0,INDEX('Bin Analysis'!$C$3:$S$10110,MATCH($L34,'Bin Analysis'!$L$3:$L$10110,0),MATCH(Q$5,'Bin Analysis'!$C$2:$S$2,0))," "))))) -> 0.56521739 | R34: =IF($L34=" "," ",(IF($M34=FALSE," ",(IF($M34>0,INDEX('Bin Analysis'!$C$3:$S$10110,MATCH($L34,'Bin Analysis'!$L$3:$L$10110,0),MATCH(R$5,'Bin Analysis'!$C$2:$S$2,0))," "))))) -> 0.26666667 | S34: =IF($L34=" "," ",(IF($M34=FALSE," ",(IF($M34>0,INDEX('Bin Analysis'!$C$3:$S$10110,MATCH($L34,'Bin Analysis'!$L$3:$L$10110,0),MATCH(S$5,'Bin Analysis'!$C$2:$S$2,0))," "))))) -> no | T34: =Assignments!K33 -> 0.52663721 | U34: =Assignments!L33 -> 0.22450509 | V34: =Assignments!V33 -> Rheostat
A35: V | B35: 2 | C35: P | D35: 1.0432744 | E35: 0.03577365 | G35: =IFERROR('Data Transformation'!M33," ") -> 28 | L35: =$G36 -> 29 | M35: =IF(L35=" "," ",(IF($L35>0,INDEX('Bin Analysis'!$C$3:$S$10110,MATCH($L35,'Bin Analysis'!$L$3:$L$10110,0),MATCH(M$5,'Bin Analysis'!$C$2:$S$2,0))," "))) -> 13 | N35: =IF($L35=" "," ",(IF($M35=FALSE," ",(IF($M35>0,INDEX('Bin Analysis'!$C$3:$S$10110,MATCH($L35,'Bin Analysis'!$L$3:$L$10110,0),MATCH(N$5,'Bin Analysis'!$C$2:$S$2,0))," "))))) -> 0 | O35: =IF($L35=" "," ",(IF($M35=FALSE," ",(IF($M35>0,INDEX('Bin Analysis'!$C$3:$S$10110,MATCH($L35,'Bin Analysis'!$L$3:$L$10110,0),MATCH(O$5,'Bin Analysis'!$C$2:$S$2,0))," "))))) -> 0.83333333 | P35: =IF($L35=" "," ",(IF($M35=FALSE," ",(IF($M35>0,INDEX('Bin Analysis'!$C$3:$S$10110,MATCH($L35,'Bin Analysis'!$L$3:$L$10110,0),MATCH(P$5,'Bin Analysis'!$C$2:$S$2,0))," "))))) -> 0.3 | Q35: =IF($L35=" "," ",(IF($M35=FALSE," ",(IF($M35>0,INDEX('Bin Analysis'!$C$3:$S$10110,MATCH($L35,'Bin Analysis'!$L$3:$L$10110,0),MATCH(Q$5,'Bin Analysis'!$C$2:$S$2,0))," "))))) -> 0.26086957 | R35: =IF($L35=" "," ",(IF($M35=FALSE," ",(IF($M35>0,INDEX('Bin Analysis'!$C$3:$S$10110,MATCH($L35,'Bin Analysis'!$L$3:$L$10110,0),MATCH(R$5,'Bin Analysis'!$C$2:$S$2,0))," "))))) -> 0 | S35: =IF($L35=" "," ",(IF($M35=FALSE," ",(IF($M35>0,INDEX('Bin Analysis'!$C$3:$S$10110,MATCH($L35,'Bin Analysis'!$L$3:$L$10110,0),MATCH(S$5,'Bin Analysis'!$C$2:$S$2,0))," "))))) -> no | T35: =Assignments!K34 -> 0.89788571 | U35: =Assignments!L34 -> 0.1915994 | V35: =Assignments!V34 -> Neutral
A36: V | B36: 2 | C36: D | D36: 1.0474998 | E36: 0.06854481 | G36: =IFERROR('Data Transformation'!M34," ") -> 29 | I36: Rheostat Score assignment | L36: =$G37 -> 30 | M36: =IF(L36=" "," ",(IF($L36>0,INDEX('Bin Analysis'!$C$3:$S$10110,MATCH($L36,'Bin Analysis'!$L$3:$L$10110,0),MATCH(M$5,'Bin Analysis'!$C$2:$S$2,0))," "))) -> 18 | N36: =IF($L36=" "," ",(IF($M36=FALSE," ",(IF($M36>0,INDEX('Bin Analysis'!$C$3:$S$10110,MATCH($L36,'Bin Analysis'!$L$3:$L$10110,0),MATCH(N$5,'Bin Analysis'!$C$2:$S$2,0))," "))))) -> 0 | O36: =IF($L36=" "," ",(IF($M36=FALSE," ",(IF($M36>0,INDEX('Bin Analysis'!$C$3:$S$10110,MATCH($L36,'Bin Analysis'!$L$3:$L$10110,0),MATCH(O$5,'Bin Analysis'!$C$2:$S$2,0))," "))))) -> 0.82352941 | P36: =IF($L36=" "," ",(IF($M36=FALSE," ",(IF($M36>0,INDEX('Bin Analysis'!$C$3:$S$10110,MATCH($L36,'Bin Analysis'!$L$3:$L$10110,0),MATCH(P$5,'Bin Analysis'!$C$2:$S$2,0))," "))))) -> 0.5 | Q36: =IF($L36=" "," ",(IF($M36=FALSE," ",(IF($M36>0,INDEX('Bin Analysis'!$C$3:$S$10110,MATCH($L36,'Bin Analysis'!$L$3:$L$10110,0),MATCH(Q$5,'Bin Analysis'!$C$2:$S$2,0))," "))))) -> 0.39130435 | R36: =IF($L36=" "," ",(IF($M36=FALSE," ",(IF($M36>0,INDEX('Bin Analysis'!$C$3:$S$10110,MATCH($L36,'Bin Analysis'!$L$3:$L$10110,0),MATCH(R$5,'Bin Analysis'!$C$2:$S$2,0))," "))))) -> 0.058823529 | S36: =IF($L36=" "," ",(IF($M36=FALSE," ",(IF($M36>0,INDEX('Bin Analysis'!$C$3:$S$10110,MATCH($L36,'Bin Analysis'!$L$3:$L$10110,0),MATCH(S$5,'Bin Analysis'!$C$2:$S$2,0))," "))))) -> no | T36: =Assignments!K35 -> 0.89549256 | U36: =Assignments!L35 -> 0.22051093 | V36: =Assignments!V35 -> Neutral
A37: V | B37: 2 | C37: F | D37: 1.0476008 | E37: 0.04402002 | G37: =IFERROR('Data Transformation'!M35," ") -> 30 | I37: Default Rheostate Score assignment | J37: 0.5 | L37: =$G38 -> 31 | M37: =IF(L37=" "," ",(IF($L37>0,INDEX('Bin Analysis'!$C$3:$S$10110,MATCH($L37,'Bin Analysis'!$L$3:$L$10110,0),MATCH(M$5,'Bin Analysis'!$C$2:$S$2,0))," "))) -> 13 | N37: =IF($L37=" "," ",(IF($M37=FALSE," ",(IF($M37>0,INDEX('Bin Analysis'!$C$3:$S$10110,MATCH($L37,'Bin Analysis'!$L$3:$L$10110,0),MATCH(N$5,'Bin Analysis'!$C$2:$S$2,0))," "))))) -> 0 | O37: =IF($L37=" "," ",(IF($M37=FALSE," ",(IF($M37>0,INDEX('Bin Analysis'!$C$3:$S$10110,MATCH($L37,'Bin Analysis'!$L$3:$L$10110,0),MATCH(O$5,'Bin Analysis'!$C$2:$S$2,0))," "))))) -> 0.41666667 | P37: =IF($L37=" "," ",(IF($M37=FALSE," ",(IF($M37>0,INDEX('Bin Analysis'!$C$3:$S$10110,MATCH($L37,'Bin Analysis'!$L$3:$L$10110,0),MATCH(P$5,'Bin Analysis'!$C$2:$S$2,0))," "))))) -> 0.7 | Q37: =IF($L37=" "," ",(IF($M37=FALSE," ",(IF($M37>0,INDEX('Bin Analysis'!$C$3:$S$10110,MATCH($L37,'Bin Analysis'!$L$3:$L$10110,0),MATCH(Q$5,'Bin Analysis'!$C$2:$S$2,0))," "))))) -> 0.65217391 | R37: =IF($L37=" "," ",(IF($M37=FALSE," ",(IF($M37>0,INDEX('Bin Analysis'!$C$3:$S$10110,MATCH($L37,'Bin Analysis'!$L$3:$L$10110,0),MATCH(R$5,'Bin Analysis'!$C$2:$S$2,0))," "))))) -> 0.083333333 | S37: =IF($L37=" "," ",(IF($M37=FALSE," ",(IF($M37>0,INDEX('Bin Analysis'!$C$3:$S$10110,MATCH($L37,'Bin Analysis'!$L$3:$L$10110,0),MATCH(S$5,'Bin Analysis'!$C$2:$S$2,0))," "))))) -> no | T37: =Assignments!K36 -> 0.69238992 | U37: =Assignments!L36 -> 0.23427367 | V37: =Assignments!V36 -> Rheostat
A38: V | B38: 2 | C38: S | D38: 1.054497 | E38: 0.02981959 | G38: =IFERROR('Data Transformation'!M36," ") -> 31 | L38: =$G39 -> 32 | M38: =IF(L38=" "," ",(IF($L38>0,INDEX('Bin Analysis'!$C$3:$S$10110,MATCH($L38,'Bin Analysis'!$L$3:$L$10110,0),MATCH(M$5,'Bin Analysis'!$C$2:$S$2,0))," "))) -> 18 | N38: =IF($L38=" "," ",(IF($M38=FALSE," ",(IF($M38>0,INDEX('Bin Analysis'!$C$3:$S$10110,MATCH($L38,'Bin Analysis'!$L$3:$L$10110,0),MATCH(N$5,'Bin Analysis'!$C$2:$S$2,0))," "))))) -> 0 | O38: =IF($L38=" "," ",(IF($M38=FALSE," ",(IF($M38>0,INDEX('Bin Analysis'!$C$3:$S$10110,MATCH($L38,'Bin Analysis'!$L$3:$L$10110,0),MATCH(O$5,'Bin Analysis'!$C$2:$S$2,0))," "))))) -> 0 | P38: =IF($L38=" "," ",(IF($M38=FALSE," ",(IF($M38>0,INDEX('Bin Analysis'!$C$3:$S$10110,MATCH($L38,'Bin Analysis'!$L$3:$L$10110,0),MATCH(P$5,'Bin Analysis'!$C$2:$S$2,0))," "))))) -> 0.3 | Q38: =IF($L38=" "," ",(IF($M38=FALSE," ",(IF($M38>0,INDEX('Bin Analysis'!$C$3:$S$10110,MATCH($L38,'Bin Analysis'!$L$3:$L$10110,0),MATCH(Q$5,'Bin Analysis'!$C$2:$S$2,0))," "))))) -> 0.17391304 | R38: =IF($L38=" "," ",(IF($M38=FALSE," ",(IF($M38>0,INDEX('Bin Analysis'!$C$3:$S$10110,MATCH($L38,'Bin Analysis'!$L$3:$L$10110,0),MATCH(R$5,'Bin Analysis'!$C$2:$S$2,0))," "))))) -> 0.88235294 | S38: =IF($L38=" "," ",(IF($M38=FALSE," ",(IF($M38>0,INDEX('Bin Analysis'!$C$3:$S$10110,MATCH($L38,'Bin Analysis'!$L$3:$L$10110,0),MATCH(S$5,'Bin Analysis'!$C$2:$S$2,0))," "))))) -> no | T38: =Assignments!K37 -> 0.22017313 | U38: =Assignments!L37 -> 0.084449929 | V38: =Assignments!V37 -> Toggle
A39: V | B39: 2 | C39: H | D39: 1.0848393 | E39: 0.04959334 | G39: =IFERROR('Data Transformation'!M37," ") -> 32 | I39: Toggle Score assignment | L39: =$G40 -> 33 | M39: =IF(L39=" "," ",(IF($L39>0,INDEX('Bin Analysis'!$C$3:$S$10110,MATCH($L39,'Bin Analysis'!$L$3:$L$10110,0),MATCH(M$5,'Bin Analysis'!$C$2:$S$2,0))," "))) -> 9 | N39: =IF($L39=" "," ",(IF($M39=FALSE," ",(IF($M39>0,INDEX('Bin Analysis'!$C$3:$S$10110,MATCH($L39,'Bin Analysis'!$L$3:$L$10110,0),MATCH(N$5,'Bin Analysis'!$C$2:$S$2,0))," "))))) -> 0 | O39: =IF($L39=" "," ",(IF($M39=FALSE," ",(IF($M39>0,INDEX('Bin Analysis'!$C$3:$S$10110,MATCH($L39,'Bin Analysis'!$L$3:$L$10110,0),MATCH(O$5,'Bin Analysis'!$C$2:$S$2,0))," "))))) -> 0.625 | P39: =IF($L39=" "," ",(IF($M39=FALSE," ",(IF($M39>0,INDEX('Bin Analysis'!$C$3:$S$10110,MATCH($L39,'Bin Analysis'!$L$3:$L$10110,0),MATCH(P$5,'Bin Analysis'!$C$2:$S$2,0))," "))))) -> 0.4 | Q39: =IF($L39=" "," ",(IF($M39=FALSE," ",(IF($M39>0,INDEX('Bin Analysis'!$C$3:$S$10110,MATCH($L39,'Bin Analysis'!$L$3:$L$10110,0),MATCH(Q$5,'Bin Analysis'!$C$2:$S$2,0))," "))))) -> 0.39130435 | R39: =IF($L39=" "," ",(IF($M39=FALSE," ",(IF($M39>0,INDEX('Bin Analysis'!$C$3:$S$10110,MATCH($L39,'Bin Analysis'!$L$3:$L$10110,0),MATCH(R$5,'Bin Analysis'!$C$2:$S$2,0))," "))))) -> 0 | S39: =IF($L39=" "," ",(IF($M39=FALSE," ",(IF($M39>0,INDEX('Bin Analysis'!$C$3:$S$10110,MATCH($L39,'Bin Analysis'!$L$3:$L$10110,0),MATCH(S$5,'Bin Analysis'!$C$2:$S$2,0))," "))))) -> no | T39: =Assignments!K38 -> 0.88017525 | U39: =Assignments!L38 -> 0.10746356 | V39: =Assignments!V38 -> Moderate
A40: V | B40: 2 | C40: E | D40: 1.088722 | E40: 0.04959822 | G40: =IFERROR('Data Transformation'!M38," ") -> 33 | I40: Default Toggle Score assignment | J40: 0.64 | L40: =$G41 -> 34 | M40: =IF(L40=" "," ",(IF($L40>0,INDEX('Bin Analysis'!$C$3:$S$10110,MATCH($L40,'Bin Analysis'!$L$3:$L$10110,0),MATCH(M$5,'Bin Analysis'!$C$2:$S$2,0))," "))) -> FALSE | N40: =IF($L40=" "," ",(IF($M40=FALSE," ",(IF($M40>0,INDEX('Bin Analysis'!$C$3:$S$10110,MATCH($L40,'Bin Analysis'!$L$3:$L$10110,0),MATCH(N$5,'Bin Analysis'!$C$2:$S$2,0))," "))))) | O40: =IF($L40=" "," ",(IF($M40=FALSE," ",(IF($M40>0,INDEX('Bin Analysis'!$C$3:$S$10110,MATCH($L40,'Bin Analysis'!$L$3:$L$10110,0),MATCH(O$5,'Bin Analysis'!$C$2:$S$2,0))," "))))) | P40: =IF($L40=" "," ",(IF($M40=FALSE," ",(IF($M40>0,INDEX('Bin Analysis'!$C$3:$S$10110,MATCH($L40,'Bin Analysis'!$L$3:$L$10110,0),MATCH(P$5,'Bin Analysis'!$C$2:$S$2,0))," "))))) | Q40: =IF($L40=" "," ",(IF($M40=FALSE," ",(IF($M40>0,INDEX('Bin Analysis'!$C$3:$S$10110,MATCH($L40,'Bin Analysis'!$L$3:$L$10110,0),MATCH(Q$5,'Bin Analysis'!$C$2:$S$2,0))," "))))) | R40: =IF($L40=" "," ",(IF($M40=FALSE," ",(IF($M40>0,INDEX('Bin Analysis'!$C$3:$S$10110,MATCH($L40,'Bin Analysis'!$L$3:$L$10110,0),MATCH(R$5,'Bin Analysis'!$C$2:$S$2,0))," "))))) | S40: =IF($L40=" "," ",(IF($M40=FALSE," ",(IF($M40>0,INDEX('Bin Analysis'!$C$3:$S$10110,MATCH($L40,'Bin Analysis'!$L$3:$L$10110,0),MATCH(S$5,'Bin Analysis'!$C$2:$S$2,0))," "))))) | T40: =Assignments!K39 -> 0.83339575 | U40: =Assignments!L39 -> 0.17054962 | V40: =Assignments!V39
A41: R | B41: 3 | C41: F | D41: 0.86198508 | E41: 0.04756635 | G41: =IFERROR('Data Transformation'!M39," ") -> 34 | L41: =$G42 -> 35 | M41: =IF(L41=" "," ",(IF($L41>0,INDEX('Bin Analysis'!$C$3:$S$10110,MATCH($L41,'Bin Analysis'!$L$3:$L$10110,0),MATCH(M$5,'Bin Analysis'!$C$2:$S$2,0))," "))) -> 18 | N41: =IF($L41=" "," ",(IF($M41=FALSE," ",(IF($M41>0,INDEX('Bin Analysis'!$C$3:$S$10110,MATCH($L41,'Bin Analysis'!$L$3:$L$10110,0),MATCH(N$5,'Bin Analysis'!$C$2:$S$2,0))," "))))) -> 0.058823529 | O41: =IF($L41=" "," ",(IF($M41=FALSE," ",(IF($M41>0,INDEX('Bin Analysis'!$C$3:$S$10110,MATCH($L41,'Bin Analysis'!$L$3:$L$10110,0),MATCH(O$5,'Bin Analysis'!$C$2:$S$2,0))," "))))) -> 0 | P41: =IF($L41=" "," ",(IF($M41=FALSE," ",(IF($M41>0,INDEX('Bin Analysis'!$C$3:$S$10110,MATCH($L41,'Bin Analysis'!$L$3:$L$10110,0),MATCH(P$5,'Bin Analysis'!$C$2:$S$2,0))," "))))) -> 0.5 | Q41: =IF($L41=" "," ",(IF($M41=FALSE," ",(IF($M41>0,INDEX('Bin Analysis'!$C$3:$S$10110,MATCH($L41,'Bin Analysis'!$L$3:$L$10110,0),MATCH(Q$5,'Bin Analysis'!$C$2:$S$2,0))," "))))) -> 0.39130435 | R41: =IF($L41=" "," ",(IF($M41=FALSE," ",(IF($M41>0,INDEX('Bin Analysis'!$C$3:$S$10110,MATCH($L41,'Bin Analysis'!$L$3:$L$10110,0),MATCH(R$5,'Bin Analysis'!$C$2:$S$2,0))," "))))) -> 0.82352941 | S41: =IF($L41=" "," ",(IF($M41=FALSE," ",(IF($M41>0,INDEX('Bin Analysis'!$C$3:$S$10110,MATCH($L41,'Bin Analysis'!$L$3:$L$10110,0),MATCH(S$5,'Bin Analysis'!$C$2:$S$2,0))," "))))) -> no | T41: =Assignments!K40 -> 0.31272927 | U41: =Assignments!L40 -> 0.27073411 | V41: =Assignments!V40 -> Toggle
