Workbook

Sheet How to use this calculator
M43: 𝝙
N46: 𝝙

Sheet Input and Summary Results
A2: Data set:
B4: Position | C4: Mutation | D4: Measured Value | E4: Error | G4: Positions Analyzed | I4: Should the data be converted to a log scale? | J4: yes | L4: Scores
A5: Wild Type | B5: NA | C5: NA | L5: Position | M5: # of variants | N5: Enhancing | O5: Neutral | P5: Unweighted rheostat | Q5: Weighted rheostat | R5: Toggle | S5: Binary | T5: Average | U5: Standard Deviation | V5: Assignment
A6: Format Example | B6: 45 | C6: A | D6: 0.563 | E6: 0.0034 | I6: Data statistics | L6: all | M6: =INDEX('Bin Analysis and Plots'!$E$3:$U$505,MATCH($L6,'Bin Analysis and Plots'!$N$3:$N$505,0),MATCH(M$5,'Bin Analysis and Plots'!$E$2:$U$2,0)) -> FALSE | N6: =INDEX('Bin Analysis and Plots'!$E$3:$U$505,MATCH($L6,'Bin Analysis and Plots'!$N$3:$N$505,0),MATCH(N$5,'Bin Analysis and Plots'!$E$2:$U$2,0)) -> 0 | O6: =INDEX('Bin Analysis and Plots'!$E$3:$U$505,MATCH($L6,'Bin Analysis and Plots'!$N$3:$N$505,0),MATCH(O$5,'Bin Analysis and Plots'!$E$2:$U$2,0)) -> #N/A | P6: =INDEX('Bin Analysis and Plots'!$E$3:$U$505,MATCH($L6,'Bin Analysis and Plots'!$N$3:$N$505,0),MATCH(P$5,'Bin Analysis and Plots'!$E$2:$U$2,0)) -> #N/A | Q6: =INDEX('Bin Analysis and Plots'!$E$3:$U$505,MATCH($L6,'Bin Analysis and Plots'!$N$3:$N$505,0),MATCH(Q$5,'Bin Analysis and Plots'!$E$2:$U$2,0)) -> #N/A | R6: =INDEX('Bin Analysis and Plots'!$E$3:$U$505,MATCH($L6,'Bin Analysis and Plots'!$N$3:$N$505,0),MATCH(R$5,'Bin Analysis and Plots'!$E$2:$U$2,0)) -> #N/A | S6: =INDEX('Bin Analysis and Plots'!$E$3:$U$505,MATCH($L6,'Bin Analysis and Plots'!$N$3:$N$505,0),MATCH(S$5,'Bin Analysis and Plots'!$E$2:$U$2,0)) -> #N/A | T6: {=Assignments!K5:K25} | U6: {=Assignments!L5:L25}
A7: the WT aa | I7: Minimum | J7: =IF($J$4="yes",10^('Data Transformation'!R3),'Data Transformation'!R3) -> 1 | L7: =$G8 | M7: =IF(L7=" "," ",(IF($L7>0,INDEX('Bin Analysis and Plots'!$E$3:$U$505,MATCH($L7,'Bin Analysis and Plots'!$N$3:$N$505,0),MATCH(M$5,'Bin Analysis and Plots'!$E$2:$U$2,0))," "))) | N7: =IF($L7=" "," ",(IF($M7=FALSE," ",(IF($M7>0,INDEX('Bin Analysis and Plots'!$E$3:$U$505,MATCH($L7,'Bin Analysis and Plots'!$N$3:$N$505,0),MATCH(N$5,'Bin Analysis and Plots'!$E$2:$U$2,0))," "))))) | O7: =IF($L7=" "," ",(IF($M7=FALSE," ",(IF($M7>0,INDEX('Bin Analysis and Plots'!$E$3:$U$505,MATCH($L7,'Bin Analysis and Plots'!$N$3:$N$505,0),MATCH(O$5,'Bin Analysis and Plots'!$E$2:$U$2,0))," "))))) | P7: =IF($L7=" "," ",(IF($M7=FALSE," ",(IF($M7>0,INDEX('Bin Analysis and Plots'!$E$3:$U$505,MATCH($L7,'Bin Analysis and Plots'!$N$3:$N$505,0),MATCH(P$5,'Bin Analysis and Plots'!$E$2:$U$2,0))," "))))) | Q7: =IF($L7=" "," ",(IF($M7=FALSE," ",(IF($M7>0,INDEX('Bin Analysis and Plots'!$E$3:$U$505,MATCH($L7,'Bin Analysis and Plots'!$N$3:$N$505,0),MATCH(Q$5,'Bin Analysis and Plots'!$E$2:$U$2,0))," "))))) | R7: =IF($L7=" "," ",(IF($M7=FALSE," ",(IF($M7>0,INDEX('Bin Analysis and Plots'!$E$3:$U$505,MATCH($L7,'Bin Analysis and Plots'!$N$3:$N$505,0),MATCH(R$5,'Bin Analysis and Plots'!$E$2:$U$2,0))," "))))) | S7: =IF($L7=" "," ",(IF($M7=FALSE," ",(IF($M7>0,INDEX('Bin Analysis and Plots'!$E$3:$U$505,MATCH($L7,'Bin Analysis and Plots'!$N$3:$N$505,0),MATCH(S$5,'Bin Analysis and Plots'!$E$2:$U$2,0))," "))))) | V7: {=Assignments!V6:V25}
A8: for each | G8: =IFERROR('Data Transformation'!M6," ") | I8: Maximum | J8: =IF($J$4="yes",10^('Data Transformation'!R4),'Data Transformation'!R4) -> 1 | L8: =$G9 | M8: =IF(L8=" "," ",(IF($L8>0,INDEX('Bin Analysis and Plots'!$E$3:$U$505,MATCH($L8,'Bin Analysis and Plots'!$N$3:$N$505,0),MATCH(M$5,'Bin Analysis and Plots'!$E$2:$U$2,0))," "))) | N8: =IF($L8=" "," ",(IF($M8=FALSE," ",(IF($M8>0,INDEX('Bin Analysis and Plots'!$E$3:$U$505,MATCH($L8,'Bin Analysis and Plots'!$N$3:$N$505,0),MATCH(N$5,'Bin Analysis and Plots'!$E$2:$U$2,0))," "))))) | O8: =IF($L8=" "," ",(IF($M8=FALSE," ",(IF($M8>0,INDEX('Bin Analysis and Plots'!$E$3:$U$505,MATCH($L8,'Bin Analysis and Plots'!$N$3:$N$505,0),MATCH(O$5,'Bin Analysis and Plots'!$E$2:$U$2,0))," "))))) | P8: =IF($L8=" "," ",(IF($M8=FALSE," ",(IF($M8>0,INDEX('Bin Analysis and Plots'!$E$3:$U$505,MATCH($L8,'Bin Analysis and Plots'!$N$3:$N$505,0),MATCH(P$5,'Bin Analysis and Plots'!$E$2:$U$2,0))," "))))) | Q8: =IF($L8=" "," ",(IF($M8=FALSE," ",(IF($M8>0,INDEX('Bin Analysis and Plots'!$E$3:$U$505,MATCH($L8,'Bin Analysis and Plots'!$N$3:$N$505,0),MATCH(Q$5,'Bin Analysis and Plots'!$E$2:$U$2,0))," "))))) | R8: =IF($L8=" "," ",(IF($M8=FALSE," ",(IF($M8>0,INDEX('Bin Analysis and Plots'!$E$3:$U$505,MATCH($L8,'Bin Analysis and Plots'!$N$3:$N$505,0),MATCH(R$5,'Bin Analysis and Plots'!$E$2:$U$2,0))," "))))) | S8: =IF($L8=" "," ",(IF($M8=FALSE," ",(IF($M8>0,INDEX('Bin Analysis and Plots'!$E$3:$U$505,MATCH($L8,'Bin Analysis and Plots'!$N$3:$N$505,0),MATCH(S$5,'Bin Analysis and Plots'!$E$2:$U$2,0))," ")))))
A9: subsitution | G9: =IFERROR('Data Transformation'!M7," ") | L9: =$G10 | M9: =IF(L9=" "," ",(IF($L9>0,INDEX('Bin Analysis and Plots'!$E$3:$U$505,MATCH($L9,'Bin Analysis and Plots'!$N$3:$N$505,0),MATCH(M$5,'Bin Analysis and Plots'!$E$2:$U$2,0))," "))) | N9: =IF($L9=" "," ",(IF($M9=FALSE," ",(IF($M9>0,INDEX('Bin Analysis and Plots'!$E$3:$U$505,MATCH($L9,'Bin Analysis and Plots'!$N$3:$N$505,0),MATCH(N$5,'Bin Analysis and Plots'!$E$2:$U$2,0))," "))))) | O9: =IF($L9=" "," ",(IF($M9=FALSE," ",(IF($M9>0,INDEX('Bin Analysis and Plots'!$E$3:$U$505,MATCH($L9,'Bin Analysis and Plots'!$N$3:$N$505,0),MATCH(O$5,'Bin Analysis and Plots'!$E$2:$U$2,0))," "))))) | P9: =IF($L9=" "," ",(IF($M9=FALSE," ",(IF($M9>0,INDEX('Bin Analysis and Plots'!$E$3:$U$505,MATCH($L9,'Bin Analysis and Plots'!$N$3:$N$505,0),MATCH(P$5,'Bin Analysis and Plots'!$E$2:$U$2,0))," "))))) | Q9: =IF($L9=" "," ",(IF($M9=FALSE," ",(IF($M9>0,INDEX('Bin Analysis and Plots'!$E$3:$U$505,MATCH($L9,'Bin Analysis and Plots'!$N$3:$N$505,0),MATCH(Q$5,'Bin Analysis and Plots'!$E$2:$U$2,0))," "))))) | R9: =IF($L9=" "," ",(IF($M9=FALSE," ",(IF($M9>0,INDEX('Bin Analysis and Plots'!$E$3:$U$505,MATCH($L9,'Bin Analysis and Plots'!$N$3:$N$505,0),MATCH(R$5,'Bin Analysis and Plots'!$E$2:$U$2,0))," "))))) | S9: =IF($L9=" "," ",(IF($M9=FALSE," ",(IF($M9>0,INDEX('Bin Analysis and Plots'!$E$3:$U$505,MATCH($L9,'Bin Analysis and Plots'!$N$3:$N$505,0),MATCH(S$5,'Bin Analysis and Plots'!$E$2:$U$2,0))," ")))))
A10: could go in | G10: =IFERROR('Data Transformation'!M8," ") | I10: Min/Max override | L10: =$G11 | M10: =IF(L10=" "," ",(IF($L10>0,INDEX('Bin Analysis and Plots'!$E$3:$U$505,MATCH($L10,'Bin Analysis and Plots'!$N$3:$N$505,0),MATCH(M$5,'Bin Analysis and Plots'!$E$2:$U$2,0))," "))) | N10: =IF($L10=" "," ",(IF($M10=FALSE," ",(IF($M10>0,INDEX('Bin Analysis and Plots'!$E$3:$U$505,MATCH($L10,'Bin Analysis and Plots'!$N$3:$N$505,0),MATCH(N$5,'Bin Analysis and Plots'!$E$2:$U$2,0))," "))))) | O10: =IF($L10=" "," ",(IF($M10=FALSE," ",(IF($M10>0,INDEX('Bin Analysis and Plots'!$E$3:$U$505,MATCH($L10,'Bin Analysis and Plots'!$N$3:$N$505,0),MATCH(O$5,'Bin Analysis and Plots'!$E$2:$U$2,0))," "))))) | P10: =IF($L10=" "," ",(IF($M10=FALSE," ",(IF($M10>0,INDEX('Bin Analysis and Plots'!$E$3:$U$505,MATCH($L10,'Bin Analysis and Plots'!$N$3:$N$505,0),MATCH(P$5,'Bin Analysis and Plots'!$E$2:$U$2,0))," "))))) | Q10: =IF($L10=" "," ",(IF($M10=FALSE," ",(IF($M10>0,INDEX('Bin Analysis and Plots'!$E$3:$U$505,MATCH($L10,'Bin Analysis and Plots'!$N$3:$N$505,0),MATCH(Q$5,'Bin Analysis and Plots'!$E$2:$U$2,0))," "))))) | R10: =IF($L10=" "," ",(IF($M10=FALSE," ",(IF($M10>0,INDEX('Bin Analysis and Plots'!$E$3:$U$505,MATCH($L10,'Bin Analysis and Plots'!$N$3:$N$505,0),MATCH(R$5,'Bin Analysis and Plots'!$E$2:$U$2,0))," "))))) | S10: =IF($L10=" "," ",(IF($M10=FALSE," ",(IF($M10>0,INDEX('Bin Analysis and Plots'!$E$3:$U$505,MATCH($L10,'Bin Analysis and Plots'!$N$3:$N$505,0),MATCH(S$5,'Bin Analysis and Plots'!$E$2:$U$2,0))," ")))))
A11: column A | G11: =IFERROR('Data Transformation'!M9," ") | I11: Minimum | L11: =$G12 | M11: =IF(L11=" "," ",(IF($L11>0,INDEX('Bin Analysis and Plots'!$E$3:$U$505,MATCH($L11,'Bin Analysis and Plots'!$N$3:$N$505,0),MATCH(M$5,'Bin Analysis and Plots'!$E$2:$U$2,0))," "))) | N11: =IF($L11=" "," ",(IF($M11=FALSE," ",(IF($M11>0,INDEX('Bin Analysis and Plots'!$E$3:$U$505,MATCH($L11,'Bin Analysis and Plots'!$N$3:$N$505,0),MATCH(N$5,'Bin Analysis and Plots'!$E$2:$U$2,0))," "))))) | O11: =IF($L11=" "," ",(IF($M11=FALSE," ",(IF($M11>0,INDEX('Bin Analysis and Plots'!$E$3:$U$505,MATCH($L11,'Bin Analysis and Plots'!$N$3:$N$505,0),MATCH(O$5,'Bin Analysis and Plots'!$E$2:$U$2,0))," "))))) | P11: =IF($L11=" "," ",(IF($M11=FALSE," ",(IF($M11>0,INDEX('Bin Analysis and Plots'!$E$3:$U$505,MATCH($L11,'Bin Analysis and Plots'!$N$3:$N$505,0),MATCH(P$5,'Bin Analysis and Plots'!$E$2:$U$2,0))," "))))) | Q11: =IF($L11=" "," ",(IF($M11=FALSE," ",(IF($M11>0,INDEX('Bin Analysis and Plots'!$E$3:$U$505,MATCH($L11,'Bin Analysis and Plots'!$N$3:$N$505,0),MATCH(Q$5,'Bin Analysis and Plots'!$E$2:$U$2,0))," "))))) | R11: =IF($L11=" "," ",(IF($M11=FALSE," ",(IF($M11>0,INDEX('Bin Analysis and Plots'!$E$3:$U$505,MATCH($L11,'Bin Analysis and Plots'!$N$3:$N$505,0),MATCH(R$5,'Bin Analysis and Plots'!$E$2:$U$2,0))," "))))) | S11: =IF($L11=" "," ",(IF($M11=FALSE," ",(IF($M11>0,INDEX('Bin Analysis and Plots'!$E$3:$U$505,MATCH($L11,'Bin Analysis and Plots'!$N$3:$N$505,0),MATCH(S$5,'Bin Analysis and Plots'!$E$2:$U$2,0))," ")))))
G12: =IFERROR('Data Transformation'!M10," ") | I12: Maximum | L12: =$G13 | M12: =IF(L12=" "," ",(IF($L12>0,INDEX('Bin Analysis and Plots'!$E$3:$U$505,MATCH($L12,'Bin Analysis and Plots'!$N$3:$N$505,0),MATCH(M$5,'Bin Analysis and Plots'!$E$2:$U$2,0))," "))) | N12: =IF($L12=" "," ",(IF($M12=FALSE," ",(IF($M12>0,INDEX('Bin Analysis and Plots'!$E$3:$U$505,MATCH($L12,'Bin Analysis and Plots'!$N$3:$N$505,0),MATCH(N$5,'Bin Analysis and Plots'!$E$2:$U$2,0))," "))))) | O12: =IF($L12=" "," ",(IF($M12=FALSE," ",(IF($M12>0,INDEX('Bin Analysis and Plots'!$E$3:$U$505,MATCH($L12,'Bin Analysis and Plots'!$N$3:$N$505,0),MATCH(O$5,'Bin Analysis and Plots'!$E$2:$U$2,0))," "))))) | P12: =IF($L12=" "," ",(IF($M12=FALSE," ",(IF($M12>0,INDEX('Bin Analysis and Plots'!$E$3:$U$505,MATCH($L12,'Bin Analysis and Plots'!$N$3:$N$505,0),MATCH(P$5,'Bin Analysis and Plots'!$E$2:$U$2,0))," "))))) | Q12: =IF($L12=" "," ",(IF($M12=FALSE," ",(IF($M12>0,INDEX('Bin Analysis and Plots'!$E$3:$U$505,MATCH($L12,'Bin Analysis and Plots'!$N$3:$N$505,0),MATCH(Q$5,'Bin Analysis and Plots'!$E$2:$U$2,0))," "))))) | R12: =IF($L12=" "," ",(IF($M12=FALSE," ",(IF($M12>0,INDEX('Bin Analysis and Plots'!$E$3:$U$505,MATCH($L12,'Bin Analysis and Plots'!$N$3:$N$505,0),MATCH(R$5,'Bin Analysis and Plots'!$E$2:$U$2,0))," "))))) | S12: =IF($L12=" "," ",(IF($M12=FALSE," ",(IF($M12>0,INDEX('Bin Analysis and Plots'!$E$3:$U$505,MATCH($L12,'Bin Analysis and Plots'!$N$3:$N$505,0),MATCH(S$5,'Bin Analysis and Plots'!$E$2:$U$2,0))," ")))))
G13: =IFERROR('Data Transformation'!M11," ") | I13: (leave blank if no override) | L13: =$G14 | M13: =IF(L13=" "," ",(IF($L13>0,INDEX('Bin Analysis and Plots'!$E$3:$U$505,MATCH($L13,'Bin Analysis and Plots'!$N$3:$N$505,0),MATCH(M$5,'Bin Analysis and Plots'!$E$2:$U$2,0))," "))) | N13: =IF($L13=" "," ",(IF($M13=FALSE," ",(IF($M13>0,INDEX('Bin Analysis and Plots'!$E$3:$U$505,MATCH($L13,'Bin Analysis and Plots'!$N$3:$N$505,0),MATCH(N$5,'Bin Analysis and Plots'!$E$2:$U$2,0))," "))))) | O13: =IF($L13=" "," ",(IF($M13=FALSE," ",(IF($M13>0,INDEX('Bin Analysis and Plots'!$E$3:$U$505,MATCH($L13,'Bin Analysis and Plots'!$N$3:$N$505,0),MATCH(O$5,'Bin Analysis and Plots'!$E$2:$U$2,0))," "))))) | P13: =IF($L13=" "," ",(IF($M13=FALSE," ",(IF($M13>0,INDEX('Bin Analysis and Plots'!$E$3:$U$505,MATCH($L13,'Bin Analysis and Plots'!$N$3:$N$505,0),MATCH(P$5,'Bin Analysis and Plots'!$E$2:$U$2,0))," "))))) | Q13: =IF($L13=" "," ",(IF($M13=FALSE," ",(IF($M13>0,INDEX('Bin Analysis and Plots'!$E$3:$U$505,MATCH($L13,'Bin Analysis and Plots'!$N$3:$N$505,0),MATCH(Q$5,'Bin Analysis and Plots'!$E$2:$U$2,0))," "))))) | R13: =IF($L13=" "," ",(IF($M13=FALSE," ",(IF($M13>0,INDEX('Bin Analysis and Plots'!$E$3:$U$505,MATCH($L13,'Bin Analysis and Plots'!$N$3:$N$505,0),MATCH(R$5,'Bin Analysis and Plots'!$E$2:$U$2,0))," "))))) | S13: =IF($L13=" "," ",(IF($M13=FALSE," ",(IF($M13>0,INDEX('Bin Analysis and Plots'!$E$3:$U$505,MATCH($L13,'Bin Analysis and Plots'!$N$3:$N$505,0),MATCH(S$5,'Bin Analysis and Plots'!$E$2:$U$2,0))," ")))))
G14: =IFERROR('Data Transformation'!M12," ") | I14: Number of values greater than the maximum | J14: =COUNTIF(D7:D386,">"&J12) -> 0 | L14: =$G15 | M14: =IF(L14=" "," ",(IF($L14>0,INDEX('Bin Analysis and Plots'!$E$3:$U$505,MATCH($L14,'Bin Analysis and Plots'!$N$3:$N$505,0),MATCH(M$5,'Bin Analysis and Plots'!$E$2:$U$2,0))," "))) | N14: =IF($L14=" "," ",(IF($M14=FALSE," ",(IF($M14>0,INDEX('Bin Analysis and Plots'!$E$3:$U$505,MATCH($L14,'Bin Analysis and Plots'!$N$3:$N$505,0),MATCH(N$5,'Bin Analysis and Plots'!$E$2:$U$2,0))," "))))) | O14: =IF($L14=" "," ",(IF($M14=FALSE," ",(IF($M14>0,INDEX('Bin Analysis and Plots'!$E$3:$U$505,MATCH($L14,'Bin Analysis and Plots'!$N$3:$N$505,0),MATCH(O$5,'Bin Analysis and Plots'!$E$2:$U$2,0))," "))))) | P14: =IF($L14=" "," ",(IF($M14=FALSE," ",(IF($M14>0,INDEX('Bin Analysis and Plots'!$E$3:$U$505,MATCH($L14,'Bin Analysis and Plots'!$N$3:$N$505,0),MATCH(P$5,'Bin Analysis and Plots'!$E$2:$U$2,0))," "))))) | Q14: =IF($L14=" "," ",(IF($M14=FALSE," ",(IF($M14>0,INDEX('Bin Analysis and Plots'!$E$3:$U$505,MATCH($L14,'Bin Analysis and Plots'!$N$3:$N$505,0),MATCH(Q$5,'Bin Analysis and Plots'!$E$2:$U$2,0))," "))))) | R14: =IF($L14=" "," ",(IF($M14=FALSE," ",(IF($M14>0,INDEX('Bin Analysis and Plots'!$E$3:$U$505,MATCH($L14,'Bin Analysis and Plots'!$N$3:$N$505,0),MATCH(R$5,'Bin Analysis and Plots'!$E$2:$U$2,0))," "))))) | S14: =IF($L14=" "," ",(IF($M14=FALSE," ",(IF($M14>0,INDEX('Bin Analysis and Plots'!$E$3:$U$505,MATCH($L14,'Bin Analysis and Plots'!$N$3:$N$505,0),MATCH(S$5,'Bin Analysis and Plots'!$E$2:$U$2,0))," ")))))
G15: =IFERROR('Data Transformation'!M13," ") | L15: =$G16 | M15: =IF(L15=" "," ",(IF($L15>0,INDEX('Bin Analysis and Plots'!$E$3:$U$505,MATCH($L15,'Bin Analysis and Plots'!$N$3:$N$505,0),MATCH(M$5,'Bin Analysis and Plots'!$E$2:$U$2,0))," "))) | N15: =IF($L15=" "," ",(IF($M15=FALSE," ",(IF($M15>0,INDEX('Bin Analysis and Plots'!$E$3:$U$505,MATCH($L15,'Bin Analysis and Plots'!$N$3:$N$505,0),MATCH(N$5,'Bin Analysis and Plots'!$E$2:$U$2,0))," "))))) | O15: =IF($L15=" "," ",(IF($M15=FALSE," ",(IF($M15>0,INDEX('Bin Analysis and Plots'!$E$3:$U$505,MATCH($L15,'Bin Analysis and Plots'!$N$3:$N$505,0),MATCH(O$5,'Bin Analysis and Plots'!$E$2:$U$2,0))," "))))) | P15: =IF($L15=" "," ",(IF($M15=FALSE," ",(IF($M15>0,INDEX('Bin Analysis and Plots'!$E$3:$U$505,MATCH($L15,'Bin Analysis and Plots'!$N$3:$N$505,0),MATCH(P$5,'Bin Analysis and Plots'!$E$2:$U$2,0))," "))))) | Q15: =IF($L15=" "," ",(IF($M15=FALSE," ",(IF($M15>0,INDEX('Bin Analysis and Plots'!$E$3:$U$505,MATCH($L15,'Bin Analysis and Plots'!$N$3:$N$505,0),MATCH(Q$5,'Bin Analysis and Plots'!$E$2:$U$2,0))," "))))) | R15: =IF($L15=" "," ",(IF($M15=FALSE," ",(IF($M15>0,INDEX('Bin Analysis and Plots'!$E$3:$U$505,MATCH($L15,'Bin Analysis and Plots'!$N$3:$N$505,0),MATCH(R$5,'Bin Analysis and Plots'!$E$2:$U$2,0))," "))))) | S15: =IF($L15=" "," ",(IF($M15=FALSE," ",(IF($M15>0,INDEX('Bin Analysis and Plots'!$E$3:$U$505,MATCH($L15,'Bin Analysis and Plots'!$N$3:$N$505,0),MATCH(S$5,'Bin Analysis and Plots'!$E$2:$U$2,0))," ")))))
G16: =IFERROR('Data Transformation'!M14," ") | I16: Background signal ("Dead" value) | J16: minimum | L16: =$G17 | M16: =IF(L16=" "," ",(IF($L16>0,INDEX('Bin Analysis and Plots'!$E$3:$U$505,MATCH($L16,'Bin Analysis and Plots'!$N$3:$N$505,0),MATCH(M$5,'Bin Analysis and Plots'!$E$2:$U$2,0))," "))) | N16: =IF($L16=" "," ",(IF($M16=FALSE," ",(IF($M16>0,INDEX('Bin Analysis and Plots'!$E$3:$U$505,MATCH($L16,'Bin Analysis and Plots'!$N$3:$N$505,0),MATCH(N$5,'Bin Analysis and Plots'!$E$2:$U$2,0))," "))))) | O16: =IF($L16=" "," ",(IF($M16=FALSE," ",(IF($M16>0,INDEX('Bin Analysis and Plots'!$E$3:$U$505,MATCH($L16,'Bin Analysis and Plots'!$N$3:$N$505,0),MATCH(O$5,'Bin Analysis and Plots'!$E$2:$U$2,0))," "))))) | P16: =IF($L16=" "," ",(IF($M16=FALSE," ",(IF($M16>0,INDEX('Bin Analysis and Plots'!$E$3:$U$505,MATCH($L16,'Bin Analysis and Plots'!$N$3:$N$505,0),MATCH(P$5,'Bin Analysis and Plots'!$E$2:$U$2,0))," "))))) | Q16: =IF($L16=" "," ",(IF($M16=FALSE," ",(IF($M16>0,INDEX('Bin Analysis and Plots'!$E$3:$U$505,MATCH($L16,'Bin Analysis and Plots'!$N$3:$N$505,0),MATCH(Q$5,'Bin Analysis and Plots'!$E$2:$U$2,0))," "))))) | R16: =IF($L16=" "," ",(IF($M16=FALSE," ",(IF($M16>0,INDEX('Bin Analysis and Plots'!$E$3:$U$505,MATCH($L16,'Bin Analysis and Plots'!$N$3:$N$505,0),MATCH(R$5,'Bin Analysis and Plots'!$E$2:$U$2,0))," "))))) | S16: =IF($L16=" "," ",(IF($M16=FALSE," ",(IF($M16>0,INDEX('Bin Analysis and Plots'!$E$3:$U$505,MATCH($L16,'Bin Analysis and Plots'!$N$3:$N$505,0),MATCH(S$5,'Bin Analysis and Plots'!$E$2:$U$2,0))," ")))))
G17: =IFERROR('Data Transformation'!M15," ") | J17: =IF(J16="maximum",'Data Transformation'!U9,'Data Transformation'!U8) -> 1 | L17: =$G18 | M17: =IF(L17=" "," ",(IF($L17>0,INDEX('Bin Analysis and Plots'!$E$3:$U$505,MATCH($L17,'Bin Analysis and Plots'!$N$3:$N$505,0),MATCH(M$5,'Bin Analysis and Plots'!$E$2:$U$2,0))," "))) | N17: =IF($L17=" "," ",(IF($M17=FALSE," ",(IF($M17>0,INDEX('Bin Analysis and Plots'!$E$3:$U$505,MATCH($L17,'Bin Analysis and Plots'!$N$3:$N$505,0),MATCH(N$5,'Bin Analysis and Plots'!$E$2:$U$2,0))," "))))) | O17: =IF($L17=" "," ",(IF($M17=FALSE," ",(IF($M17>0,INDEX('Bin Analysis and Plots'!$E$3:$U$505,MATCH($L17,'Bin Analysis and Plots'!$N$3:$N$505,0),MATCH(O$5,'Bin Analysis and Plots'!$E$2:$U$2,0))," "))))) | P17: =IF($L17=" "," ",(IF($M17=FALSE," ",(IF($M17>0,INDEX('Bin Analysis and Plots'!$E$3:$U$505,MATCH($L17,'Bin Analysis and Plots'!$N$3:$N$505,0),MATCH(P$5,'Bin Analysis and Plots'!$E$2:$U$2,0))," "))))) | Q17: =IF($L17=" "," ",(IF($M17=FALSE," ",(IF($M17>0,INDEX('Bin Analysis and Plots'!$E$3:$U$505,MATCH($L17,'Bin Analysis and Plots'!$N$3:$N$505,0),MATCH(Q$5,'Bin Analysis and Plots'!$E$2:$U$2,0))," "))))) | R17: =IF($L17=" "," ",(IF($M17=FALSE," ",(IF($M17>0,INDEX('Bin Analysis and Plots'!$E$3:$U$505,MATCH($L17,'Bin Analysis and Plots'!$N$3:$N$505,0),MATCH(R$5,'Bin Analysis and Plots'!$E$2:$U$2,0))," "))))) | S17: =IF($L17=" "," ",(IF($M17=FALSE," ",(IF($M17>0,INDEX('Bin Analysis and Plots'!$E$3:$U$505,MATCH($L17,'Bin Analysis and Plots'!$N$3:$N$505,0),MATCH(S$5,'Bin Analysis and Plots'!$E$2:$U$2,0))," ")))))
G18: =IFERROR('Data Transformation'!M16," ") | L18: =$G19 | M18: =IF(L18=" "," ",(IF($L18>0,INDEX('Bin Analysis and Plots'!$E$3:$U$505,MATCH($L18,'Bin Analysis and Plots'!$N$3:$N$505,0),MATCH(M$5,'Bin Analysis and Plots'!$E$2:$U$2,0))," "))) | N18: =IF($L18=" "," ",(IF($M18=FALSE," ",(IF($M18>0,INDEX('Bin Analysis and Plots'!$E$3:$U$505,MATCH($L18,'Bin Analysis and Plots'!$N$3:$N$505,0),MATCH(N$5,'Bin Analysis and Plots'!$E$2:$U$2,0))," "))))) | O18: =IF($L18=" "," ",(IF($M18=FALSE," ",(IF($M18>0,INDEX('Bin Analysis and Plots'!$E$3:$U$505,MATCH($L18,'Bin Analysis and Plots'!$N$3:$N$505,0),MATCH(O$5,'Bin Analysis and Plots'!$E$2:$U$2,0))," "))))) | P18: =IF($L18=" "," ",(IF($M18=FALSE," ",(IF($M18>0,INDEX('Bin Analysis and Plots'!$E$3:$U$505,MATCH($L18,'Bin Analysis and Plots'!$N$3:$N$505,0),MATCH(P$5,'Bin Analysis and Plots'!$E$2:$U$2,0))," "))))) | Q18: =IF($L18=" "," ",(IF($M18=FALSE," ",(IF($M18>0,INDEX('Bin Analysis and Plots'!$E$3:$U$505,MATCH($L18,'Bin Analysis and Plots'!$N$3:$N$505,0),MATCH(Q$5,'Bin Analysis and Plots'!$E$2:$U$2,0))," "))))) | R18: =IF($L18=" "," ",(IF($M18=FALSE," ",(IF($M18>0,INDEX('Bin Analysis and Plots'!$E$3:$U$505,MATCH($L18,'Bin Analysis and Plots'!$N$3:$N$505,0),MATCH(R$5,'Bin Analysis and Plots'!$E$2:$U$2,0))," "))))) | S18: =IF($L18=" "," ",(IF($M18=FALSE," ",(IF($M18>0,INDEX('Bin Analysis and Plots'!$E$3:$U$505,MATCH($L18,'Bin Analysis and Plots'!$N$3:$N$505,0),MATCH(S$5,'Bin Analysis and Plots'!$E$2:$U$2,0))," ")))))
G19: =IFERROR('Data Transformation'!M17," ") | I19: Error override | L19: =$G20 | M19: =IF(L19=" "," ",(IF($L19>0,INDEX('Bin Analysis and Plots'!$E$3:$U$505,MATCH($L19,'Bin Analysis and Plots'!$N$3:$N$505,0),MATCH(M$5,'Bin Analysis and Plots'!$E$2:$U$2,0))," "))) | N19: =IF($L19=" "," ",(IF($M19=FALSE," ",(IF($M19>0,INDEX('Bin Analysis and Plots'!$E$3:$U$505,MATCH($L19,'Bin Analysis and Plots'!$N$3:$N$505,0),MATCH(N$5,'Bin Analysis and Plots'!$E$2:$U$2,0))," "))))) | O19: =IF($L19=" "," ",(IF($M19=FALSE," ",(IF($M19>0,INDEX('Bin Analysis and Plots'!$E$3:$U$505,MATCH($L19,'Bin Analysis and Plots'!$N$3:$N$505,0),MATCH(O$5,'Bin Analysis and Plots'!$E$2:$U$2,0))," "))))) | P19: =IF($L19=" "," ",(IF($M19=FALSE," ",(IF($M19>0,INDEX('Bin Analysis and Plots'!$E$3:$U$505,MATCH($L19,'Bin Analysis and Plots'!$N$3:$N$505,0),MATCH(P$5,'Bin Analysis and Plots'!$E$2:$U$2,0))," "))))) | Q19: =IF($L19=" "," ",(IF($M19=FALSE," ",(IF($M19>0,INDEX('Bin Analysis and Plots'!$E$3:$U$505,MATCH($L19,'Bin Analysis and Plots'!$N$3:$N$505,0),MATCH(Q$5,'Bin Analysis and Plots'!$E$2:$U$2,0))," "))))) | R19: =IF($L19=" "," ",(IF($M19=FALSE," ",(IF($M19>0,INDEX('Bin Analysis and Plots'!$E$3:$U$505,MATCH($L19,'Bin Analysis and Plots'!$N$3:$N$505,0),MATCH(R$5,'Bin Analysis and Plots'!$E$2:$U$2,0))," "))))) | S19: =IF($L19=" "," ",(IF($M19=FALSE," ",(IF($M19>0,INDEX('Bin Analysis and Plots'!$E$3:$U$505,MATCH($L19,'Bin Analysis and Plots'!$N$3:$N$505,0),MATCH(S$5,'Bin Analysis and Plots'!$E$2:$U$2,0))," ")))))
G20: =IFERROR('Data Transformation'!M18," ") | I20: =IF(AND(J4="yes",NOT(J19="")),"see note #3 under the 'Entering data on the Input and Summary Results worksheet' section on first page regarding log and error","leave blank if no override") -> leave blank if no override | L20: =$G21 | M20: =IF(L20=" "," ",(IF($L20>0,INDEX('Bin Analysis and Plots'!$E$3:$U$505,MATCH($L20,'Bin Analysis and Plots'!$N$3:$N$505,0),MATCH(M$5,'Bin Analysis and Plots'!$E$2:$U$2,0))," "))) | N20: =IF($L20=" "," ",(IF($M20=FALSE," ",(IF($M20>0,INDEX('Bin Analysis and Plots'!$E$3:$U$505,MATCH($L20,'Bin Analysis and Plots'!$N$3:$N$505,0),MATCH(N$5,'Bin Analysis and Plots'!$E$2:$U$2,0))," "))))) | O20: =IF($L20=" "," ",(IF($M20=FALSE," ",(IF($M20>0,INDEX('Bin Analysis and Plots'!$E$3:$U$505,MATCH($L20,'Bin Analysis and Plots'!$N$3:$N$505,0),MATCH(O$5,'Bin Analysis and Plots'!$E$2:$U$2,0))," "))))) | P20: =IF($L20=" "," ",(IF($M20=FALSE," ",(IF($M20>0,INDEX('Bin Analysis and Plots'!$E$3:$U$505,MATCH($L20,'Bin Analysis and Plots'!$N$3:$N$505,0),MATCH(P$5,'Bin Analysis and Plots'!$E$2:$U$2,0))," "))))) | Q20: =IF($L20=" "," ",(IF($M20=FALSE," ",(IF($M20>0,INDEX('Bin Analysis and Plots'!$E$3:$U$505,MATCH($L20,'Bin Analysis and Plots'!$N$3:$N$505,0),MATCH(Q$5,'Bin Analysis and Plots'!$E$2:$U$2,0))," "))))) | R20: =IF($L20=" "," ",(IF($M20=FALSE," ",(IF($M20>0,INDEX('Bin Analysis and Plots'!$E$3:$U$505,MATCH($L20,'Bin Analysis and Plots'!$N$3:$N$505,0),MATCH(R$5,'Bin Analysis and Plots'!$E$2:$U$2,0))," "))))) | S20: =IF($L20=" "," ",(IF($M20=FALSE," ",(IF($M20>0,INDEX('Bin Analysis and Plots'!$E$3:$U$505,MATCH($L20,'Bin Analysis and Plots'!$N$3:$N$505,0),MATCH(S$5,'Bin Analysis and Plots'!$E$2:$U$2,0))," ")))))
G21: =IFERROR('Data Transformation'!M19," ") | L21: =$G22 | M21: =IF(L21=" "," ",(IF($L21>0,INDEX('Bin Analysis and Plots'!$E$3:$U$505,MATCH($L21,'Bin Analysis and Plots'!$N$3:$N$505,0),MATCH(M$5,'Bin Analysis and Plots'!$E$2:$U$2,0))," "))) | N21: =IF($L21=" "," ",(IF($M21=FALSE," ",(IF($M21>0,INDEX('Bin Analysis and Plots'!$E$3:$U$505,MATCH($L21,'Bin Analysis and Plots'!$N$3:$N$505,0),MATCH(N$5,'Bin Analysis and Plots'!$E$2:$U$2,0))," "))))) | O21: =IF($L21=" "," ",(IF($M21=FALSE," ",(IF($M21>0,INDEX('Bin Analysis and Plots'!$E$3:$U$505,MATCH($L21,'Bin Analysis and Plots'!$N$3:$N$505,0),MATCH(O$5,'Bin Analysis and Plots'!$E$2:$U$2,0))," "))))) | P21: =IF($L21=" "," ",(IF($M21=FALSE," ",(IF($M21>0,INDEX('Bin Analysis and Plots'!$E$3:$U$505,MATCH($L21,'Bin Analysis and Plots'!$N$3:$N$505,0),MATCH(P$5,'Bin Analysis and Plots'!$E$2:$U$2,0))," "))))) | Q21: =IF($L21=" "," ",(IF($M21=FALSE," ",(IF($M21>0,INDEX('Bin Analysis and Plots'!$E$3:$U$505,MATCH($L21,'Bin Analysis and Plots'!$N$3:$N$505,0),MATCH(Q$5,'Bin Analysis and Plots'!$E$2:$U$2,0))," "))))) | R21: =IF($L21=" "," ",(IF($M21=FALSE," ",(IF($M21>0,INDEX('Bin Analysis and Plots'!$E$3:$U$505,MATCH($L21,'Bin Analysis and Plots'!$N$3:$N$505,0),MATCH(R$5,'Bin Analysis and Plots'!$E$2:$U$2,0))," "))))) | S21: =IF($L21=" "," ",(IF($M21=FALSE," ",(IF($M21>0,INDEX('Bin Analysis and Plots'!$E$3:$U$505,MATCH($L21,'Bin Analysis and Plots'!$N$3:$N$505,0),MATCH(S$5,'Bin Analysis and Plots'!$E$2:$U$2,0))," ")))))
G22: =IFERROR('Data Transformation'!M20," ") | I22: Recommended number of bins | J22: ='Data Transformation'!R23 -> #DIV/0! | L22: =$G23 | M22: =IF(L22=" "," ",(IF($L22>0,INDEX('Bin Analysis and Plots'!$E$3:$U$505,MATCH($L22,'Bin Analysis and Plots'!$N$3:$N$505,0),MATCH(M$5,'Bin Analysis and Plots'!$E$2:$U$2,0))," "))) | N22: =IF($L22=" "," ",(IF($M22=FALSE," ",(IF($M22>0,INDEX('Bin Analysis and Plots'!$E$3:$U$505,MATCH($L22,'Bin Analysis and Plots'!$N$3:$N$505,0),MATCH(N$5,'Bin Analysis and Plots'!$E$2:$U$2,0))," "))))) | O22: =IF($L22=" "," ",(IF($M22=FALSE," ",(IF($M22>0,INDEX('Bin Analysis and Plots'!$E$3:$U$505,MATCH($L22,'Bin Analysis and Plots'!$N$3:$N$505,0),MATCH(O$5,'Bin Analysis and Plots'!$E$2:$U$2,0))," "))))) | P22: =IF($L22=" "," ",(IF($M22=FALSE," ",(IF($M22>0,INDEX('Bin Analysis and Plots'!$E$3:$U$505,MATCH($L22,'Bin Analysis and Plots'!$N$3:$N$505,0),MATCH(P$5,'Bin Analysis and Plots'!$E$2:$U$2,0))," "))))) | Q22: =IF($L22=" "," ",(IF($M22=FALSE," ",(IF($M22>0,INDEX('Bin Analysis and Plots'!$E$3:$U$505,MATCH($L22,'Bin Analysis and Plots'!$N$3:$N$505,0),MATCH(Q$5,'Bin Analysis and Plots'!$E$2:$U$2,0))," "))))) | R22: =IF($L22=" "," ",(IF($M22=FALSE," ",(IF($M22>0,INDEX('Bin Analysis and Plots'!$E$3:$U$505,MATCH($L22,'Bin Analysis and Plots'!$N$3:$N$505,0),MATCH(R$5,'Bin Analysis and Plots'!$E$2:$U$2,0))," "))))) | S22: =IF($L22=" "," ",(IF($M22=FALSE," ",(IF($M22>0,INDEX('Bin Analysis and Plots'!$E$3:$U$505,MATCH($L22,'Bin Analysis and Plots'!$N$3:$N$505,0),MATCH(S$5,'Bin Analysis and Plots'!$E$2:$U$2,0))," ")))))
G23: =IFERROR('Data Transformation'!M21," ") | I23: Number of bins override | L23: =$G24 | M23: =IF(L23=" "," ",(IF($L23>0,INDEX('Bin Analysis and Plots'!$E$3:$U$505,MATCH($L23,'Bin Analysis and Plots'!$N$3:$N$505,0),MATCH(M$5,'Bin Analysis and Plots'!$E$2:$U$2,0))," "))) | N23: =IF($L23=" "," ",(IF($M23=FALSE," ",(IF($M23>0,INDEX('Bin Analysis and Plots'!$E$3:$U$505,MATCH($L23,'Bin Analysis and Plots'!$N$3:$N$505,0),MATCH(N$5,'Bin Analysis and Plots'!$E$2:$U$2,0))," "))))) | O23: =IF($L23=" "," ",(IF($M23=FALSE," ",(IF($M23>0,INDEX('Bin Analysis and Plots'!$E$3:$U$505,MATCH($L23,'Bin Analysis and Plots'!$N$3:$N$505,0),MATCH(O$5,'Bin Analysis and Plots'!$E$2:$U$2,0))," "))))) | P23: =IF($L23=" "," ",(IF($M23=FALSE," ",(IF($M23>0,INDEX('Bin Analysis and Plots'!$E$3:$U$505,MATCH($L23,'Bin Analysis and Plots'!$N$3:$N$505,0),MATCH(P$5,'Bin Analysis and Plots'!$E$2:$U$2,0))," "))))) | Q23: =IF($L23=" "," ",(IF($M23=FALSE," ",(IF($M23>0,INDEX('Bin Analysis and Plots'!$E$3:$U$505,MATCH($L23,'Bin Analysis and Plots'!$N$3:$N$505,0),MATCH(Q$5,'Bin Analysis and Plots'!$E$2:$U$2,0))," "))))) | R23: =IF($L23=" "," ",(IF($M23=FALSE," ",(IF($M23>0,INDEX('Bin Analysis and Plots'!$E$3:$U$505,MATCH($L23,'Bin Analysis and Plots'!$N$3:$N$505,0),MATCH(R$5,'Bin Analysis and Plots'!$E$2:$U$2,0))," "))))) | S23: =IF($L23=" "," ",(IF($M23=FALSE," ",(IF($M23>0,INDEX('Bin Analysis and Plots'!$E$3:$U$505,MATCH($L23,'Bin Analysis and Plots'!$N$3:$N$505,0),MATCH(S$5,'Bin Analysis and Plots'!$E$2:$U$2,0))," ")))))
G24: =IFERROR('Data Transformation'!M22," ") | I24: (leave blank if no override) | L24: =$G25 | M24: =IF(L24=" "," ",(IF($L24>0,INDEX('Bin Analysis and Plots'!$E$3:$U$505,MATCH($L24,'Bin Analysis and Plots'!$N$3:$N$505,0),MATCH(M$5,'Bin Analysis and Plots'!$E$2:$U$2,0))," "))) | N24: =IF($L24=" "," ",(IF($M24=FALSE," ",(IF($M24>0,INDEX('Bin Analysis and Plots'!$E$3:$U$505,MATCH($L24,'Bin Analysis and Plots'!$N$3:$N$505,0),MATCH(N$5,'Bin Analysis and Plots'!$E$2:$U$2,0))," "))))) | O24: =IF($L24=" "," ",(IF($M24=FALSE," ",(IF($M24>0,INDEX('Bin Analysis and Plots'!$E$3:$U$505,MATCH($L24,'Bin Analysis and Plots'!$N$3:$N$505,0),MATCH(O$5,'Bin Analysis and Plots'!$E$2:$U$2,0))," "))))) | P24: =IF($L24=" "," ",(IF($M24=FALSE," ",(IF($M24>0,INDEX('Bin Analysis and Plots'!$E$3:$U$505,MATCH($L24,'Bin Analysis and Plots'!$N$3:$N$505,0),MATCH(P$5,'Bin Analysis and Plots'!$E$2:$U$2,0))," "))))) | Q24: =IF($L24=" "," ",(IF($M24=FALSE," ",(IF($M24>0,INDEX('Bin Analysis and Plots'!$E$3:$U$505,MATCH($L24,'Bin Analysis and Plots'!$N$3:$N$505,0),MATCH(Q$5,'Bin Analysis and Plots'!$E$2:$U$2,0))," "))))) | R24: =IF($L24=" "," ",(IF($M24=FALSE," ",(IF($M24>0,INDEX('Bin Analysis and Plots'!$E$3:$U$505,MATCH($L24,'Bin Analysis and Plots'!$N$3:$N$505,0),MATCH(R$5,'Bin Analysis and Plots'!$E$2:$U$2,0))," "))))) | S24: =IF($L24=" "," ",(IF($M24=FALSE," ",(IF($M24>0,INDEX('Bin Analysis and Plots'!$E$3:$U$505,MATCH($L24,'Bin Analysis and Plots'!$N$3:$N$505,0),MATCH(S$5,'Bin Analysis and Plots'!$E$2:$U$2,0))," ")))))
G25: =IFERROR('Data Transformation'!M23," ") | I25: Rheostat/toggle bin width | J25: ='Data Transformation'!R25 -> #DIV/0! | L25: =$G26 | M25: =IF(L25=" "," ",(IF($L25>0,INDEX('Bin Analysis and Plots'!$E$3:$U$505,MATCH($L25,'Bin Analysis and Plots'!$N$3:$N$505,0),MATCH(M$5,'Bin Analysis and Plots'!$E$2:$U$2,0))," "))) | N25: =IF($L25=" "," ",(IF($M25=FALSE," ",(IF($M25>0,INDEX('Bin Analysis and Plots'!$E$3:$U$505,MATCH($L25,'Bin Analysis and Plots'!$N$3:$N$505,0),MATCH(N$5,'Bin Analysis and Plots'!$E$2:$U$2,0))," "))))) | O25: =IF($L25=" "," ",(IF($M25=FALSE," ",(IF($M25>0,INDEX('Bin Analysis and Plots'!$E$3:$U$505,MATCH($L25,'Bin Analysis and Plots'!$N$3:$N$505,0),MATCH(O$5,'Bin Analysis and Plots'!$E$2:$U$2,0))," "))))) | P25: =IF($L25=" "," ",(IF($M25=FALSE," ",(IF($M25>0,INDEX('Bin Analysis and Plots'!$E$3:$U$505,MATCH($L25,'Bin Analysis and Plots'!$N$3:$N$505,0),MATCH(P$5,'Bin Analysis and Plots'!$E$2:$U$2,0))," "))))) | Q25: =IF($L25=" "," ",(IF($M25=FALSE," ",(IF($M25>0,INDEX('Bin Analysis and Plots'!$E$3:$U$505,MATCH($L25,'Bin Analysis and Plots'!$N$3:$N$505,0),MATCH(Q$5,'Bin Analysis and Plots'!$E$2:$U$2,0))," "))))) | R25: =IF($L25=" "," ",(IF($M25=FALSE," ",(IF($M25>0,INDEX('Bin Analysis and Plots'!$E$3:$U$505,MATCH($L25,'Bin Analysis and Plots'!$N$3:$N$505,0),MATCH(R$5,'Bin Analysis and Plots'!$E$2:$U$2,0))," "))))) | S25: =IF($L25=" "," ",(IF($M25=FALSE," ",(IF($M25>0,INDEX('Bin Analysis and Plots'!$E$3:$U$505,MATCH($L25,'Bin Analysis and Plots'!$N$3:$N$505,0),MATCH(S$5,'Bin Analysis and Plots'!$E$2:$U$2,0))," ")))))
G26: =IFERROR('Data Transformation'!M24," ") | L26: =$G27 | M26: =IF(L26=" "," ",(IF($L26>0,INDEX('Bin Analysis and Plots'!$E$3:$U$505,MATCH($L26,'Bin Analysis and Plots'!$N$3:$N$505,0),MATCH(M$5,'Bin Analysis and Plots'!$E$2:$U$2,0))," "))) | N26: =IF($L26=" "," ",(IF($M26=FALSE," ",(IF($M26>0,INDEX('Bin Analysis and Plots'!$E$3:$U$505,MATCH($L26,'Bin Analysis and Plots'!$N$3:$N$505,0),MATCH(N$5,'Bin Analysis and Plots'!$E$2:$U$2,0))," "))))) | O26: =IF($L26=" "," ",(IF($M26=FALSE," ",(IF($M26>0,INDEX('Bin Analysis and Plots'!$E$3:$U$505,MATCH($L26,'Bin Analysis and Plots'!$N$3:$N$505,0),MATCH(O$5,'Bin Analysis and Plots'!$E$2:$U$2,0))," "))))) | P26: =IF($L26=" "," ",(IF($M26=FALSE," ",(IF($M26>0,INDEX('Bin Analysis and Plots'!$E$3:$U$505,MATCH($L26,'Bin Analysis and Plots'!$N$3:$N$505,0),MATCH(P$5,'Bin Analysis and Plots'!$E$2:$U$2,0))," "))))) | Q26: =IF($L26=" "," ",(IF($M26=FALSE," ",(IF($M26>0,INDEX('Bin Analysis and Plots'!$E$3:$U$505,MATCH($L26,'Bin Analysis and Plots'!$N$3:$N$505,0),MATCH(Q$5,'Bin Analysis and Plots'!$E$2:$U$2,0))," "))))) | R26: =IF($L26=" "," ",(IF($M26=FALSE," ",(IF($M26>0,INDEX('Bin Analysis and Plots'!$E$3:$U$505,MATCH($L26,'Bin Analysis and Plots'!$N$3:$N$505,0),MATCH(R$5,'Bin Analysis and Plots'!$E$2:$U$2,0))," "))))) | S26: =IF($L26=" "," ",(IF($M26=FALSE," ",(IF($M26>0,INDEX('Bin Analysis and Plots'!$E$3:$U$505,MATCH($L26,'Bin Analysis and Plots'!$N$3:$N$505,0),MATCH(S$5,'Bin Analysis and Plots'!$E$2:$U$2,0))," ")))))
G27: =IFERROR('Data Transformation'!M25," ") | I27: Neutral Bin size override
I28: Neutral bin size | J28: ='Data Transformation'!U25 -> #DIV/0!
I30: Enhancing Score assignment
I31: Default Enhancing Score assignment | J31: 0.8
I33: Neutral Score assignment
I34: Default Neutral Score assignment | J34: 0.7
I36: Rheostat Score assignment
I37: Default Rheostat Score assignment | J37: 0.5
I39: Toggle Score assignment
I40: Default Toggle Score assignment | J40: 0.64
E161: 0.23465

Sheet Analysis working notes
A1: This worksheet is a good place to keep track of why and how the values were chosen for WT and "dead", as well as any other analysis parameters.

Sheet Larger Data Sets
A1: 8000 data points | J1: Position Statistics | O1: Data Set Analysis
B2: Position | C2: Mutation | D2: Data | E2: Error | F2: Log of Data | G2: Error of logged data | M2: Threshold
F3: =IF(B3="","",LOG10(D3)) | G3: =IF(E3="", "",0.434*E3/D3) | J3: Unique Distinct Positions | L3: Total# of Mutants | M3: # of variants | O3: Minimum | P3: =IF('Input and Summary Results'!$J$4="yes",MIN('Larger Data Sets'!$F$3:$F$8003),MIN('Larger Data Sets'!$D$3:$D$8003)) -> 0
F4: =IF(B4="","",LOG10(D4)) | G4: =IF(E4="", "",0.434*E4/D4) | J4: all | L4: =COUNTIF($B$3:$B$8003,">0") -> 0 | M4: =IF(L4>4,L4,FALSE) -> FALSE | O4: Maximum | P4: =IF('Input and Summary Results'!$J$4="yes",MAX('Larger Data Sets'!$F$3:$F$8003),MAX('Larger Data Sets'!$D$3:$D$8003)) -> 0
F5: =IF(B5="","",LOG10(D5)) | G5: =IF(E5="", "",0.434*E5/D5) | J5: =LOOKUP(2,1/(COUNTIF($J$4:J4,'Larger Data Sets'!$B$3:$B$8003)=0),'Larger Data Sets'!$B$3:$B$8003) -> 0 | K5: =IFERROR(J5," ") -> 0 | L5: =COUNTIF($B$3:$B$8003,$J5) -> 0 | M5: =IF(L5>4,L5,FALSE) -> FALSE
F6: =IF(B6="","",LOG10(D6)) | G6: =IF(E6="", "",0.434*E6/D6) | J6: =LOOKUP(2,1/(COUNTIF($J$4:J5,'Larger Data Sets'!$B$3:$B$8003)=0),'Larger Data Sets'!$B$3:$B$8003) -> #N/A | K6: =IFERROR(J6," ") | L6: =COUNTIF($B$3:$B$8003,$J6) -> 0 | M6: =IF(L6>4,L6+1,FALSE) -> FALSE | O6: Mean Error | P6: =IF('Input and Summary Results'!J4="yes",AVERAGE('Larger Data Sets'!G3:G8003),AVERAGE('Larger Data Sets'!E3:E8003)) -> #DIV/0!
F7: =IF(B7="","",LOG10(D7)) | G7: =IF(E7="", "",0.434*E7/D7) | J7: =LOOKUP(2,1/(COUNTIF($J$4:J6,'Larger Data Sets'!$B$3:$B$8003)=0),'Larger Data Sets'!$B$3:$B$8003) -> #N/A | K7: =IFERROR(J7," ") | L7: =COUNTIF($B$3:$B$8003,$J7) -> 0 | M7: =IF(L7>4,L7+1,FALSE) -> FALSE | O7: 4 sigma error | P7: =P6*4 -> #DIV/0!
F8: =IF(B8="","",LOG10(D8)) | G8: =IF(E8="", "",0.434*E8/D8) | J8: =LOOKUP(2,1/(COUNTIF($J$4:J7,'Larger Data Sets'!$B$3:$B$8003)=0),'Larger Data Sets'!$B$3:$B$8003) -> #N/A | K8: =IFERROR(J8," ") | L8: =COUNTIF($B$3:$B$8003,$J8) -> 0 | M8: =IF(L8>4,L8+1,FALSE) -> FALSE
F9: =IF(B9="","",LOG10(D9)) | G9: =IF(E9="", "",0.434*E9/D9) | J9: =LOOKUP(2,1/(COUNTIF($J$4:J8,'Larger Data Sets'!$B$3:$B$8003)=0),'Larger Data Sets'!$B$3:$B$8003) -> #N/A | K9: =IFERROR(J9," ") | L9: =COUNTIF($B$3:$B$8003,$J9) -> 0 | M9: =IF(L9>4,L9+1,FALSE) -> FALSE | O9: # of bins
F10: =IF(B10="","",LOG10(D10)) | G10: =IF(E10="", "",0.434*E10/D10) | J10: =LOOKUP(2,1/(COUNTIF($J$4:J9,'Larger Data Sets'!$B$3:$B$8003)=0),'Larger Data Sets'!$B$3:$B$8003) -> #N/A | K10: =IFERROR(J10," ") | L10: =COUNTIF($B$3:$B$8003,$J10) -> 0 | M10: =IF(L10>4,L10+1,FALSE) -> FALSE | O10: Error based | P10: =(P4-P3)/P7 -> #DIV/0!
F11: =IF(B11="","",LOG10(D11)) | G11: =IF(E11="", "",0.434*E11/D11) | J11: =LOOKUP(2,1/(COUNTIF($J$4:J10,'Larger Data Sets'!$B$3:$B$8003)=0),'Larger Data Sets'!$B$3:$B$8003) -> #N/A | K11: =IFERROR(J11," ") | L11: =COUNTIF($B$3:$B$8003,$J11) -> 0 | M11: =IF(L11>4,L11+1,FALSE) -> FALSE | O11: Mean | P11: =AVERAGE(M6:M506) -> #DIV/0!
F12: =IF(B12="","",LOG10(D12)) | G12: =IF(E12="", "",0.434*E12/D12) | J12: =LOOKUP(2,1/(COUNTIF($J$4:J11,'Larger Data Sets'!$B$3:$B$8003)=0),'Larger Data Sets'!$B$3:$B$8003) -> #N/A | K12: =IFERROR(J12," ") | L12: =COUNTIF($B$3:$B$8003,$J12) -> 0 | M12: =IF(L12>4,L12+1,FALSE) -> FALSE | O12: Median | P12: =MEDIAN(M6:M506) -> #NUM!
F13: =IF(B13="","",LOG10(D13)) | G13: =IF(E13="", "",0.434*E13/D13) | J13: =LOOKUP(2,1/(COUNTIF($J$4:J12,'Larger Data Sets'!$B$3:$B$8003)=0),'Larger Data Sets'!$B$3:$B$8003) -> #N/A | K13: =IFERROR(J13," ") | L13: =COUNTIF($B$3:$B$8003,$J13) -> 0 | M13: =IF(L13>4,L13+1,FALSE) -> FALSE
F14: =IF(B14="","",LOG10(D14)) | G14: =IF(E14="", "",0.434*E14/D14) | J14: =LOOKUP(2,1/(COUNTIF($J$4:J13,'Larger Data Sets'!$B$3:$B$8003)=0),'Larger Data Sets'!$B$3:$B$8003) -> #N/A | K14: =IFERROR(J14," ") | L14: =COUNTIF($B$3:$B$8003,$J14) -> 0 | M14: =IF(L14>4,L14+1,FALSE) -> FALSE | O14: Bin Recommendation | P14: =ROUNDDOWN(MIN(P10:P12),0) -> #DIV/0!
F15: =IF(B15="","",LOG10(D15)) | G15: =IF(E15="", "",0.434*E15/D15) | J15: =LOOKUP(2,1/(COUNTIF($J$4:J14,'Larger Data Sets'!$B$3:$B$8003)=0),'Larger Data Sets'!$B$3:$B$8003) -> #N/A | K15: =IFERROR(J15," ") | L15: =COUNTIF($B$3:$B$8003,$J15) -> 0 | M15: =IF(L15>4,L15+1,FALSE) -> FALSE
F16: =IF(B16="","",LOG10(D16)) | G16: =IF(E16="", "",0.434*E16/D16) | J16: =LOOKUP(2,1/(COUNTIF($J$4:J15,'Larger Data Sets'!$B$3:$B$8003)=0),'Larger Data Sets'!$B$3:$B$8003) -> #N/A | K16: =IFERROR(J16," ") | L16: =COUNTIF($B$3:$B$8003,$J16) -> 0 | M16: =IF(L16>4,L16+1,FALSE) -> FALSE | O16: Bin size | P16: =(P4-P3)/P14+0.0000000000001 -> #DIV/0!
F17: =IF(B17="","",LOG10(D17)) | G17: =IF(E17="", "",0.434*E17/D17) | J17: =LOOKUP(2,1/(COUNTIF($J$4:J16,'Larger Data Sets'!$B$3:$B$8003)=0),'Larger Data Sets'!$B$3:$B$8003) -> #N/A | K17: =IFERROR(J17," ") | L17: =COUNTIF($B$3:$B$8003,$J17) -> 0 | M17: =IF(L17>4,L17+1,FALSE) -> FALSE
F18: =IF(B18="","",LOG10(D18)) | G18: =IF(E18="", "",0.434*E18/D18) | J18: =LOOKUP(2,1/(COUNTIF($J$4:J17,'Larger Data Sets'!$B$3:$B$8003)=0),'Larger Data Sets'!$B$3:$B$8003) -> #N/A | K18: =IFERROR(J18," ") | L18: =COUNTIF($B$3:$B$8003,$J18) -> 0 | M18: =IF(L18>4,L18+1,FALSE) -> FALSE
F19: =IF(B19="","",LOG10(D19)) | G19: =IF(E19="", "",0.434*E19/D19) | J19: =LOOKUP(2,1/(COUNTIF($J$4:J18,'Larger Data Sets'!$B$3:$B$8003)=0),'Larger Data Sets'!$B$3:$B$8003) -> #N/A | K19: =IFERROR(J19," ") | L19: =COUNTIF($B$3:$B$8003,$J19) -> 0 | M19: =IF(L19>4,L19+1,FALSE) -> FALSE
F20: =IF(B20="","",LOG10(D20)) | G20: =IF(E20="", "",0.434*E20/D20) | J20: =LOOKUP(2,1/(COUNTIF($J$4:J19,'Larger Data Sets'!$B$3:$B$8003)=0),'Larger Data Sets'!$B$3:$B$8003) -> #N/A | K20: =IFERROR(J20," ") | L20: =COUNTIF($B$3:$B$8003,$J20) -> 0 | M20: =IF(L20>4,L20+1,FALSE) -> FALSE
F21: =IF(B21="","",LOG10(D21)) | G21: =IF(E21="", "",0.434*E21/D21) | J21: =LOOKUP(2,1/(COUNTIF($J$4:J20,'Larger Data Sets'!$B$3:$B$8003)=0),'Larger Data Sets'!$B$3:$B$8003) -> #N/A | K21: =IFERROR(J21," ") | L21: =COUNTIF($B$3:$B$8003,$J21) -> 0 | M21: =IF(L21>4,L21+1,FALSE) -> FALSE
F22: =IF(B22="","",LOG10(D22)) | G22: =IF(E22="", "",0.434*E22/D22) | J22: =LOOKUP(2,1/(COUNTIF($J$4:J21,'Larger Data Sets'!$B$3:$B$8003)=0),'Larger Data Sets'!$B$3:$B$8003) -> #N/A | K22: =IFERROR(J22," ") | L22: =COUNTIF($B$3:$B$8003,$J22) -> 0 | M22: =IF(L22>4,L22+1,FALSE) -> FALSE
F23: =IF(B23="","",LOG10(D23)) | G23: =IF(E23="", "",0.434*E23/D23) | J23: =LOOKUP(2,1/(COUNTIF($J$4:J22,'Larger Data Sets'!$B$3:$B$8003)=0),'Larger Data Sets'!$B$3:$B$8003) -> #N/A | K23: =IFERROR(J23," ") | L23: =COUNTIF($B$3:$B$8003,$J23) -> 0 | M23: =IF(L23>4,L23+1,FALSE) -> FALSE
F24: =IF(B24="","",LOG10(D24)) | G24: =IF(E24="", "",0.434*E24/D24) | J24: =LOOKUP(2,1/(COUNTIF($J$4:J23,'Larger Data Sets'!$B$3:$B$8003)=0),'Larger Data Sets'!$B$3:$B$8003) -> #N/A | K24: =IFERROR(J24," ") | L24: =COUNTIF($B$3:$B$8003,$J24) -> 0 | M24: =IF(L24>4,L24+1,FALSE) -> FALSE
F25: =IF(B25="","",LOG10(D25)) | G25: =IF(E25="", "",0.434*E25/D25) | J25: =LOOKUP(2,1/(COUNTIF($J$4:J24,'Larger Data Sets'!$B$3:$B$8003)=0),'Larger Data Sets'!$B$3:$B$8003) -> #N/A | K25: =IFERROR(J25," ") | L25: =COUNTIF($B$3:$B$8003,$J25) -> 0 | M25: =IF(L25>4,L25+1,FALSE) -> FALSE
F26: =IF(B26="","",LOG10(D26)) | G26: =IF(E26="", "",0.434*E26/D26) | J26: =LOOKUP(2,1/(COUNTIF($J$4:J25,'Larger Data Sets'!$B$3:$B$8003)=0),'Larger Data Sets'!$B$3:$B$8003) -> #N/A | K26: =IFERROR(J26," ") | L26: =COUNTIF($B$3:$B$8003,$J26) -> 0 | M26: =IF(L26>4,L26+1,FALSE) -> FALSE
F27: =IF(B27="","",LOG10(D27)) | G27: =IF(E27="", "",0.434*E27/D27) | J27: =LOOKUP(2,1/(COUNTIF($J$4:J26,'Larger Data Sets'!$B$3:$B$8003)=0),'Larger Data Sets'!$B$3:$B$8003) -> #N/A | K27: =IFERROR(J27," ") | L27: =COUNTIF($B$3:$B$8003,$J27) -> 0 | M27: =IF(L27>4,L27+1,FALSE) -> FALSE
F28: =IF(B28="","",LOG10(D28)) | G28: =IF(E28="", "",0.434*E28/D28) | J28: =LOOKUP(2,1/(COUNTIF($J$4:J27,'Larger Data Sets'!$B$3:$B$8003)=0),'Larger Data Sets'!$B$3:$B$8003) -> #N/A | K28: =IFERROR(J28," ") | L28: =COUNTIF($B$3:$B$8003,$J28) -> 0 | M28: =IF(L28>4,L28+1,FALSE) -> FALSE
... F505: =IF(B505="","",LOG10(D505)) | G505: =IF(E505="", "",0.434*E505/D505) | J505: =LOOKUP(2,1/(COUNTIF($J$4:J504,'Larger Data Sets'!$B$3:$B$8003)=0),'Larger Data Sets'!$B$3:$B$8003) -> #N/A | K505: =IFERROR(J505," ") | L505: =COUNTIF($B$3:$B$8003,$J505) -> 0 | M505: =IF(L505>4,L505+1,FALSE) -> FALSE
F506: =IF(B506="","",LOG10(D506)) | G506: =IF(E506="", "",0.434*E506/D506) | M506: =IF(L506>4,L506+1,FALSE) -> FALSE
F507: =IF(B507="","",LOG10(D507)) | G507: =IF(E507="", "",0.434*E507/D507)
F508: =IF(B508="","",LOG10(D508)) | G508: =IF(E508="", "",0.434*E508/D508)
F509: =IF(B509="","",LOG10(D509)) | G509: =IF(E509="", "",0.434*E509/D509)
F510: =IF(B510="","",LOG10(D510)) | G510: =IF(E510="", "",0.434*E510/D510)
F511: =IF(B511="","",LOG10(D511)) | G511: =IF(E511="", "",0.434*E511/D511)
F512: =IF(B512="","",LOG10(D512)) | G512: =IF(E512="", "",0.434*E512/D512)
F513: =IF(B513="","",LOG10(D513)) | G513: =IF(E513="", "",0.434*E513/D513)
F514: =IF(B514="","",LOG10(D514)) | G514: =IF(E514="", "",0.434*E514/D514)
F515: =IF(B515="","",LOG10(D515)) | G515: =IF(E515="", "",0.434*E515/D515)
F516: =IF(B516="","",LOG10(D516)) | G516: =IF(E516="", "",0.434*E516/D516)
...

Sheet Data Transformation
B1: Data | J1: Position Statistics | Q1: Bin determination | T1: Drop down menu options
B2: Position | C2: Data | D2: Error | E2: Log Data | F2: Error of Log Data | G2: Data to be analyzed | H2: Error to be analyzed | O2: Threshold
A3: WT | C3: =IF(ISNUMBER('Input and Summary Results'!$D$5),'Input and Summary Results'!$D$5,FALSE) -> FALSE | D3: =IF(ISNUMBER('Input and Summary Results'!$E$5),'Input and Summary Results'!$E$5,FALSE) -> FALSE | E3: =LOG10(C3) -> #NUM! | F3: =0.434*D4/C4 -> #DIV/0! | G3: =IF('Input and Summary Results'!$J$4="yes",'Data Transformation'!E3,'Data Transformation'!C3) -> #NUM! | H3: =IF('Input and Summary Results'!$J$4="yes",'Data Transformation'!F3,'Data Transformation'!D3) -> #DIV/0! | J3: Unique Distinct Positions | M3: Positions ordered | N3: Total# of Mutants | O3: # of variants | Q3: Minimum | R3: =MIN(G4:G404) -> 0 | T3: log scale?
A4: WT | B4: ='Input and Summary Results'!G$8 | C4: =IF(B4=0,FALSE,IF(ISNUMBER('Input and Summary Results'!$D$5),'Input and Summary Results'!$D$5,FALSE)) -> FALSE | D4: =IF(B4=0,FALSE,'Input and Summary Results'!$E$5) -> 0 | E4: =IF(C4=FALSE,FALSE,LOG10(C4)) -> FALSE | F4: =IF(D4=FALSE, FALSE,0.434*D4/C4) -> #DIV/0! | G4: =IF(B4=" ",FALSE,(IF('Input and Summary Results'!$J$4="yes",'Data Transformation'!E4,'Data Transformation'!C4))) -> FALSE | H4: =IF(B4=" ",FALSE,(IF('Input and Summary Results'!$J$4="yes",'Data Transformation'!F4,'Data Transformation'!D4))) -> FALSE | J4: all | M4: =J4 -> all | N4: =COUNTIF(B24:B404,">0")+COUNTIF(B4,">0") -> 0 | O4: =IF(N4>4,N4,FALSE) -> FALSE | Q4: Maximum | R4: =IF('Input and Summary Results'!J4="yes",MAX('Data Transformation'!E24:E404),MAX(C24:C404)) -> 0 | T4: yes
A5: WT | B5: ='Input and Summary Results'!$G9 | C5: =IF(B5=0,FALSE,IF(ISNUMBER('Input and Summary Results'!$D$5),'Input and Summary Results'!$D$5,FALSE)) -> FALSE | D5: =IF(B5=0,FALSE,'Input and Summary Results'!$E$5) -> 0 | E5: =IF(C5=FALSE,FALSE,LOG10(C5)) -> FALSE | F5: =IF(D5=FALSE, FALSE,0.434*D5/C5) -> #DIV/0! | G5: =IF(B5=" ",FALSE,(IF('Input and Summary Results'!$J$4="yes",'Data Transformation'!E5,'Data Transformation'!C5))) -> FALSE | H5: =IF(B5=" ",FALSE,(IF('Input and Summary Results'!$J$4="yes",'Data Transformation'!F5,'Data Transformation'!D5))) -> FALSE | J5: =LOOKUP(2,1/(COUNTIF($J$4:J4,'Input and Summary Results'!$B$7:$B$404)=0),'Input and Summary Results'!$B$7:$B$404) -> 0 | K5: =IFERROR(J5," ") -> 0 | N5: =COUNTIF($B$4:$B$404,$J5) -> 0 | O5: =IF(N5>4,N5,FALSE) -> FALSE | Q5: Wild Type | R5: =$G$3 -> #NUM! | T5: no
A6: WT | B6: ='Input and Summary Results'!$G10 | C6: =IF(B6=0,FALSE,IF(ISNUMBER('Input and Summary Results'!$D$5),'Input and Summary Results'!$D$5,FALSE)) -> FALSE | D6: =IF(B6=0,FALSE,'Input and Summary Results'!$E$5) -> 0 | E6: =IF(C6=FALSE,FALSE,LOG10(C6)) -> FALSE | F6: =IF(D6=FALSE, FALSE,0.434*D6/C6) -> #DIV/0! | G6: =IF(B6=" ",FALSE,(IF('Input and Summary Results'!$J$4="yes",'Data Transformation'!E6,'Data Transformation'!C6))) -> FALSE | H6: =IF(B6=" ",FALSE,(IF('Input and Summary Results'!$J$4="yes",'Data Transformation'!F6,'Data Transformation'!D6))) -> FALSE | J6: =LOOKUP(2,1/(COUNTIF($J$4:J5,'Input and Summary Results'!$B$7:$B$404)=0),'Input and Summary Results'!$B$7:$B$404) -> #N/A | K6: =IFERROR(J6," ") | L6: 1 | M6: =SMALL($K$6:$K$25,L6) -> #NUM! | N6: =COUNTIF($B$4:$B$404,$M6) -> 0 | O6: =IF(N6>4,N6,FALSE) -> FALSE | Q6: Dead | R6: =IF('Input and Summary Results'!J4="yes",LOG('Input and Summary Results'!J17,10),'Input and Summary Results'!J17) -> 0
A7: WT | B7: ='Input and Summary Results'!$G11 | C7: =IF(B7=0,FALSE,IF(ISNUMBER('Input and Summary Results'!$D$5),'Input and Summary Results'!$D$5,FALSE)) -> FALSE | D7: =IF(B7=0,FALSE,'Input and Summary Results'!$E$5) -> 0 | E7: =IF(C7=FALSE,FALSE,LOG10(C7)) -> FALSE | F7: =IF(D7=FALSE, FALSE,0.434*D7/C7) -> #DIV/0! | G7: =IF(B7=" ",FALSE,(IF('Input and Summary Results'!$J$4="yes",'Data Transformation'!E7,'Data Transformation'!C7))) -> FALSE | H7: =IF(B7=" ",FALSE,(IF('Input and Summary Results'!$J$4="yes",'Data Transformation'!F7,'Data Transformation'!D7))) -> FALSE | J7: =LOOKUP(2,1/(COUNTIF($J$4:J6,'Input and Summary Results'!$B$7:$B$404)=0),'Input and Summary Results'!$B$7:$B$404) -> #N/A | K7: =IFERROR(J7," ") | L7: 2 | M7: =SMALL($K$6:$K$25,L7) -> #NUM! | N7: =COUNTIF($B$4:$B$404,$M7) -> 0 | O7: =IF(N7>4,N7,FALSE) -> FALSE | T7: non fxnal value
A8: WT | B8: ='Input and Summary Results'!$G12 | C8: =IF(B8=0,FALSE,IF(ISNUMBER('Input and Summary Results'!$D$5),'Input and Summary Results'!$D$5,FALSE)) -> FALSE | D8: =IF(B8=0,FALSE,'Input and Summary Results'!$E$5) -> 0 | E8: =IF(C8=FALSE,FALSE,LOG10(C8)) -> FALSE | F8: =IF(D8=FALSE, FALSE,0.434*D8/C8) -> #DIV/0! | G8: =IF(B8=" ",FALSE,(IF('Input and Summary Results'!$J$4="yes",'Data Transformation'!E8,'Data Transformation'!C8))) -> FALSE | H8: =IF(B8=" ",FALSE,(IF('Input and Summary Results'!$J$4="yes",'Data Transformation'!F8,'Data Transformation'!D8))) -> FALSE | J8: =LOOKUP(2,1/(COUNTIF($J$4:J7,'Input and Summary Results'!$B$7:$B$404)=0),'Input and Summary Results'!$B$7:$B$404) -> #N/A | K8: =IFERROR(J8," ") | L8: 3 | M8: =SMALL($K$6:$K$25,L8) -> #NUM! | N8: =COUNTIF($B$4:$B$404,$M8) -> 0 | O8: =IF(N8>4,N8,FALSE) -> FALSE | Q8: Max/Min override | T8: minimum | U8: =IF('Input and Summary Results'!J4="yes",10^R9,R9) -> 1
A9: WT | B9: ='Input and Summary Results'!$G13 | C9: =IF(B9=0,FALSE,IF(ISNUMBER('Input and Summary Results'!$D$5),'Input and Summary Results'!$D$5,FALSE)) -> FALSE | D9: =IF(B9=0,FALSE,'Input and Summary Results'!$E$5) -> 0 | E9: =IF(C9=FALSE,FALSE,LOG10(C9)) -> FALSE | F9: =IF(D9=FALSE, FALSE,0.434*D9/C9) -> #DIV/0! | G9: =IF(B9=" ",FALSE,(IF('Input and Summary Results'!$J$4="yes",'Data Transformation'!E9,'Data Transformation'!C9))) -> FALSE | H9: =IF(B9=" ",FALSE,(IF('Input and Summary Results'!$J$4="yes",'Data Transformation'!F9,'Data Transformation'!D9))) -> FALSE | J9: =LOOKUP(2,1/(COUNTIF($J$4:J8,'Input and Summary Results'!$B$7:$B$404)=0),'Input and Summary Results'!$B$7:$B$404) -> #N/A | K9: =IFERROR(J9," ") | L9: 4 | M9: =SMALL($K$6:$K$25,L9) -> #NUM! | N9: =COUNTIF($B$4:$B$404,$M9) -> 0 | O9: =IF(N9>4,N9,FALSE) -> FALSE | Q9: Minimum | R9: =IF('Input and Summary Results'!J11="",'Data Transformation'!R3,IF('Input and Summary Results'!$J$4="yes",LOG('Input and Summary Results'!J11,10),'Input and Summary Results'!J11)) -> 0 | T9: maximum | U9: =IF('Input and Summary Results'!J4="yes",10^R10,R10) -> 1
A10: WT | B10: ='Input and Summary Results'!$G14 | C10: =IF(B10=0,FALSE,IF(ISNUMBER('Input and Summary Results'!$D$5),'Input and Summary Results'!$D$5,FALSE)) -> FALSE | D10: =IF(B10=0,FALSE,'Input and Summary Results'!$E$5) -> 0 | E10: =IF(C10=FALSE,FALSE,LOG10(C10)) -> FALSE | F10: =IF(D10=FALSE, FALSE,0.434*D10/C10) -> #DIV/0! | G10: =IF(B10=" ",FALSE,(IF('Input and Summary Results'!$J$4="yes",'Data Transformation'!E10,'Data Transformation'!C10))) -> FALSE | H10: =IF(B10=" ",FALSE,(IF('Input and Summary Results'!$J$4="yes",'Data Transformation'!F10,'Data Transformation'!D10))) -> FALSE | J10: =LOOKUP(2,1/(COUNTIF($J$4:J9,'Input and Summary Results'!$B$7:$B$404)=0),'Input and Summary Results'!$B$7:$B$404) -> #N/A | K10: =IFERROR(J10," ") | L10: 5 | M10: =SMALL($K$6:$K$25,L10) -> #NUM! | N10: =COUNTIF($B$4:$B$404,$M10) -> 0 | O10: =IF(N10>4,N10,FALSE) -> FALSE | Q10: Maximum | R10: =IF('Input and Summary Results'!J12="",'Data Transformation'!R4,IF('Input and Summary Results'!$J$4="yes",LOG('Input and Summary Results'!J12,10),'Input and Summary Results'!J12)) -> 0
A11: WT | B11: ='Input and Summary Results'!$G15 | C11: =IF(B11=0,FALSE,IF(ISNUMBER('Input and Summary Results'!$D$5),'Input and Summary Results'!$D$5,FALSE)) -> FALSE | D11: =IF(B11=0,FALSE,'Input and Summary Results'!$E$5) -> 0 | E11: =IF(C11=FALSE,FALSE,LOG10(C11)) -> FALSE | F11: =IF(D11=FALSE, FALSE,0.434*D11/C11) -> #DIV/0! | G11: =IF(B11=" ",FALSE,(IF('Input and Summary Results'!$J$4="yes",'Data Transformation'!E11,'Data Transformation'!C11))) -> FALSE | H11: =IF(B11=" ",FALSE,(IF('Input and Summary Results'!$J$4="yes",'Data Transformation'!F11,'Data Transformation'!D11))) -> FALSE | J11: =LOOKUP(2,1/(COUNTIF($J$4:J10,'Input and Summary Results'!$B$7:$B$404)=0),'Input and Summary Results'!$B$7:$B$404) -> #N/A | K11: =IFERROR(J11," ") | L11: 6 | M11: =SMALL($K$6:$K$25,L11) -> #NUM! | N11: =COUNTIF($B$4:$B$404,$M11) -> 0 | O11: =IF(N11>4,N11,FALSE) -> FALSE | T11: Top WT boundary | U11: ='Data Transformation'!$G$3+0.5*'Data Transformation'!$U$25 -> #NUM!
A12: WT | B12: ='Input and Summary Results'!$G16 | C12: =IF(B12=0,FALSE,IF(ISNUMBER('Input and Summary Results'!$D$5),'Input and Summary Results'!$D$5,FALSE)) -> FALSE | D12: =IF(B12=0,FALSE,'Input and Summary Results'!$E$5) -> 0 | E12: =IF(C12=FALSE,FALSE,LOG10(C12)) -> FALSE | F12: =IF(D12=FALSE, FALSE,0.434*D12/C12) -> #DIV/0! | G12: =IF(B12=" ",FALSE,(IF('Input and Summary Results'!$J$4="yes",'Data Transformation'!E12,'Data Transformation'!C12))) -> FALSE | H12: =IF(B12=" ",FALSE,(IF('Input and Summary Results'!$J$4="yes",'Data Transformation'!F12,'Data Transformation'!D12))) -> FALSE | J12: =LOOKUP(2,1/(COUNTIF($J$4:J11,'Input and Summary Results'!$B$7:$B$404)=0),'Input and Summary Results'!$B$7:$B$404) -> #N/A | K12: =IFERROR(J12," ") | L12: 7 | M12: =SMALL($K$6:$K$25,L12) -> #NUM! | N12: =COUNTIF($B$4:$B$404,$M12) -> 0 | O12: =IF(N12>4,N12,FALSE) -> FALSE | T12: Bottom WT boundary | U12: =U11-U25 -> #NUM!
A13: WT | B13: ='Input and Summary Results'!$G17 | C13: =IF(B13=0,FALSE,IF(ISNUMBER('Input and Summary Results'!$D$5),'Input and Summary Results'!$D$5,FALSE)) -> FALSE | D13: =IF(B13=0,FALSE,'Input and Summary Results'!$E$5) -> 0 | E13: =IF(C13=FALSE,FALSE,LOG10(C13)) -> FALSE | F13: =IF(D13=FALSE, FALSE,0.434*D13/C13) -> #DIV/0! | G13: =IF(B13=" ",FALSE,(IF('Input and Summary Results'!$J$4="yes",'Data Transformation'!E13,'Data Transformation'!C13))) -> FALSE | H13: =IF(B13=" ",FALSE,(IF('Input and Summary Results'!$J$4="yes",'Data Transformation'!F13,'Data Transformation'!D13))) -> FALSE | J13: =LOOKUP(2,1/(COUNTIF($J$4:J12,'Input and Summary Results'!$B$7:$B$404)=0),'Input and Summary Results'!$B$7:$B$404) -> #N/A | K13: =IFERROR(J13," ") | L13: 8 | M13: =SMALL($K$6:$K$25,L13) -> #NUM! | N13: =COUNTIF($B$4:$B$404,$M13) -> 0 | O13: =IF(N13>4,N13,FALSE) -> FALSE
A14: WT | B14: ='Input and Summary Results'!$G18 | C14: =IF(B14=0,FALSE,IF(ISNUMBER('Input and Summary Results'!$D$5),'Input and Summary Results'!$D$5,FALSE)) -> FALSE | D14: =IF(B14=0,FALSE,'Input and Summary Results'!$E$5) -> 0 | E14: =IF(C14=FALSE,FALSE,LOG10(C14)) -> FALSE | F14: =IF(D14=FALSE, FALSE,0.434*D14/C14) -> #DIV/0! | G14: =IF(B14=" ",FALSE,(IF('Input and Summary Results'!$J$4="yes",'Data Transformation'!E14,'Data Transformation'!C14))) -> FALSE | H14: =IF(B14=" ",FALSE,(IF('Input and Summary Results'!$J$4="yes",'Data Transformation'!F14,'Data Transformation'!D14))) -> FALSE | J14: =LOOKUP(2,1/(COUNTIF($J$4:J13,'Input and Summary Results'!$B$7:$B$404)=0),'Input and Summary Results'!$B$7:$B$404) -> #N/A | K14: =IFERROR(J14," ") | L14: 9 | M14: =SMALL($K$6:$K$25,L14) -> #NUM! | N14: =COUNTIF($B$4:$B$404,$M14) -> 0 | O14: =IF(N14>4,N14,FALSE) -> FALSE | Q14: Mean error | R14: =_xlfn.AGGREGATE(1,6,H3,H24:H404) -> #DIV/0!
A15: WT | B15: ='Input and Summary Results'!$G19 | C15: =IF(B15=0,FALSE,IF(ISNUMBER('Input and Summary Results'!$D$5),'Input and Summary Results'!$D$5,FALSE)) -> FALSE | D15: =IF(B15=0,FALSE,'Input and Summary Results'!$E$5) -> 0 | E15: =IF(C15=FALSE,FALSE,LOG10(C15)) -> FALSE | F15: =IF(D15=FALSE, FALSE,0.434*D15/C15) -> #DIV/0! | G15: =IF(B15=" ",FALSE,(IF('Input and Summary Results'!$J$4="yes",'Data Transformation'!E15,'Data Transformation'!C15))) -> FALSE | H15: =IF(B15=" ",FALSE,(IF('Input and Summary Results'!$J$4="yes",'Data Transformation'!F15,'Data Transformation'!D15))) -> FALSE | J15: =LOOKUP(2,1/(COUNTIF($J$4:J14,'Input and Summary Results'!$B$7:$B$404)=0),'Input and Summary Results'!$B$7:$B$404) -> #N/A | K15: =IFERROR(J15," ") | L15: 10 | M15: =SMALL($K$6:$K$25,L15) -> #NUM! | N15: =COUNTIF($B$4:$B$404,$M15) -> 0 | O15: =IF(N15>4,N15,FALSE) -> FALSE | Q15: Error for calculations | R15: =IF('Input and Summary Results'!J19="",'Data Transformation'!R14,(IF('Input and Summary Results'!J4="yes",'Input and Summary Results'!J19*0.434/C3,'Input and Summary Results'!J19))) -> #DIV/0!
A16: WT | B16: ='Input and Summary Results'!$G20 | C16: =IF(B16=0,FALSE,IF(ISNUMBER('Input and Summary Results'!$D$5),'Input and Summary Results'!$D$5,FALSE)) -> FALSE | D16: =IF(B16=0,FALSE,'Input and Summary Results'!$E$5) -> 0 | E16: =IF(C16=FALSE,FALSE,LOG10(C16)) -> FALSE | F16: =IF(D16=FALSE, FALSE,0.434*D16/C16) -> #DIV/0! | G16: =IF(B16=" ",FALSE,(IF('Input and Summary Results'!$J$4="yes",'Data Transformation'!E16,'Data Transformation'!C16))) -> FALSE | H16: =IF(B16=" ",FALSE,(IF('Input and Summary Results'!$J$4="yes",'Data Transformation'!F16,'Data Transformation'!D16))) -> FALSE | J16: =LOOKUP(2,1/(COUNTIF($J$4:J15,'Input and Summary Results'!$B$7:$B$404)=0),'Input and Summary Results'!$B$7:$B$404) -> #N/A | K16: =IFERROR(J16," ") | L16: 11 | M16: =SMALL($K$6:$K$25,L16) -> #NUM! | N16: =COUNTIF($B$4:$B$404,$M16) -> 0 | O16: =IF(N16>4,N16,FALSE) -> FALSE | Q16: 2 sigma error | R16: =R15*2 -> #DIV/0!
A17: WT | B17: ='Input and Summary Results'!$G21 | C17: =IF(B17=0,FALSE,IF(ISNUMBER('Input and Summary Results'!$D$5),'Input and Summary Results'!$D$5,FALSE)) -> FALSE | D17: =IF(B17=0,FALSE,'Input and Summary Results'!$E$5) -> 0 | E17: =IF(C17=FALSE,FALSE,LOG10(C17)) -> FALSE | F17: =IF(D17=FALSE, FALSE,0.434*D17/C17) -> #DIV/0! | G17: =IF(B17=" ",FALSE,(IF('Input and Summary Results'!$J$4="yes",'Data Transformation'!E17,'Data Transformation'!C17))) -> FALSE | H17: =IF(B17=" ",FALSE,(IF('Input and Summary Results'!$J$4="yes",'Data Transformation'!F17,'Data Transformation'!D17))) -> FALSE | J17: =LOOKUP(2,1/(COUNTIF($J$4:J16,'Input and Summary Results'!$B$7:$B$404)=0),'Input and Summary Results'!$B$7:$B$404) -> #N/A | K17: =IFERROR(J17," ") | L17: 12 | M17: =SMALL($K$6:$K$25,L17) -> #NUM! | N17: =COUNTIF($B$4:$B$404,$M17) -> 0 | O17: =IF(N17>4,N17,FALSE) -> FALSE
A18: WT | B18: ='Input and Summary Results'!$G22 | C18: =IF(B18=0,FALSE,IF(ISNUMBER('Input and Summary Results'!$D$5),'Input and Summary Results'!$D$5,FALSE)) -> FALSE | D18: =IF(B18=0,FALSE,'Input and Summary Results'!$E$5) -> 0 | E18: =IF(C18=FALSE,FALSE,LOG10(C18)) -> FALSE | F18: =IF(D18=FALSE, FALSE,0.434*D18/C18) -> #DIV/0! | G18: =IF(B18=" ",FALSE,(IF('Input and Summary Results'!$J$4="yes",'Data Transformation'!E18,'Data Transformation'!C18))) -> FALSE | H18: =IF(B18=" ",FALSE,(IF('Input and Summary Results'!$J$4="yes",'Data Transformation'!F18,'Data Transformation'!D18))) -> FALSE | J18: =LOOKUP(2,1/(COUNTIF($J$4:J17,'Input and Summary Results'!$B$7:$B$404)=0),'Input and Summary Results'!$B$7:$B$404) -> #N/A | K18: =IFERROR(J18," ") | L18: 13 | M18: =SMALL($K$6:$K$25,L18) -> #NUM! | N18: =COUNTIF($B$4:$B$404,$M18) -> 0 | O18: =IF(N18>4,N18,FALSE) -> FALSE | Q18: # of bins
A19: WT | B19: ='Input and Summary Results'!$G23 | C19: =IF(B19=0,FALSE,IF(ISNUMBER('Input and Summary Results'!$D$5),'Input and Summary Results'!$D$5,FALSE)) -> FALSE | D19: =IF(B19=0,FALSE,'Input and Summary Results'!$E$5) -> 0 | E19: =IF(C19=FALSE,FALSE,LOG10(C19)) -> FALSE | F19: =IF(D19=FALSE, FALSE,0.434*D19/C19) -> #DIV/0! | G19: =IF(B19=" ",FALSE,(IF('Input and Summary Results'!$J$4="yes",'Data Transformation'!E19,'Data Transformation'!C19))) -> FALSE | H19: =IF(B19=" ",FALSE,(IF('Input and Summary Results'!$J$4="yes",'Data Transformation'!F19,'Data Transformation'!D19))) -> FALSE | J19: =LOOKUP(2,1/(COUNTIF($J$4:J18,'Input and Summary Results'!$B$7:$B$404)=0),'Input and Summary Results'!$B$7:$B$404) -> #N/A | K19: =IFERROR(J19," ") | L19: 14 | M19: =SMALL($K$6:$K$25,L19) -> #NUM! | N19: =COUNTIF($B$4:$B$404,$M19) -> 0 | O19: =IF(N19>4,N19,FALSE) -> FALSE | Q19: Error based | R19: =(R10-R9)/R16 -> #DIV/0!
A20: WT | B20: ='Input and Summary Results'!$G24 | C20: =IF(B20=0,FALSE,IF(ISNUMBER('Input and Summary Results'!$D$5),'Input and Summary Results'!$D$5,FALSE)) -> FALSE | D20: =IF(B20=0,FALSE,'Input and Summary Results'!$E$5) -> 0 | E20: =IF(C20=FALSE,FALSE,LOG10(C20)) -> FALSE | F20: =IF(D20=FALSE, FALSE,0.434*D20/C20) -> #DIV/0! | G20: =IF(B20=" ",FALSE,(IF('Input and Summary Results'!$J$4="yes",'Data Transformation'!E20,'Data Transformation'!C20))) -> FALSE | H20: =IF(B20=" ",FALSE,(IF('Input and Summary Results'!$J$4="yes",'Data Transformation'!F20,'Data Transformation'!D20))) -> FALSE | J20: =LOOKUP(2,1/(COUNTIF($J$4:J19,'Input and Summary Results'!$B$7:$B$404)=0),'Input and Summary Results'!$B$7:$B$404) -> #N/A | K20: =IFERROR(J20," ") | L20: 15 | M20: =SMALL($K$6:$K$25,L20) -> #NUM! | N20: =COUNTIF($B$4:$B$404,$M20) -> 0 | O20: =IF(N20>4,N20,FALSE) -> FALSE | Q20: Mean | R20: =AVERAGE(O5:O24) -> #DIV/0!
A21: WT | B21: ='Input and Summary Results'!$G25 | C21: =IF(B21=0,FALSE,IF(ISNUMBER('Input and Summary Results'!$D$5),'Input and Summary Results'!$D$5,FALSE)) -> FALSE | D21: =IF(B21=0,FALSE,'Input and Summary Results'!$E$5) -> 0 | E21: =IF(C21=FALSE,FALSE,LOG10(C21)) -> FALSE | F21: =IF(D21=FALSE, FALSE,0.434*D21/C21) -> #DIV/0! | G21: =IF(B21=" ",FALSE,(IF('Input and Summary Results'!$J$4="yes",'Data Transformation'!E21,'Data Transformation'!C21))) -> FALSE | H21: =IF(B21=" ",FALSE,(IF('Input and Summary Results'!$J$4="yes",'Data Transformation'!F21,'Data Transformation'!D21))) -> FALSE | J21: =LOOKUP(2,1/(COUNTIF($J$4:J20,'Input and Summary Results'!$B$7:$B$404)=0),'Input and Summary Results'!$B$7:$B$404) -> #N/A | K21: =IFERROR(J21," ") | L21: 16 | M21: =SMALL($K$6:$K$25,L21) -> #NUM! | N21: =COUNTIF($B$4:$B$404,$M21) -> 0 | O21: =IF(N21>4,N21,FALSE) -> FALSE | Q21: Median | R21: =MEDIAN(O5:O24) -> #NUM!
